Workbook

Sheet Задание 3
B1: Задание 3. Ориентировочное время - 15-20 минут | G1: Год | H1: 2020 | I1: =H1+1 -> 2021 | J1: =I1+1 -> 2022 | K1: =J1+1 -> 2023 | L1: =K1+1 -> 2024 | N1: 2020 | O1: 2020 | P1: 2020 | Q1: 2020 | R1: 2020 | S1: 2020 | T1: 2020 | U1: 2020 | V1: 2020 | W1: 2020 | X1: 2020 | Y1: 2020 | Z1: =N1+1 -> 2021 | AA1: =O1+1 -> 2021 | AB1: =P1+1 -> 2021 | AC1: =Q1+1 -> 2021 | AD1: =R1+1 -> 2021 | AE1: =S1+1 -> 2021 | AF1: =T1+1 -> 2021 | AG1: =U1+1 -> 2021 | ... BU1: =BI1+1 -> 2024
B2: Показатель | E2: ед. изм. | G2: Месяц | N2: 1 | O2: =N2+1 -> 2 | P2: =O2+1 -> 3 | Q2: =P2+1 -> 4 | R2: =Q2+1 -> 5 | S2: =R2+1 -> 6 | T2: =S2+1 -> 7 | U2: =T2+1 -> 8 | V2: =U2+1 -> 9 | ... Y2: =X2+1 -> 12 | Z2: =N2 -> 1 | AA2: =O2 -> 2 | AB2: =P2 -> 3 | AC2: =Q2 -> 4 | AD2: =R2 -> 5 | AE2: =S2 -> 6 | AF2: =T2 -> 7 | AG2: =U2 -> 8 | ... BU2: =BI2 -> 12
E3: 5. Закрепляем строки/столбцы
B4: Задачи:
B5: На основе листа "Декларации" - нужно посчитать и заполнить выделенные блоки ниже (то, что фиолетовым)
B6: Расчеты - делать по месяцам, далее суммирование в годы
B7: hint 1 - можно (даже нужно) делать дополнительные расчетные столбцы/ячейки
B8: hint 2 - для идентификации нужных товаров (гороховый изолят и гороховый концентрат) - использовать слова "горох", "изолят", "концентр"
B11: Важно!!!
B12: Все должно быть аккуратно оформлено
B14: Импорт
N15: 7. Аккуратно пишем формулу: без хардов, правильно закрепленные ячейки и тд
B16: В тоннах | F16: 6. Создаем доп столбец - "ИМ" и "ЭК" - чтобы не менять фомрулу | H16: 8. Через суммесли - сводим месячные данные по годам
B17: Гороховый изолят | E17: тонн | F17: ИМ | H17: =SUMIFS($N17:$BU17,$N$1:$BU$1,H$1) -> 91.51197 | I17: =SUMIFS($N17:$BU17,$N$1:$BU$1,I$1) -> 387.48 | J17: =SUMIFS($N17:$BU17,$N$1:$BU$1,J$1) -> 728.367 | K17: =SUMIFS($N17:$BU17,$N$1:$BU$1,K$1) -> 957.70136 | L17: =SUMIFS($N17:$BU17,$N$1:$BU$1,L$1) -> 771.04255 | N17: =SUMIFS(Декларации!$O:$O,Декларации!$C:$C,N$1,Декларации!$D:$D,N$2,Декларации!$E:$E,$F17,Декларации!$L:$L,$B17)/1000 -> 10.52 | O17: =SUMIFS(Декларации!$O:$O,Декларации!$C:$C,O$1,Декларации!$D:$D,O$2,Декларации!$E:$E,$F17,Декларации!$L:$L,$B17)/1000 -> 6.303 | P17: =SUMIFS(Декларации!$O:$O,Декларации!$C:$C,P$1,Декларации!$D:$D,P$2,Декларации!$E:$E,$F17,Декларации!$L:$L,$B17)/1000 -> 3.78 | Q17: =SUMIFS(Декларации!$O:$O,Декларации!$C:$C,Q$1,Декларации!$D:$D,Q$2,Декларации!$E:$E,$F17,Декларации!$L:$L,$B17)/1000 -> 6.73 | R17: =SUMIFS(Декларации!$O:$O,Декларации!$C:$C,R$1,Декларации!$D:$D,R$2,Декларации!$E:$E,$F17,Декларации!$L:$L,$B17)/1000 -> 5.00879 | S17: =SUMIFS(Декларации!$O:$O,Декларации!$C:$C,S$1,Декларации!$D:$D,S$2,Декларации!$E:$E,$F17,Декларации!$L:$L,$B17)/1000 -> 8.20018 | T17: =SUMIFS(Декларации!$O:$O,Декларации!$C:$C,T$1,Декларации!$D:$D,T$2,Декларации!$E:$E,$F17,Декларации!$L:$L,$B17)/1000 -> 5.04 | U17: =SUMIFS(Декларации!$O:$O,Декларации!$C:$C,U$1,Декларации!$D:$D,U$2,Декларации!$E:$E,$F17,Декларации!$L:$L,$B17)/1000 -> 28.82 | ... BU17: =SUMIFS(Декларации!$O:$O,Декларации!$C:$C,BU$1,Декларации!$D:$D,BU$2,Декларации!$E:$E,$F17,Декларации!$L:$L,$B17)/1000 -> 82.2
B18: Гороховый концентрат | E18: тонн | F18: ИМ | H18: =SUMIFS($N18:$BU18,$N$1:$BU$1,H$1) -> 548.9 | I18: =SUMIFS($N18:$BU18,$N$1:$BU$1,I$1) -> 303.201 | J18: =SUMIFS($N18:$BU18,$N$1:$BU$1,J$1) -> 975.85405 | K18: =SUMIFS($N18:$BU18,$N$1:$BU$1,K$1) -> 790.7118 | L18: =SUMIFS($N18:$BU18,$N$1:$BU$1,L$1) -> 1174.9395 | N18: =SUMIFS(Декларации!$O:$O,Декларации!$C:$C,N$1,Декларации!$D:$D,N$2,Декларации!$E:$E,$F18,Декларации!$L:$L,$B18)/1000 -> 90 | O18: =SUMIFS(Декларации!$O:$O,Декларации!$C:$C,O$1,Декларации!$D:$D,O$2,Декларации!$E:$E,$F18,Декларации!$L:$L,$B18)/1000 -> 0 | P18: =SUMIFS(Декларации!$O:$O,Декларации!$C:$C,P$1,Декларации!$D:$D,P$2,Декларации!$E:$E,$F18,Декларации!$L:$L,$B18)/1000 -> 112 | Q18: =SUMIFS(Декларации!$O:$O,Декларации!$C:$C,Q$1,Декларации!$D:$D,Q$2,Декларации!$E:$E,$F18,Декларации!$L:$L,$B18)/1000 -> 80 | R18: =SUMIFS(Декларации!$O:$O,Декларации!$C:$C,R$1,Декларации!$D:$D,R$2,Декларации!$E:$E,$F18,Декларации!$L:$L,$B18)/1000 -> 22.2 | S18: =SUMIFS(Декларации!$O:$O,Декларации!$C:$C,S$1,Декларации!$D:$D,S$2,Декларации!$E:$E,$F18,Декларации!$L:$L,$B18)/1000 -> 40.7 | T18: =SUMIFS(Декларации!$O:$O,Декларации!$C:$C,T$1,Декларации!$D:$D,T$2,Декларации!$E:$E,$F18,Декларации!$L:$L,$B18)/1000 -> 62 | U18: =SUMIFS(Декларации!$O:$O,Декларации!$C:$C,U$1,Декларации!$D:$D,U$2,Декларации!$E:$E,$F18,Декларации!$L:$L,$B18)/1000 -> 40 | ... BU18: =SUMIFS(Декларации!$O:$O,Декларации!$C:$C,BU$1,Декларации!$D:$D,BU$2,Декларации!$E:$E,$F18,Декларации!$L:$L,$B18)/1000 -> 244.7836
B19: Всего | E19: тонн | F19: ИМ | H19: =SUMIFS($N19:$BU19,$N$1:$BU$1,H$1) -> 640.41197 | I19: =SUMIFS($N19:$BU19,$N$1:$BU$1,I$1) -> 690.681 | J19: =SUMIFS($N19:$BU19,$N$1:$BU$1,J$1) -> 1704.2211 | K19: =SUMIFS($N19:$BU19,$N$1:$BU$1,K$1) -> 1748.4132 | L19: =SUMIFS($N19:$BU19,$N$1:$BU$1,L$1) -> 1945.9821 | N19: =SUM(N17:N18) -> 100.52 | O19: =SUM(O17:O18) -> 6.303 | P19: =SUM(P17:P18) -> 115.78 | Q19: =SUM(Q17:Q18) -> 86.73 | R19: =SUM(R17:R18) -> 27.20879 | S19: =SUM(S17:S18) -> 48.90018 | T19: =SUM(T17:T18) -> 67.04 | U19: =SUM(U17:U18) -> 68.82 | ... BU19: =SUM(BU17:BU18) -> 326.9836
B21: В деньгах | H21: 9. Прям целиком копируем все расчеты в таблице выше и вставляем сюда | N21: 10. меняем ссылку на столбец - с веса на стоимость
B22: Гороховый изолят | E22: тыс. долл. | F22: ИМ | H22: =SUMIFS($N22:$BU22,$N$1:$BU$1,H$1) -> 412.67531 | I22: =SUMIFS($N22:$BU22,$N$1:$BU$1,I$1) -> 1463.085 | J22: =SUMIFS($N22:$BU22,$N$1:$BU$1,J$1) -> 2760.3047 | K22: =SUMIFS($N22:$BU22,$N$1:$BU$1,K$1) -> 3045.8797 | L22: =SUMIFS($N22:$BU22,$N$1:$BU$1,L$1) -> 2350.0055 | N22: =SUMIFS(Декларации!$P:$P,Декларации!$C:$C,N$1,Декларации!$D:$D,N$2,Декларации!$E:$E,$F22,Декларации!$L:$L,$B22)/1000 -> 37.67208 | O22: =SUMIFS(Декларации!$P:$P,Декларации!$C:$C,O$1,Декларации!$D:$D,O$2,Декларации!$E:$E,$F22,Декларации!$L:$L,$B22)/1000 -> 30.42155 | P22: =SUMIFS(Декларации!$P:$P,Декларации!$C:$C,P$1,Декларации!$D:$D,P$2,Декларации!$E:$E,$F22,Декларации!$L:$L,$B22)/1000 -> 18.41793 | Q22: =SUMIFS(Декларации!$P:$P,Декларации!$C:$C,Q$1,Декларации!$D:$D,Q$2,Декларации!$E:$E,$F22,Декларации!$L:$L,$B22)/1000 -> 35.14405 | R22: =SUMIFS(Декларации!$P:$P,Декларации!$C:$C,R$1,Декларации!$D:$D,R$2,Декларации!$E:$E,$F22,Декларации!$L:$L,$B22)/1000 -> 22.93789 | S22: =SUMIFS(Декларации!$P:$P,Декларации!$C:$C,S$1,Декларации!$D:$D,S$2,Декларации!$E:$E,$F22,Декларации!$L:$L,$B22)/1000 -> 40.4534 | T22: =SUMIFS(Декларации!$P:$P,Декларации!$C:$C,T$1,Декларации!$D:$D,T$2,Декларации!$E:$E,$F22,Декларации!$L:$L,$B22)/1000 -> 25.16574 | U22: =SUMIFS(Декларации!$P:$P,Декларации!$C:$C,U$1,Декларации!$D:$D,U$2,Декларации!$E:$E,$F22,Декларации!$L:$L,$B22)/1000 -> 106.98763 | ... BU22: =SUMIFS(Декларации!$P:$P,Декларации!$C:$C,BU$1,Декларации!$D:$D,BU$2,Декларации!$E:$E,$F22,Декларации!$L:$L,$B22)/1000 -> 240.7527
B23: Гороховый концентрат | E23: тыс. долл. | F23: ИМ | H23: =SUMIFS($N23:$BU23,$N$1:$BU$1,H$1) -> 1833.7213 | I23: =SUMIFS($N23:$BU23,$N$1:$BU$1,I$1) -> 855.42981 | J23: =SUMIFS($N23:$BU23,$N$1:$BU$1,J$1) -> 3358.2656 | K23: =SUMIFS($N23:$BU23,$N$1:$BU$1,K$1) -> 2435.1957 | L23: =SUMIFS($N23:$BU23,$N$1:$BU$1,L$1) -> 3346.3376 | N23: =SUMIFS(Декларации!$P:$P,Декларации!$C:$C,N$1,Декларации!$D:$D,N$2,Декларации!$E:$E,$F23,Декларации!$L:$L,$B23)/1000 -> 331.47394 | O23: =SUMIFS(Декларации!$P:$P,Декларации!$C:$C,O$1,Декларации!$D:$D,O$2,Декларации!$E:$E,$F23,Декларации!$L:$L,$B23)/1000 -> 0 | P23: =SUMIFS(Декларации!$P:$P,Декларации!$C:$C,P$1,Декларации!$D:$D,P$2,Декларации!$E:$E,$F23,Декларации!$L:$L,$B23)/1000 -> 351.84154 | Q23: =SUMIFS(Декларации!$P:$P,Декларации!$C:$C,Q$1,Декларации!$D:$D,Q$2,Декларации!$E:$E,$F23,Декларации!$L:$L,$B23)/1000 -> 270.0488 | R23: =SUMIFS(Декларации!$P:$P,Декларации!$C:$C,R$1,Декларации!$D:$D,R$2,Декларации!$E:$E,$F23,Декларации!$L:$L,$B23)/1000 -> 68.2 | S23: =SUMIFS(Декларации!$P:$P,Декларации!$C:$C,S$1,Декларации!$D:$D,S$2,Декларации!$E:$E,$F23,Декларации!$L:$L,$B23)/1000 -> 136.70943 | T23: =SUMIFS(Декларации!$P:$P,Декларации!$C:$C,T$1,Декларации!$D:$D,T$2,Декларации!$E:$E,$F23,Декларации!$L:$L,$B23)/1000 -> 201.61174 | U23: =SUMIFS(Декларации!$P:$P,Декларации!$C:$C,U$1,Декларации!$D:$D,U$2,Декларации!$E:$E,$F23,Декларации!$L:$L,$B23)/1000 -> 134.41511 | ... BU23: =SUMIFS(Декларации!$P:$P,Декларации!$C:$C,BU$1,Декларации!$D:$D,BU$2,Декларации!$E:$E,$F23,Декларации!$L:$L,$B23)/1000 -> 715.61362
B24: Всего | E24: тыс. долл. | F24: ИМ | H24: =SUMIFS($N24:$BU24,$N$1:$BU$1,H$1) -> 2246.3966 | I24: =SUMIFS($N24:$BU24,$N$1:$BU$1,I$1) -> 2318.5149 | J24: =SUMIFS($N24:$BU24,$N$1:$BU$1,J$1) -> 6118.5703 | K24: =SUMIFS($N24:$BU24,$N$1:$BU$1,K$1) -> 5481.0754 | L24: =SUMIFS($N24:$BU24,$N$1:$BU$1,L$1) -> 5696.3431 | N24: =SUM(N22:N23) -> 369.14602 | O24: =SUM(O22:O23) -> 30.42155 | P24: =SUM(P22:P23) -> 370.25947 | Q24: =SUM(Q22:Q23) -> 305.19285 | R24: =SUM(R22:R23) -> 91.13789 | S24: =SUM(S22:S23) -> 177.16283 | T24: =SUM(T22:T23) -> 226.77748 | U24: =SUM(U22:U23) -> 241.40274 | ... BU24: =SUM(BU22:BU23) -> 956.36632
B26: Цена | N26: 11. Считаем среднюю цену. Обязательно - через "еслиошибка"
B27: Гороховый изолят | E27: долл./кг | F27: ИМ | H27: =IFERROR(H22/H17,0) -> 4.5095227 | I27: =IFERROR(I22/I17,0) -> 3.7758982 | J27: =IFERROR(J22/J17,0) -> 3.7897169 | K27: =IFERROR(K22/K17,0) -> 3.1804066 | L27: =IFERROR(L22/L17,0) -> 3.0478285 | N27: =IFERROR(N22/N17,0) -> 3.5809962 | O27: =IFERROR(O22/O17,0) -> 4.8265191 | P27: =IFERROR(P22/P17,0) -> 4.8724683 | Q27: =IFERROR(Q22/Q17,0) -> 5.2219985 | R27: =IFERROR(R22/R17,0) -> 4.5795272 | S27: =IFERROR(S22/S17,0) -> 4.9332332 | T27: =IFERROR(T22/T17,0) -> 4.9932024 | U27: =IFERROR(U22/U17,0) -> 3.7122703 | ... BU27: =IFERROR(BU22/BU17,0) -> 2.928865
B28: Гороховый концентрат | E28: долл./кг | F28: ИМ | H28: =IFERROR(H23/H18,0) -> 3.3407202 | I28: =IFERROR(I23/I18,0) -> 2.8213291 | J28: =IFERROR(J23/J18,0) -> 3.4413605 | K28: =IFERROR(K23/K18,0) -> 3.0797513 | L28: =IFERROR(L23/L18,0) -> 2.8480935 | N28: =IFERROR(N23/N18,0) -> 3.6830438 | O28: =IFERROR(O23/O18,0) -> 0 | P28: =IFERROR(P23/P18,0) -> 3.1414423 | Q28: =IFERROR(Q23/Q18,0) -> 3.37561 | R28: =IFERROR(R23/R18,0) -> 3.0720721 | S28: =IFERROR(S23/S18,0) -> 3.3589541 | T28: =IFERROR(T23/T18,0) -> 3.2518023 | U28: =IFERROR(U23/U18,0) -> 3.3603778 | ... BU28: =IFERROR(BU23/BU18,0) -> 2.9234541
B29: Всего | E29: долл./кг | F29: ИМ | H29: =IFERROR(H24/H19,0) -> 3.5077368 | I29: =IFERROR(I24/I19,0) -> 3.3568534 | J29: =IFERROR(J24/J19,0) -> 3.5902446 | K29: =IFERROR(K24/K19,0) -> 3.1348857 | L29: =IFERROR(L24/L19,0) -> 2.9272331 | N29: =IFERROR(N24/N19,0) -> 3.6723639 | O29: =IFERROR(O24/O19,0) -> 4.8265191 | P29: =IFERROR(P24/P19,0) -> 3.1979571 | Q29: =IFERROR(Q24/Q19,0) -> 3.5188845 | R29: =IFERROR(R24/R19,0) -> 3.3495753 | S29: =IFERROR(S24/S19,0) -> 3.6229484 | T29: =IFERROR(T24/T19,0) -> 3.382719 | U29: =IFERROR(U24/U19,0) -> 3.5077411 | ... BU29: =IFERROR(BU24/BU19,0) -> 2.9248143
B31: Экспорт
B33: В тоннах | H33: 12. Прям целиком копируем со столбца Н строки 17-29. И все должно нормально сразу посчитаться по экспорту
B34: Гороховый изолят | E34: тонн | F34: ЭК | H34: =SUMIFS($N34:$BU34,$N$1:$BU$1,H$1) -> 0.10231 | I34: =SUMIFS($N34:$BU34,$N$1:$BU$1,I$1) -> 0.00768 | J34: =SUMIFS($N34:$BU34,$N$1:$BU$1,J$1) -> 0 | K34: =SUMIFS($N34:$BU34,$N$1:$BU$1,K$1) -> 0.0511 | L34: =SUMIFS($N34:$BU34,$N$1:$BU$1,L$1) -> 0 | N34: =SUMIFS(Декларации!$O:$O,Декларации!$C:$C,N$1,Декларации!$D:$D,N$2,Декларации!$E:$E,$F34,Декларации!$L:$L,$B34)/1000 -> 0 | O34: =SUMIFS(Декларации!$O:$O,Декларации!$C:$C,O$1,Декларации!$D:$D,O$2,Декларации!$E:$E,$F34,Декларации!$L:$L,$B34)/1000 -> 0 | P34: =SUMIFS(Декларации!$O:$O,Декларации!$C:$C,P$1,Декларации!$D:$D,P$2,Декларации!$E:$E,$F34,Декларации!$L:$L,$B34)/1000 -> 0 | Q34: =SUMIFS(Декларации!$O:$O,Декларации!$C:$C,Q$1,Декларации!$D:$D,Q$2,Декларации!$E:$E,$F34,Декларации!$L:$L,$B34)/1000 -> 0 | R34: =SUMIFS(Декларации!$O:$O,Декларации!$C:$C,R$1,Декларации!$D:$D,R$2,Декларации!$E:$E,$F34,Декларации!$L:$L,$B34)/1000 -> 0 | S34: =SUMIFS(Декларации!$O:$O,Декларации!$C:$C,S$1,Декларации!$D:$D,S$2,Декларации!$E:$E,$F34,Декларации!$L:$L,$B34)/1000 -> 0 | T34: =SUMIFS(Декларации!$O:$O,Декларации!$C:$C,T$1,Декларации!$D:$D,T$2,Декларации!$E:$E,$F34,Декларации!$L:$L,$B34)/1000 -> 0.10231 | U34: =SUMIFS(Декларации!$O:$O,Декларации!$C:$C,U$1,Декларации!$D:$D,U$2,Декларации!$E:$E,$F34,Декларации!$L:$L,$B34)/1000 -> 0 | ... BU34: =SUMIFS(Декларации!$O:$O,Декларации!$C:$C,BU$1,Декларации!$D:$D,BU$2,Декларации!$E:$E,$F34,Декларации!$L:$L,$B34)/1000 -> 0
B35: Гороховый концентрат | E35: тонн | F35: ЭК | H35: =SUMIFS($N35:$BU35,$N$1:$BU$1,H$1) -> 1.87 | I35: =SUMIFS($N35:$BU35,$N$1:$BU$1,I$1) -> 0 | J35: =SUMIFS($N35:$BU35,$N$1:$BU$1,J$1) -> 0.464 | K35: =SUMIFS($N35:$BU35,$N$1:$BU$1,K$1) -> 0 | L35: =SUMIFS($N35:$BU35,$N$1:$BU$1,L$1) -> 0.039 | N35: =SUMIFS(Декларации!$O:$O,Декларации!$C:$C,N$1,Декларации!$D:$D,N$2,Декларации!$E:$E,$F35,Декларации!$L:$L,$B35)/1000 -> 0 | O35: =SUMIFS(Декларации!$O:$O,Декларации!$C:$C,O$1,Декларации!$D:$D,O$2,Декларации!$E:$E,$F35,Декларации!$L:$L,$B35)/1000 -> 0 | P35: =SUMIFS(Декларации!$O:$O,Декларации!$C:$C,P$1,Декларации!$D:$D,P$2,Декларации!$E:$E,$F35,Декларации!$L:$L,$B35)/1000 -> 0 | Q35: =SUMIFS(Декларации!$O:$O,Декларации!$C:$C,Q$1,Декларации!$D:$D,Q$2,Декларации!$E:$E,$F35,Декларации!$L:$L,$B35)/1000 -> 0 | R35: =SUMIFS(Декларации!$O:$O,Декларации!$C:$C,R$1,Декларации!$D:$D,R$2,Декларации!$E:$E,$F35,Декларации!$L:$L,$B35)/1000 -> 0.21 | S35: =SUMIFS(Декларации!$O:$O,Декларации!$C:$C,S$1,Декларации!$D:$D,S$2,Декларации!$E:$E,$F35,Декларации!$L:$L,$B35)/1000 -> 0.58 | T35: =SUMIFS(Декларации!$O:$O,Декларации!$C:$C,T$1,Декларации!$D:$D,T$2,Декларации!$E:$E,$F35,Декларации!$L:$L,$B35)/1000 -> 0 | U35: =SUMIFS(Декларации!$O:$O,Декларации!$C:$C,U$1,Декларации!$D:$D,U$2,Декларации!$E:$E,$F35,Декларации!$L:$L,$B35)/1000 -> 0 | ... BU35: =SUMIFS(Декларации!$O:$O,Декларации!$C:$C,BU$1,Декларации!$D:$D,BU$2,Декларации!$E:$E,$F35,Декларации!$L:$L,$B35)/1000 -> 0.039
B36: Всего | E36: тонн | F36: ЭК | H36: =SUMIFS($N36:$BU36,$N$1:$BU$1,H$1) -> 1.97231 | I36: =SUMIFS($N36:$BU36,$N$1:$BU$1,I$1) -> 0.00768 | J36: =SUMIFS($N36:$BU36,$N$1:$BU$1,J$1) -> 0.464 | K36: =SUMIFS($N36:$BU36,$N$1:$BU$1,K$1) -> 0.0511 | L36: =SUMIFS($N36:$BU36,$N$1:$BU$1,L$1) -> 0.039 | N36: =SUM(N34:N35) -> 0 | O36: =SUM(O34:O35) -> 0 | P36: =SUM(P34:P35) -> 0 | Q36: =SUM(Q34:Q35) -> 0 | R36: =SUM(R34:R35) -> 0.21 | S36: =SUM(S34:S35) -> 0.58 | T36: =SUM(T34:T35) -> 0.10231 | U36: =SUM(U34:U35) -> 0 | ... BU36: =SUM(BU34:BU35) -> 0.039
B38: В деньгах
B39: Гороховый изолят | E39: тыс. долл. | F39: ЭК | H39: =SUMIFS($N39:$BU39,$N$1:$BU$1,H$1) -> 1.89254 | I39: =SUMIFS($N39:$BU39,$N$1:$BU$1,I$1) -> 0.10791 | J39: =SUMIFS($N39:$BU39,$N$1:$BU$1,J$1) -> 0 | K39: =SUMIFS($N39:$BU39,$N$1:$BU$1,K$1) -> 1.34909 | L39: =SUMIFS($N39:$BU39,$N$1:$BU$1,L$1) -> 0 | N39: =SUMIFS(Декларации!$P:$P,Декларации!$C:$C,N$1,Декларации!$D:$D,N$2,Декларации!$E:$E,$F39,Декларации!$L:$L,$B39)/1000 -> 0 | O39: =SUMIFS(Декларации!$P:$P,Декларации!$C:$C,O$1,Декларации!$D:$D,O$2,Декларации!$E:$E,$F39,Декларации!$L:$L,$B39)/1000 -> 0 | P39: =SUMIFS(Декларации!$P:$P,Декларации!$C:$C,P$1,Декларации!$D:$D,P$2,Декларации!$E:$E,$F39,Декларации!$L:$L,$B39)/1000 -> 0 | Q39: =SUMIFS(Декларации!$P:$P,Декларации!$C:$C,Q$1,Декларации!$D:$D,Q$2,Декларации!$E:$E,$F39,Декларации!$L:$L,$B39)/1000 -> 0 | R39: =SUMIFS(Декларации!$P:$P,Декларации!$C:$C,R$1,Декларации!$D:$D,R$2,Декларации!$E:$E,$F39,Декларации!$L:$L,$B39)/1000 -> 0 | S39: =SUMIFS(Декларации!$P:$P,Декларации!$C:$C,S$1,Декларации!$D:$D,S$2,Декларации!$E:$E,$F39,Декларации!$L:$L,$B39)/1000 -> 0 | T39: =SUMIFS(Декларации!$P:$P,Декларации!$C:$C,T$1,Декларации!$D:$D,T$2,Декларации!$E:$E,$F39,Декларации!$L:$L,$B39)/1000 -> 1.89254 | U39: =SUMIFS(Декларации!$P:$P,Декларации!$C:$C,U$1,Декларации!$D:$D,U$2,Декларации!$E:$E,$F39,Декларации!$L:$L,$B39)/1000 -> 0 | ... BU39: =SUMIFS(Декларации!$P:$P,Декларации!$C:$C,BU$1,Декларации!$D:$D,BU$2,Декларации!$E:$E,$F39,Декларации!$L:$L,$B39)/1000 -> 0
B40: Гороховый концентрат | E40: тыс. долл. | F40: ЭК | H40: =SUMIFS($N40:$BU40,$N$1:$BU$1,H$1) -> 8.22991 | I40: =SUMIFS($N40:$BU40,$N$1:$BU$1,I$1) -> 0 | J40: =SUMIFS($N40:$BU40,$N$1:$BU$1,J$1) -> 2.67935 | K40: =SUMIFS($N40:$BU40,$N$1:$BU$1,K$1) -> 0 | L40: =SUMIFS($N40:$BU40,$N$1:$BU$1,L$1) -> 0.13735 | N40: =SUMIFS(Декларации!$P:$P,Декларации!$C:$C,N$1,Декларации!$D:$D,N$2,Декларации!$E:$E,$F40,Декларации!$L:$L,$B40)/1000 -> 0 | O40: =SUMIFS(Декларации!$P:$P,Декларации!$C:$C,O$1,Декларации!$D:$D,O$2,Декларации!$E:$E,$F40,Декларации!$L:$L,$B40)/1000 -> 0 | P40: =SUMIFS(Декларации!$P:$P,Декларации!$C:$C,P$1,Декларации!$D:$D,P$2,Декларации!$E:$E,$F40,Декларации!$L:$L,$B40)/1000 -> 0 | Q40: =SUMIFS(Декларации!$P:$P,Декларации!$C:$C,Q$1,Декларации!$D:$D,Q$2,Декларации!$E:$E,$F40,Декларации!$L:$L,$B40)/1000 -> 0 | R40: =SUMIFS(Декларации!$P:$P,Декларации!$C:$C,R$1,Декларации!$D:$D,R$2,Декларации!$E:$E,$F40,Декларации!$L:$L,$B40)/1000 -> 1.56009 | S40: =SUMIFS(Декларации!$P:$P,Декларации!$C:$C,S$1,Декларации!$D:$D,S$2,Декларации!$E:$E,$F40,Декларации!$L:$L,$B40)/1000 -> 2.21482 | T40: =SUMIFS(Декларации!$P:$P,Декларации!$C:$C,T$1,Декларации!$D:$D,T$2,Декларации!$E:$E,$F40,Декларации!$L:$L,$B40)/1000 -> 0 | U40: =SUMIFS(Декларации!$P:$P,Декларации!$C:$C,U$1,Декларации!$D:$D,U$2,Декларации!$E:$E,$F40,Декларации!$L:$L,$B40)/1000 -> 0 | ... BU40: =SUMIFS(Декларации!$P:$P,Декларации!$C:$C,BU$1,Декларации!$D:$D,BU$2,Декларации!$E:$E,$F40,Декларации!$L:$L,$B40)/1000 -> 0.13735
B41: Всего | E41: тыс. долл. | F41: ЭК | H41: =SUMIFS($N41:$BU41,$N$1:$BU$1,H$1) -> 10.12245 | I41: =SUMIFS($N41:$BU41,$N$1:$BU$1,I$1) -> 0.10791 | J41: =SUMIFS($N41:$BU41,$N$1:$BU$1,J$1) -> 2.67935 | K41: =SUMIFS($N41:$BU41,$N$1:$BU$1,K$1) -> 1.34909 | L41: =SUMIFS($N41:$BU41,$N$1:$BU$1,L$1) -> 0.13735 | N41: =SUM(N39:N40) -> 0 | O41: =SUM(O39:O40) -> 0 | P41: =SUM(P39:P40) -> 0 | Q41: =SUM(Q39:Q40) -> 0 | R41: =SUM(R39:R40) -> 1.56009 | S41: =SUM(S39:S40) -> 2.21482 | T41: =SUM(T39:T40) -> 1.89254 | U41: =SUM(U39:U40) -> 0 | ... BU41: =SUM(BU39:BU40) -> 0.13735
B43: Средневзвешенная цена
B44: Гороховый изолят | E44: долл./кг | F44: ЭК | H44: =IFERROR(H39/H34,0) -> 18.498094 | I44: =IFERROR(I39/I34,0) -> 14.050781 | J44: =IFERROR(J39/J34,0) -> 0 | K44: =IFERROR(K39/K34,0) -> 26.400978 | L44: =IFERROR(L39/L34,0) -> 0 | N44: =IFERROR(N39/N34,0) -> 0 | O44: =IFERROR(O39/O34,0) -> 0 | P44: =IFERROR(P39/P34,0) -> 0 | Q44: =IFERROR(Q39/Q34,0) -> 0 | R44: =IFERROR(R39/R34,0) -> 0 | S44: =IFERROR(S39/S34,0) -> 0 | T44: =IFERROR(T39/T34,0) -> 18.498094 | U44: =IFERROR(U39/U34,0) -> 0 | ... BU44: =IFERROR(BU39/BU34,0) -> 0
B45: Гороховый концентрат | E45: долл./кг | F45: ЭК | H45: =IFERROR(H40/H35,0) -> 4.4010214 | I45: =IFERROR(I40/I35,0) -> 0 | J45: =IFERROR(J40/J35,0) -> 5.7744612 | K45: =IFERROR(K40/K35,0) -> 0 | L45: =IFERROR(L40/L35,0) -> 3.5217949 | N45: =IFERROR(N40/N35,0) -> 0 | O45: =IFERROR(O40/O35,0) -> 0 | P45: =IFERROR(P40/P35,0) -> 0 | Q45: =IFERROR(Q40/Q35,0) -> 0 | R45: =IFERROR(R40/R35,0) -> 7.429 | S45: =IFERROR(S40/S35,0) -> 3.8186552 | T45: =IFERROR(T40/T35,0) -> 0 | U45: =IFERROR(U40/U35,0) -> 0 | ... BU45: =IFERROR(BU40/BU35,0) -> 3.5217949
B46: Всего | E46: долл./кг | F46: ЭК | H46: =IFERROR(H41/H36,0) -> 5.1322814 | I46: =IFERROR(I41/I36,0) -> 14.050781 | J46: =IFERROR(J41/J36,0) -> 5.7744612 | K46: =IFERROR(K41/K36,0) -> 26.400978 | L46: =IFERROR(L41/L36,0) -> 3.5217949 | N46: =IFERROR(N41/N36,0) -> 0 | O46: =IFERROR(O41/O36,0) -> 0 | P46: =IFERROR(P41/P36,0) -> 0 | Q46: =IFERROR(Q41/Q36,0) -> 0 | R46: =IFERROR(R41/R36,0) -> 7.429 | S46: =IFERROR(S41/S36,0) -> 3.8186552 | T46: =IFERROR(T41/T36,0) -> 18.498094 | U46: =IFERROR(U41/U36,0) -> 0 | ... BU46: =IFERROR(BU41/BU36,0) -> 3.5217949
B48: Импорт - в разрезе стран (суммарно - изолят и концентрат)
H49: Дальше, думаю, понятно, как это работает
B50: Доля крупнейшей страны от общего импорта | E50: %
...

Sheet Декларации
C1: 1. Добавляем столбец год | D1: 2. Добавляем столбец месяц | I1: 3. Добавляем расчеты, которые находят нужные слова: 1 - есть, 0 - нет | L1: 4. Собираем столбец с названием продукта. Лучше это делать в одном столбце, чтобы формулу не менять) | M1: 4.1 Либо - можно так 2 столбца сделать, но тогда нужно будет менять формулы на сводном листе
B2: D1 Дата выпуска груза | C2: Год | D2: Месяц | E2: 011 ИМ.ЭК - направление перемещения | F2: 16 Страна происхождения | G2: 17 Страна назначения | H2: 31_1 Описание и характеристика товара | I2: горох | J2: изолят | K2: концентрат | L2: Продукт | M2: Гороховый изолят | N2: Гороховый концентрат | O2: 38 Вес нетто, кг | P2: 46 Статистическая стоимость, долл.
B3: 45588 | C3: =YEAR(B3) -> 2024 | D3: =MONTH(B3) -> 10 | E3: Им | F3: КИТАЙ | G3: РОССИЯ | H3: -НАРЕЗАННЯ СОЕВАЯ СУХАЯ СПАРЖА ФУЧЖУ, СОЕВЫЙ ПРОДУКТ ДЛЯ ПРИГОТОВЛЕНИЯ ГОТОВЫХ БЛЮД ЯПОНСКОЙ КУХНИ ДЛЯ УПОТРЕБЛЕНИЯ В ПИЩУ, НЕ CОДЕРЖИТ ГМО.. | I3: =MIN(1,IFERROR(SEARCH(I$2,$H3),0)) -> 0 | J3: =MIN(1,IFERROR(SEARCH(J$2,$H3),0)) -> 0 | K3: =MIN(1,IFERROR(SEARCH(K$2,$H3),0)) -> 0 | L3: =IF(I3*J3=1,"Гороховый изолят",IF(I3*K3=1,"Гороховый концентрат",0)) -> 0 | M3: =$I3*J3 -> 0 | N3: =$I3*K3 -> 0 | O3: 18000 | P3: 51399.62
B4: 200 | C4: =YEAR(B4) -> 1900 | D4: =MONTH(B4) -> 7 | E4: ЭК | F4: РОССИЯ | G4: ГРУЗИЯ | H4: ТЕКСТУРИРОВАННЫЕ БЕЛКОВЫЕ ПРОДУКТЫ, ПРЕДНАЗНАЧЕННЫЕ ДЛЯ ПРИГОТОВЛЕНИЯ ПИЩИ, А ТАК ЖЕ ДЛЯ ПЕРЕРАБОТКИ В ГОТОВЫЕ БЛЮДА, НЕ СОДЕРЖАТ ГМО: | I4: =MIN(1,IFERROR(SEARCH(I$2,$H4),0)) -> 0 | J4: =MIN(1,IFERROR(SEARCH(J$2,$H4),0)) -> 0 | K4: =MIN(1,IFERROR(SEARCH(K$2,$H4),0)) -> 0 | L4: =IF(I4*J4=1,"Гороховый изолят",IF(I4*K4=1,"Гороховый концентрат",0)) -> 0 | M4: =$I4*J4 -> 0 | N4: =$I4*K4 -> 0 | O4: 200 | P4: 919.93
B5: 10.11.2023 | C5: =YEAR(B5) -> 2023 | D5: =MONTH(B5) -> 11 | E5: ИМ | F5: СОЕДИНЕННЫЕ ШТАТЫ | G5: РОССИЯ | H5: "KERA TEIN Z 1000 SD". СОСТОИТ ИЗ СМЕСИ: ГИДРОЛИЗОВАННЫЙ КЕРАТИН (HYDROLYZED KERATIN) 89% И ВОДА 8% + БЕНЗОАТ НАТРИЯ (SODIUM BENZOATE) 1-3%. ЯВЛЯЕТСЯ АКТИВНЫМ ИНГРЕДИЕНТОМ В КОСМЕТИЧЕСКИХ СРЕДСТВАХ И СРЕДСТВАХ ЛИЧНОЙ ГИГИЕНЫ. ИСПОЛЬЗУЕТСЯ ПРИ ПРОИЗВО | I5: =MIN(1,IFERROR(SEARCH(I$2,$H5),0)) -> 0 | J5: =MIN(1,IFERROR(SEARCH(J$2,$H5),0)) -> 0 | K5: =MIN(1,IFERROR(SEARCH(K$2,$H5),0)) -> 0 | L5: =IF(I5*J5=1,"Гороховый изолят",IF(I5*K5=1,"Гороховый концентрат",0)) -> 0 | M5: =$I5*J5 -> 0 | N5: =$I5*K5 -> 0 | O5: 180 | P5: 17208.79
B6: 18.03.2020 | C6: =YEAR(B6) -> 2020 | D6: =MONTH(B6) -> 3 | E6: ИМ | F6: ФЕДЕРАТИВНАЯ РЕСПУБЛИКА ГЕРМАНИЯ | G6: РОССИЯ | H6: (КФ РОХШТОФФ 65). КОНЦЕНТРАТ СОЕВОГО БЕЛКА. СОСТАВ: КОНЦЕНТРАТ СОЕВОГО БЕЛКА. (КФ РОХШТОФФ 65). КОНЦЕНТРАТ СОЕВОГО БЕЛКА. СОСТАВ: КОНЦЕНТРАТ СОЕВОГО БЕЛКА. НЕ СОДЕРЖ.МОЛОЧНЫХ ЖИРОВ,САХАРОЗЫ,ИЗОГЛЮКОЗЫ,ГЛЮКОЗЫ ИЛИ КРАХМАЛА, ПОЛУЧЕННЫЙ ВОДНОЙ ЭКСТРАКЦИЕЙ, ДЛЯ ИСПОЛЬЗ. В ПИЩ. ПРОМЫШЛЕННОСТИ. KOENIGSHOF GMBH LEBENSMITTELADDITIVE ОТСУТСТВУЕТ KF ROHSTOFF 65 KF ROHSTOFF 65 20 | I6: =MIN(1,IFERROR(SEARCH(I$2,$H6),0)) -> 0 | J6: =MIN(1,IFERROR(SEARCH(J$2,$H6),0)) -> 0 | K6: =MIN(1,IFERROR(SEARCH(K$2,$H6),0)) -> 1 | L6: =IF(I6*J6=1,"Гороховый изолят",IF(I6*K6=1,"Гороховый концентрат",0)) -> 0 | M6: =$I6*J6 -> 0 | N6: =$I6*K6 -> 0 | O6: 20.24 | P6: 79.71
B7: 13.01.2022 | C7: =YEAR(B7) -> 2022 | D7: =MONTH(B7) -> 1 | E7: ИМ | F7: ГЕРМАНИЯ | G7: РОССИЯ | H7: (ТРИПТИЧЕСКИЙ ПЕПТОН ИЗ КАЗЕИНА) ТРИПТОН ДЛЯ БИОХИМИИ, РЕАГЕНТ ДЛЯ НАУЧНО-ИССЛЕДОВАТЕЛЬСКИХ РАБОТ, КАС № 91079-40-2, НЕ ДЛЯ МЕДИЦИНЫ, НЕ ДЛЯ ВЕТЕРИНАРИИ, НЕ ЯВЛЯЕТСЯ ОТХОДАМИ,НЕ ФАРМ. СУБСТАНЦИЯ, БЕЗ СОДЕРЖАНИЯ ЭТИЛОВОГО СПИРТА: | I7: =MIN(1,IFERROR(SEARCH(I$2,$H7),0)) -> 0 | J7: =MIN(1,IFERROR(SEARCH(J$2,$H7),0)) -> 0 | K7: =MIN(1,IFERROR(SEARCH(K$2,$H7),0)) -> 0 | L7: =IF(I7*J7=1,"Гороховый изолят",IF(I7*K7=1,"Гороховый концентрат",0)) -> 0 | M7: =$I7*J7 -> 0 | N7: =$I7*K7 -> 0 | O7: 28 | P7: 1689.43
B8: 45433 | C8: =YEAR(B8) -> 2024 | D8: =MONTH(B8) -> 5 | E8: Им | F8: КИТАЙ | G8: РОССИЯ | H8: <СЫРЬЁ (КОМПОНЕНТЫ) ДЛЯ ПРИМЕНЕНИЯ В ПИЩЕВОЙ ПРОМЫШЛЕННОСТИ>: ГИДРОЛИЗОВАННЫЙ КЕРАТИН. МЕЖДУНАРОДНОЕ (АНГЛИЙСКОЕ) НАЗВАНИЕ: HYDROLIZED KERATIN. СИНОНИM: ГИДРОЛИЗАТ КЕРАТИНА. CAS NO: 92113-31-0. ПАРТИЯ 2024032261. ДАТА ПРОИЗВОДСТВА 22.03.2024, СРОК | I8: =MIN(1,IFERROR(SEARCH(I$2,$H8),0)) -> 0 | J8: =MIN(1,IFERROR(SEARCH(J$2,$H8),0)) -> 0 | K8: =MIN(1,IFERROR(SEARCH(K$2,$H8),0)) -> 0 | L8: =IF(I8*J8=1,"Гороховый изолят",IF(I8*K8=1,"Гороховый концентрат",0)) -> 0 | M8: =$I8*J8 -> 0 | N8: =$I8*K8 -> 0 | O8: 100 | P8: 3353.34
B9: 20.08.2021 | C9: =YEAR(B9) -> 2021 | D9: =MONTH(B9) -> 8 | E9: ИМ | F9: ЯПОНИЯ | G9: РОССИЯ | H9: 1- СЕРТИФИЦИРОВАННЫЕ СТАНДАРТНЫЕ ОБРАЗЦЫ, РАСХОДНЫЙ МАТЕРИАЛ ДЛЯ ПРОВЕДЕНИЯ ЭКСПЕРТИЗЫ КАЧЕСТВА, НЕ ДЛЯ ПРОИЗВОДСТВА ИЛИ ИЗГОТОВЛЕНИЯ ЛЕКАРСТВЕННЫХ СРЕДСТВ, ПРЕПАРАТОВ, НЕ ДЛЯ МЕДИЦИНЫ, НЕ ДЛЯ КЛИНИЧЕСКИХ ИССЛЕДОВАНИЙ, | I9: =MIN(1,IFERROR(SEARCH(I$2,$H9),0)) -> 0 | J9: =MIN(1,IFERROR(SEARCH(J$2,$H9),0)) -> 0 | K9: =MIN(1,IFERROR(SEARCH(K$2,$H9),0)) -> 0 | L9: =IF(I9*J9=1,"Гороховый изолят",IF(I9*K9=1,"Гороховый концентрат",0)) -> 0 | M9: =$I9*J9 -> 0 | N9: =$I9*K9 -> 0 | O9: 1.7 | P9: 13761.87
B10: 7.536 | C10: =YEAR(B10) -> 1900 | D10: =MONTH(B10) -> 1 | E10: ЭК | F10: РОССИЯ | G10: ТАДЖИКИСТАН | H10: БЕЛКОВЫЕ КОНЦЕНТРАТЫ И ТЕКСТУРИРОВАННЫЕ БЕЛКОВЫЕ ВЕЩЕСТВА,НЕ СОДЕРЖ.МОЛОЧНЫХ ЖИРОВ,САХАРОЗЫ,ИЗОГЛЮКОЗЫ,ГЛЮКОЗЫ ИЛИ КРАХМАЛА ИЛИ СОДЕРЖАЩИЕ МЕНЕЕ 1,5 МАС.% МОЛОЧНОГО ЖИРА,5 МАС.% САХАРОЗЫ/ИЗОГЛЮКОЗЫ, 5 МАС.% ГЛЮКОЗЫ ИЛИ КРАХМАЛА: | I10: =MIN(1,IFERROR(SEARCH(I$2,$H10),0)) -> 0 | J10: =MIN(1,IFERROR(SEARCH(J$2,$H10),0)) -> 0 | K10: =MIN(1,IFERROR(SEARCH(K$2,$H10),0)) -> 1 | L10: =IF(I10*J10=1,"Гороховый изолят",IF(I10*K10=1,"Гороховый концентрат",0)) -> 0 | M10: =$I10*J10 -> 0 | N10: =$I10*K10 -> 0 | O10: 7.536 | P10: 104.43
B11: 7.52 | C11: =YEAR(B11) -> 1900 | D11: =MONTH(B11) -> 1 | E11: ЭК | F11: РОССИЯ | G11: ТАДЖИКИСТАН | H11: БЕЛКОВЫЕ КОНЦЕНТРАТЫ И ТЕКСТУРИРОВАННЫЕ БEЛКОВЫЕ ВЕЩЕСТВА: | I11: =MIN(1,IFERROR(SEARCH(I$2,$H11),0)) -> 0 | J11: =MIN(1,IFERROR(SEARCH(J$2,$H11),0)) -> 0 | K11: =MIN(1,IFERROR(SEARCH(K$2,$H11),0)) -> 1 | L11: =IF(I11*J11=1,"Гороховый изолят",IF(I11*K11=1,"Гороховый концентрат",0)) -> 0 | M11: =$I11*J11 -> 0 | N11: =$I11*K11 -> 0 | O11: 7.52 | P11: 123.25
B12: 25.08.2021 | C12: =YEAR(B12) -> 2021 | D12: =MONTH(B12) -> 8 | E12: ИМ | F12: ЯПОНИЯ | G12: РОССИЯ | H12: 1- СЕРТИФИЦИРОВАННЫЕ СТАНДАРТНЫЕ ОБРАЗЦЫ, РАСХОДНЫЙ МАТЕРИАЛ ДЛЯ ПРОВЕДЕНИЯ ЭКСПЕРТИЗЫ КАЧЕСТВА, НЕ ДЛЯ ПРОИЗВОДСТВА ИЛИ ИЗГОТОВЛЕНИЯ ЛЕКАРСТВЕННЫХ СРЕДСТВ, ПРЕПАРАТОВ, НЕ ДЛЯ МЕДИЦИНЫ, НЕ ДЛЯ КЛИНИЧЕСКИХ ИССЛЕДОВАНИЙ, | I12: =MIN(1,IFERROR(SEARCH(I$2,$H12),0)) -> 0 | J12: =MIN(1,IFERROR(SEARCH(J$2,$H12),0)) -> 0 | K12: =MIN(1,IFERROR(SEARCH(K$2,$H12),0)) -> 0 | L12: =IF(I12*J12=1,"Гороховый изолят",IF(I12*K12=1,"Гороховый концентрат",0)) -> 0 | M12: =$I12*J12 -> 0 | N12: =$I12*K12 -> 0 | O12: 1.7 | P12: 13712.57
B13: 23.06.2021 | C13: =YEAR(B13) -> 2021 | D13: =MONTH(B13) -> 6 | E13: ИМ | F13: ГЕРМАНИЯ | G13: РОССИЯ | H13: 1- СЕРТИФИЦИРОВАННЫЕ СТАНДАРТНЫЕ ОБРАЗЦЫ, РАСХОДНЫЙ МАТЕРИАЛ ДЛЯ ПРОВЕДЕНИЯ ЭКСПЕРТИЗЫ КАЧЕСТВА, НЕ ДЛЯ ПРОИЗВОДСТВА ИЛИ ИЗГОТОВЛЕНИЯ ЛЕКАРСТВЕННЫХ СРЕДСТВ, ПРЕПАРАТОВ, НЕ ДЛЯ МЕДИЦИНЫ, НЕ ДЛЯ КЛИНИЧЕСКИХ ИССЛЕДОВАНИЙ, | I13: =MIN(1,IFERROR(SEARCH(I$2,$H13),0)) -> 0 | J13: =MIN(1,IFERROR(SEARCH(J$2,$H13),0)) -> 0 | K13: =MIN(1,IFERROR(SEARCH(K$2,$H13),0)) -> 0 | L13: =IF(I13*J13=1,"Гороховый изолят",IF(I13*K13=1,"Гороховый концентрат",0)) -> 0 | M13: =$I13*J13 -> 0 | N13: =$I13*K13 -> 0 | O13: 1 | P13: 278.91
B14: 23.06.2021 | C14: =YEAR(B14) -> 2021 | D14: =MONTH(B14) -> 6 | E14: ИМ | F14: ЯПОНИЯ | G14: РОССИЯ | H14: 1- СЕРТИФИЦИРОВАННЫЕ СТАНДАРТНЫЕ ОБРАЗЦЫ, РАСХОДНЫЙ МАТЕРИАЛ ДЛЯ ПРОВЕДЕНИЯ ЭКСПЕРТИЗЫ КАЧЕСТВА, НЕ ДЛЯ ПРОИЗВОДСТВА ИЛИ ИЗГОТОВЛЕНИЯ ЛЕКАРСТВЕННЫХ СРЕДСТВ, ПРЕПАРАТОВ, НЕ ДЛЯ МЕДИЦИНЫ, НЕ ДЛЯ КЛИНИЧЕСКИХ ИССЛЕДОВАНИЙ, | I14: =MIN(1,IFERROR(SEARCH(I$2,$H14),0)) -> 0 | J14: =MIN(1,IFERROR(SEARCH(J$2,$H14),0)) -> 0 | K14: =MIN(1,IFERROR(SEARCH(K$2,$H14),0)) -> 0 | L14: =IF(I14*J14=1,"Гороховый изолят",IF(I14*K14=1,"Гороховый концентрат",0)) -> 0 | M14: =$I14*J14 -> 0 | N14: =$I14*K14 -> 0 | O14: 0.15 | P14: 1272.03
B15: 0.3 | C15: =YEAR(B15) -> 1900 | D15: =MONTH(B15) -> 1 | E15: ЭК | F15: РОССИЯ | H15: ПРОИЗВОДНЫЕ БЕЛКОВЫЕ ВЕЩЕСТВА (ПЕПТОНЫ), БЕЗ СОДЕРЖАНИЯ МОЛОЧНЫХ ЖИРОВ, ЭТИЛОВОГО СПИРТА, ПРЕКУРСОРОВ И КОНТРОЛИРУЕМЫХ ВЕЩЕСТВ, ДЛЯ ИСПОЛЬЗОВАНИЯ В МЕДИКО-ДИАГНОСТИЧЕСКИХ ЦЕЛЯХ: ПЕПТОН ФЕРМЕНТАТИВНЫЙ (НИЦФ) ООО НИЦФ ОТСУТСТВУЕТ .25 | I15: =MIN(1,IFERROR(SEARCH(I$2,$H15),0)) -> 0 | J15: =MIN(1,IFERROR(SEARCH(J$2,$H15),0)) -> 0 | K15: =MIN(1,IFERROR(SEARCH(K$2,$H15),0)) -> 0 | L15: =IF(I15*J15=1,"Гороховый изолят",IF(I15*K15=1,"Гороховый концентрат",0)) -> 0 | M15: =$I15*J15 -> 0 | N15: =$I15*K15 -> 0 | O15: 0.3 | P15: 21.97
B16: 23.06.2021 | C16: =YEAR(B16) -> 2021 | D16: =MONTH(B16) -> 6 | E16: ИМ | F16: ЯПОНИЯ | G16: РОССИЯ | H16: 1- СЕРТИФИЦИРОВАННЫЕ СТАНДАРТНЫЕ ОБРАЗЦЫ, РАСХОДНЫЙ МАТЕРИАЛ ДЛЯ ПРОВЕДЕНИЯ ЭКСПЕРТИЗЫ КАЧЕСТВА, НЕ ДЛЯ ПРОИЗВОДСТВА ИЛИ ИЗГОТОВЛЕНИЯ ЛЕКАРСТВЕННЫХ СРЕДСТВ, ПРЕПАРАТОВ, НЕ ДЛЯ МЕДИЦИНЫ, НЕ ДЛЯ КЛИНИЧЕСКИХ ИССЛЕДОВАНИЙ, | I16: =MIN(1,IFERROR(SEARCH(I$2,$H16),0)) -> 0 | J16: =MIN(1,IFERROR(SEARCH(J$2,$H16),0)) -> 0 | K16: =MIN(1,IFERROR(SEARCH(K$2,$H16),0)) -> 0 | L16: =IF(I16*J16=1,"Гороховый изолят",IF(I16*K16=1,"Гороховый концентрат",0)) -> 0 | M16: =$I16*J16 -> 0 | N16: =$I16*K16 -> 0 | O16: 0.01 | P16: 155.46
B17: 45490 | C17: =YEAR(B17) -> 2024 | D17: =MONTH(B17) -> 7 | E17: Им | F17: ШВЕЙЦАРИЯ | G17: РОССИЯ | H17: 100% ГИДРОЛИЗАТ КОЛЛАГЕНА, БЕЛКОВЫЙ ГИДРОЛИЗАТ ГОВЯЖЬЕГО ПРОИСХОЖДЕНИЯ, БИОЛОГИЧЕСКИ АКTИВНАЯ ДОБАВКА (БАД) К ПИЩЕ - ДОПОЛНИТЕЛЬНЫЙ ИСТОЧНИК АМИНОКИСЛОТ, ПОРОШОК В ПЛАСТИКОВЫХ БАНКАХ ПО 310 Г (ВСЕГО 2160 БАНОК), С МЕРНОЙ ЛОЖКОЙ; | I17: =MIN(1,IFERROR(SEARCH(I$2,$H17),0)) -> 0 | J17: =MIN(1,IFERROR(SEARCH(J$2,$H17),0)) -> 0 | K17: =MIN(1,IFERROR(SEARCH(K$2,$H17),0)) -> 0 | L17: =IF(I17*J17=1,"Гороховый изолят",IF(I17*K17=1,"Гороховый концентрат",0)) -> 0 | M17: =$I17*J17 -> 0 | N17: =$I17*K17 -> 0 | O17: 669.6 | P17: 24275.68
B18: 45492 | C18: =YEAR(B18) -> 2024 | D18: =MONTH(B18) -> 7 | E18: Им | F18: ШВЕЙЦАРИЯ | G18: РОССИЯ | H18: 100% ГИДРОЛИЗАТ КОЛЛАГЕНА, БЕЛКОВЫЙ ГИДРОЛИЗАТ ГОВЯЖЬЕГО ПРОИСХОЖДЕНИЯ, БИОЛОГИЧЕСКИ АКТИВНАЯ ДОБАВКА (БАД) К ПИЩЕ - ДОПОЛНИТЕЛЬНЫЙ ИСТОЧНИК АМИНОКИСЛОТ, ПОРОШОК В ПЛАСТИКОВЫХ БАНКАХ ПО 310 Г (ВСЕГО 2160 БАНОК), С МЕРНОЙ ЛОЖКОЙ; | I18: =MIN(1,IFERROR(SEARCH(I$2,$H18),0)) -> 0 | J18: =MIN(1,IFERROR(SEARCH(J$2,$H18),0)) -> 0 | K18: =MIN(1,IFERROR(SEARCH(K$2,$H18),0)) -> 0 | L18: =IF(I18*J18=1,"Гороховый изолят",IF(I18*K18=1,"Гороховый концентрат",0)) -> 0 | M18: =$I18*J18 -> 0 | N18: =$I18*K18 -> 0 | O18: 669.6 | P18: 24333.31
B19: 700 | C19: =YEAR(B19) -> 1901 | D19: =MONTH(B19) -> 11 | E19: ЭК | F19: РОССИЯ | H19: БЕЛОК ЖИВОТНЫЙ ИЗ СВИНОЙ ШКУРЫ, ПРЕДНАЗНАЧЕН ДЛЯ ИСПОЛЬЗОВАНИЯ В КАЧЕСТВЕ ДОБАВКИ В ПИЩЕВОЙ ПРОМЫШЛЕННОСТИ ДЛЯ ИСПОЛЬЗОВАНИЯ В ЭМУЛЬГИРОВАННЫХ МЯСНЫХ СИСТЕМАХ С ПРИМЕНЕНИЕМ КУТТЕРА: БЕЛОК ЖИВОТНЫЙ БЕЛКОТОН А 96 ООО ДБК ОТСУТСТВУЕТ 700 | I19: =MIN(1,IFERROR(SEARCH(I$2,$H19),0)) -> 0 | J19: =MIN(1,IFERROR(SEARCH(J$2,$H19),0)) -> 0 | K19: =MIN(1,IFERROR(SEARCH(K$2,$H19),0)) -> 0 | L19: =IF(I19*J19=1,"Гороховый изолят",IF(I19*K19=1,"Гороховый концентрат",0)) -> 0 | M19: =$I19*J19 -> 0 | N19: =$I19*K19 -> 0 | O19: 700 | P19: 3853.48
B20: 09.07.2022 | C20: =YEAR(B20) -> 2022 | D20: =MONTH(B20) -> 7 | E20: ИМ | F20: СОЕДИНЕННЫЕ ШТАТЫ | G20: РОССИЯ | H20: 1-БЕЛКОВЫЕ КОНЦЕНТРАТЫ И ТЕКСТУРИРОВАННЫЕ БЕЛКОВЫЕ ВЕЩЕСТВА,НЕ СОДЕРЖ.МОЛОЧНЫХ ЖИРОВ,САХАРОЗЫ,ИЗОГЛЮКОЗЫ,ГЛЮКОЗЫ ИЛИ КРАХМАЛА ИЛИ СОДЕРЖАЩИЕ МЕНЕЕ 1,5 МАС.% МОЛОЧНОГО ЖИРА,5 МАС.% САХАРОЗЫ/ИЗОГЛЮКОЗЫ, 5 МАС.% ГЛЮКОЗЫ ИЛИ КРАХМАЛА: | I20: =MIN(1,IFERROR(SEARCH(I$2,$H20),0)) -> 0 | J20: =MIN(1,IFERROR(SEARCH(J$2,$H20),0)) -> 0 | K20: =MIN(1,IFERROR(SEARCH(K$2,$H20),0)) -> 1 | L20: =IF(I20*J20=1,"Гороховый изолят",IF(I20*K20=1,"Гороховый концентрат",0)) -> 0 | M20: =$I20*J20 -> 0 | N20: =$I20*K20 -> 0 | O20: 4989.6 | P20: 30386.66
B21: 45482 | C21: =YEAR(B21) -> 2024 | D21: =MONTH(B21) -> 7 | E21: Им | F21: КИТАЙ | G21: РОССИЯ | H21: 1-КОРМОВАЯ ДОБАВKА: БЕЛОК РАСТИТЕЛЬНЫЙ "МСГ БАЙ-ПРОДУКТ", С МАРКИРОВКОЙ "MSG BY-PRODUCT". СОСТАВ "МСГ БАЙ-ПРОДУКТ" ПРЕДСТАВЛЯЕТ СОБОЙ ПОБОЧНЫЙ ПРОДУКТ КУЛЬТИВИРОВАНИЯ CORYNEBACTERIUM GLUTAMICUM ПРИ ПРОИЗВОДСТВЕ ГЛУТАМИНОВОЙ КИСЛОТЫ. | I21: =MIN(1,IFERROR(SEARCH(I$2,$H21),0)) -> 0 | J21: =MIN(1,IFERROR(SEARCH(J$2,$H21),0)) -> 0 | K21: =MIN(1,IFERROR(SEARCH(K$2,$H21),0)) -> 0 | L21: =IF(I21*J21=1,"Гороховый изолят",IF(I21*K21=1,"Гороховый концентрат",0)) -> 0 | M21: =$I21*J21 -> 0 | N21: =$I21*K21 -> 0 | O21: 65000 | P21: 35328.87
B22: 377.52 | C22: =YEAR(B22) -> 1901 | D22: =MONTH(B22) -> 1 | E22: ЭК | F22: РОССИЯ | H22: ГОТОВЫЕ ПИЩЕВЫЕ ПРОДУКТЫ: ЗАМЕНИТЕЛИ ИКРЫ ЛОСОСЕВЫХ, ПРЕДСТАВЛЯЮТ СОБОЙ БЕЛКОВЫЙ КОНЦЕНТРАТ,НЕ СОДЕРЖАЩИЙ МОЛОЧНЫХ ЖИРОВ, САХАРОЗЫ, ИЗОГЛЮКОЗЫ, ГЛЮКОЗЫ ИЛИ КРАХМАЛА ИЛИ СОДЕРЖАЩИЙ МЕНЕЕ 1,5 МАС% МОЛОЧНОГО ЖИРА, 5 МАС% САХАРОЗЫ ИЛИ ИЗОГЛЮКОЗЫ, 5 ИКРА АНАЛОГ. КРАСНАЯ КЕТА 220 Г С/Б ББ ИКРА АНАЛОГ. КРАСНАЯ ГОРБУША 220 Г С/Б ББ ИКРА АНАЛОГ. КРАСНАЯ ГОРБУША 220 Г С/Б ББ ИКРА АНАЛОГ. КРАСНАЯ КЕТА 220 Г С/Б ББ ИКРА АНАЛОГ. КРАСНАЯ ФОРЕЛЬ 220 Г С/Б ББ ИКРА АНАЛОГ. КРАСНАЯ КЕТА 220 Г С/Б ББ ИКРА АНАЛОГ. КРАСНАЯ НЕРКА 220 Г С/Б ББ ИКРА АНАЛОГ. КРАСНАЯ ФОРЕЛЬ 220 Г С/Б ББ МАС.% ГЛЮКОЗЫ ИЛИ КРАХМАЛА, СФОРМОВАННЫЙ В ШАРИКИ, ВИЗУАЛЬНО СХОДНЫЕ С ИКРОЙ ЛОСОСЕВЫХ РЫБ. ООО ТОРГОВЫЙ ДОМ БАЛТИЙСКИЙ БЕРЕГ БАЛТИЙСКИЙ БЕРЕГ БАЛТИЙСКИЙ БЕРЕГ ОТСУТСТВУЕТ ОТСУТСТВУЕТ 402 ООО ТОРГОВЫЙ ДОМ БАЛТИЙСКИЙ БЕРЕГ БАЛТИЙСКИЙ БЕРЕГ БАЛТИЙСКИЙ БЕРЕГ ОТСУТСТВУЕТ ОТСУТСТВУЕТ 300 ООО ТОРГОВЫЙ ДОМ БАЛТИЙСКИЙ БЕРЕГ БАЛТИЙСКИЙ БЕРЕГ БАЛТИЙСКИЙ БЕРЕГ ОТСУТСТВУЕТ ОТСУТСТВУЕТ 18 ООО ТОРГОВЫЙ ДОМ БАЛТИЙСКИЙ БЕРЕГ БАЛТИЙСКИЙ БЕРЕГ БАЛТИЙСКИЙ БЕРЕГ ОТСУТСТВУЕТ ОТСУТСТВУЕТ 168 ООО ТОРГОВЫЙ ДОМ БАЛТИЙСКИЙ БЕРЕГ БАЛТИЙСКИЙ БЕРЕГ БАЛТИЙСКИЙ БЕРЕГ ОТСУТСТВУЕТ ОТСУТСТВУЕТ 300 ООО ТОРГОВЫЙ ДОМ БАЛТИЙСКИЙ БЕРЕГ БАЛТИЙСКИЙ БЕРЕГ БАЛТИЙСКИЙ БЕРЕГ ОТСУТСТВУЕТ ОТСУТСТВУЕТ 84 ООО ТОРГОВЫЙ ДОМ БАЛТИЙСКИЙ БЕРЕГ БАЛТИЙСКИЙ БЕРЕГ БАЛТИЙСКИЙ БЕРЕГ ОТСУТСТВУЕТ ОТСУТСТВУЕТ 360 ООО ТОРГОВЫЙ ДОМ БАЛТИЙСКИЙ БЕРЕГ БАЛТИЙСКИЙ БЕРЕГ БАЛТИЙСКИЙ БЕРЕГ ОТСУТСТВУЕТ ОТСУТСТВУЕТ 84 | I22: =MIN(1,IFERROR(SEARCH(I$2,$H22),0)) -> 0 | J22: =MIN(1,IFERROR(SEARCH(J$2,$H22),0)) -> 0 | K22: =MIN(1,IFERROR(SEARCH(K$2,$H22),0)) -> 1 | L22: =IF(I22*J22=1,"Гороховый изолят",IF(I22*K22=1,"Гороховый концентрат",0)) -> 0 | M22: =$I22*J22 -> 0 | N22: =$I22*K22 -> 0 | O22: 377.52 | P22: 1154.27
B23: 02.03.2020 | C23: =YEAR(B23) -> 2020 | D23: =MONTH(B23) -> 3 | E23: ИМ | F23: ШВЕЦИЯ | G23: РОССИЯ | H23: 1-ПОРОШКООБРАЗНЫЙ СВИНОЙ БЕЛОК GELIPRO ИЗ СЫРОЙ КОЖИ ДЛЯ ПРОИЗВОДСТВА ЭКСТРУДИРОВАННЫХ СУХИХ КОРМОВ ПРОДУКТ ПОЛУЧАЮТ ПУТЕМ ЭКСТРАКЦИИ ЖИРА ИЗ ИЗМЕЛЬЧЕННОЙ СВИНОЙ НЕДУБЛЕНОЙ КОЖИ С УДАЛЕННОЙ ЩЕТИНОЙ, ОБРАБОТКИ, СУШКИ И РАЗМОЛА СУХОГО БЕЛКА. СОЕДИНЕНИЙ 6-ТИ ВАЛЕНТНОГО ХРОМА И БИОЦИДОВ НЕ СОДЕРЖИТ. ДАННЫЙ ПРОДУКТ ИСПОЛЬЗУЕТСЯ КАК ЗАМЕНИТЕЛЬ МЯСОСЫРЬЯ ПРИ ИЗГОТОВЛЕНИИ СУХИХ КОРМОВ ДЛЯ КОШЕК И СОБАК. ДОБАВЛЕНИЕ ПРОИСХОДИТ НА ЭТАПЕ РЕЦЕПТУРНОЙ КОМПОНОВКИ КОРМА. СОДЕРЖАНИЕ БЕЛКА 83.4%, СОДЕРЖАНИЕ ЖИРА 9.8%. СОДЕРЖАНИЕ СУХОГО ВЕЩЕСТВА 98.1%, СОДЕРЖАНИЕ ЗОЛЫ 5.1%. GELITA SWEDEN AB GELITA 7130010 20080 | I23: =MIN(1,IFERROR(SEARCH(I$2,$H23),0)) -> 0 | J23: =MIN(1,IFERROR(SEARCH(J$2,$H23),0)) -> 0 | K23: =MIN(1,IFERROR(SEARCH(K$2,$H23),0)) -> 0 | L23: =IF(I23*J23=1,"Гороховый изолят",IF(I23*K23=1,"Гороховый концентрат",0)) -> 0 | M23: =$I23*J23 -> 0 | N23: =$I23*K23 -> 0 | O23: 20080 | P23: 25568.93
B24: 12.03.2020 | C24: =YEAR(B24) -> 2020 | D24: =MONTH(B24) -> 3 | E24: ИМ | F24: ШВЕЦИЯ | G24: РОССИЯ | H24: 1-ПОРОШКООБРАЗНЫЙ СВИНОЙ БЕЛОК GELIPRO ИЗ СЫРОЙ КОЖИ ДЛЯ ПРОИЗВОДСТВА ЭКСТРУДИРОВАННЫХ СУХИХ КОРМОВ; ПРОДУКТ ПОЛУЧАЮТ ПУТЕМ ЭКСТРАКЦИИ ЖИРА ИЗ ИЗМЕЛЬЧЕННОЙ СВИНОЙ НЕДУБЛЕНОЙ КОЖИ С УДАЛЕННОЙ ЩЕТИНОЙ, ОБРАБОТКИ, СУШКИ И РАЗМОЛА СУХОГО БЕЛКА. СОЕДИНЕНИЙ 6-ТИ ВАЛЕНТНОГО ХРОМА И БИОЦИДОВ НЕ СОДЕРЖИТ. ДАННЫЙ ПРОДУКТ ИСПОЛЬЗУЕТСЯ КАК ЗАМЕНИТЕЛЬ МЯСОСЫРЬЯ ПРИ ИЗГОТОВЛЕНИИ СУХИХ КОРМОВ ДЛЯ КОШЕК И СОБАК. ДОБАВЛЕНИЕ ПРОИСХОДИТ НА ЭТАПЕ РЕЦЕПТУРНОЙ КОМПОНОВКИ КОРМА. СОДЕРЖАНИЕ БЕЛКА 83.4%, СОДЕРЖАНИЕ ЖИРА 9.8%. СОДЕРЖАНИЕ СУХОГО ВЕЩЕСТВА 98.1%, СОДЕРЖАНИЕ ЗОЛЫ 5.1%. GELITA SWEDEN AB GELITA 7130010 20060 | I24: =MIN(1,IFERROR(SEARCH(I$2,$H24),0)) -> 0 | J24: =MIN(1,IFERROR(SEARCH(J$2,$H24),0)) -> 0 | K24: =MIN(1,IFERROR(SEARCH(K$2,$H24),0)) -> 0 | L24: =IF(I24*J24=1,"Гороховый изолят",IF(I24*K24=1,"Гороховый концентрат",0)) -> 0 | M24: =$I24*J24 -> 0 | N24: =$I24*K24 -> 0 | O24: 20060 | P24: 26311.75
B25: 26.11.2020 | C25: =YEAR(B25) -> 2020 | D25: =MONTH(B25) -> 11 | E25: ИМ | F25: СОЕДИНЕННОЕ КОРОЛЕВСТВО | G25: РОССИЯ | H25: 693623 EXTRUDED SOYA 9403-ТЕКСТУРИРОВАННАЯ СОЕВАЯ МУКА ДЛЯ ИСПОЛЬЗОВАНИЯ В ПИЩЕВОЙ ПРОМЫШЛЕННОСТИ ПРИ ПРОИЗВОДСТВЕ ПИЩЕВЫХ ПРОДУКТОВ.УПАКОВАНА В МЕШОК ПО 10 КГ. НЕ СОДЕРЖИТ ГМО,МОЛОЧНЫХ,ЖИРОВ,САХАРОЗЫ, ИЗОГЛЮКОЗЫ, ГЛЮКОЗЫ,КРАХМАЛА. ПРЕДНАЗНАЧЕНА ДЛЯ | I25: =MIN(1,IFERROR(SEARCH(I$2,$H25),0)) -> 0 | J25: =MIN(1,IFERROR(SEARCH(J$2,$H25),0)) -> 0 | K25: =MIN(1,IFERROR(SEARCH(K$2,$H25),0)) -> 0 | L25: =IF(I25*J25=1,"Гороховый изолят",IF(I25*K25=1,"Гороховый концентрат",0)) -> 0 | M25: =$I25*J25 -> 0 | N25: =$I25*K25 -> 0 | O25: 10 | P25: 54.24
B26: 15.02.2021 | C26: =YEAR(B26) -> 2021 | D26: =MONTH(B26) -> 2 | E26: ИМ | F26: СОЕДИНЕННОЕ КОРОЛЕВСТВО | G26: РОССИЯ | H26: 693623 EXTRUDED SOYA 9403-ТЕКСТУРИРОВАННАЯ СОЕВАЯ МУКА ДЛЯ ИСПОЛЬЗОВАНИЯ В ПИЩЕВОЙ ПРОМЫШЛЕННОСТИ ПРИ ПРОИЗВОДСТВЕ ПИЩЕВЫХ ПРОДУКТОВ.УПАКОВАНА В МЕШОК ПО 10 КГ. НЕ СОДЕРЖИТ ГМО,МОЛОЧНЫХ,ЖИРОВ,САХАРОЗЫ, ИЗОГЛЮКОЗЫ, ГЛЮКОЗЫ,КРАХМАЛА. ПРЕДНАЗНАЧЕНА ДЛЯ | I26: =MIN(1,IFERROR(SEARCH(I$2,$H26),0)) -> 0 | J26: =MIN(1,IFERROR(SEARCH(J$2,$H26),0)) -> 0 | K26: =MIN(1,IFERROR(SEARCH(K$2,$H26),0)) -> 0 | L26: =IF(I26*J26=1,"Гороховый изолят",IF(I26*K26=1,"Гороховый концентрат",0)) -> 0 | M26: =$I26*J26 -> 0 | N26: =$I26*K26 -> 0 | O26: 70 | P26: 171.6
B27: 09.06.2023 | C27: =YEAR(B27) -> 2023 | D27: =MONTH(B27) -> 6 | E27: ИМ | F27: СОЕДИНЕННЫЕ ШТАТЫ | G27: РОССИЯ | H27: B- ЛАКТОГЛОБУЛИН , ИЗ КОРОВЬЕГО МОЛОКА, ЛАБОРАТОРНЫЙ РЕАГЕНТ ДЛЯ ПРОВЕДЕНИЯ ЛАБОРАТОРНЫХ И НАУЧНО-ИССЛЕДОВАТЕЛЬСКИХ РАБОТ. РАЗРЕШЕНИЕ ФС/УВН-03/ 596100 ОТ <23> МАРТА 2023 Г., СРОКИ ГОДНОСТИ ОТ 15.07.2021 ДО 07.2025, KАС № 9045-23-2, НЕ ДЛЯ МЕДИЦИНЫ, | I27: =MIN(1,IFERROR(SEARCH(I$2,$H27),0)) -> 0 | J27: =MIN(1,IFERROR(SEARCH(J$2,$H27),0)) -> 0 | K27: =MIN(1,IFERROR(SEARCH(K$2,$H27),0)) -> 0 | L27: =IF(I27*J27=1,"Гороховый изолят",IF(I27*K27=1,"Гороховый концентрат",0)) -> 0 | M27: =$I27*J27 -> 0 | N27: =$I27*K27 -> 0 | O27: 0.001 | P27: 398.68
B28: 23.04.2021 | C28: =YEAR(B28) -> 2021 | D28: =MONTH(B28) -> 4 | E28: ИМ | F28: СОЕДИНЕННЫЕ ШТАТЫ | G28: РОССИЯ | H28: BACTO МЯСНОЙ ЭКСТРАКТ, СУХОЙ, ЛАБОРАТОРНЫЙ РЕАКТИВ, НЕ ДЛЯ МЕДИЦИНЫ, НЕ ДЛЯ ВЕТЕРИНАРИИ, НЕ ЯВЛЯЕТСЯ ОТХОДАМИ,НЕ ФАРМ. СУБСТАНЦИЯ, БЕЗ СОДЕРЖАНИЯ ЭТИЛОВОГО СПИРТА: | I28: =MIN(1,IFERROR(SEARCH(I$2,$H28),0)) -> 0 | J28: =MIN(1,IFERROR(SEARCH(J$2,$H28),0)) -> 0 | K28: =MIN(1,IFERROR(SEARCH(K$2,$H28),0)) -> 0 | L28: =IF(I28*J28=1,"Гороховый изолят",IF(I28*K28=1,"Гороховый концентрат",0)) -> 0 | M28: =$I28*J28 -> 0 | N28: =$I28*K28 -> 0 | O28: 1.9 | P28: 310.69
B29: 12.01.2022 | C29: =YEAR(B29) -> 2022 | D29: =MONTH(B29) -> 1 | E29: ИМ | F29: СОЕДИНЕННЫЕ ШТАТЫ | G29: РОССИЯ | H29: BАСТО МЯСНОЙ ПЕПТОН, ДЛЯ МИКРОБИОЛОГИИ, 500 Г, ЛАБОРАТОРНЫЙРЕАГЕНТ ДЛЯ ПРОВЕДЕНИЯ ЛАБОРАТОРНЫХ И НАУЧНО-ИССЛЕДОВАТЕЛЬСКИХ РАБОТ, КАС № 73049-73-7, НЕ ДЛЯ МЕДИЦИНЫ, НЕ ДЛЯ ВЕТЕРИНАРИИ, НЕ ЯВЛЯЕТСЯ ОТХОДАМИ,НЕ ФАРМ. СУБСТАНЦИЯ, БЕЗ СОДЕРЖАНИЯ | I29: =MIN(1,IFERROR(SEARCH(I$2,$H29),0)) -> 0 | J29: =MIN(1,IFERROR(SEARCH(J$2,$H29),0)) -> 0 | K29: =MIN(1,IFERROR(SEARCH(K$2,$H29),0)) -> 0 | L29: =IF(I29*J29=1,"Гороховый изолят",IF(I29*K29=1,"Гороховый концентрат",0)) -> 0 | M29: =$I29*J29 -> 0 | N29: =$I29*K29 -> 0 | O29: 4.4 | P29: 1413.35
B30: 13.07.2021 | C30: =YEAR(B30) -> 2021 | D30: =MONTH(B30) -> 7 | E30: ИМ | F30: ФРАНЦИЯ | G30: РОССИЯ | H30: BАСТО ТРИПТИЧЕСКИЙ ПЕПТОН ИЗ КАЗЕИНА (ТРИПТОН), ДЛЯ МИКРОБИОЛОГИИ, 10 КГ, ЛАБОРАТОРНЫЙ РЕАКТИВ, КАС № 91079-40-2, НЕ ДЛЯ МЕДИЦИНЫ, НЕ ДЛЯ ВЕТЕРИНАРИИ, НЕ ЯВЛЯЕТСЯ ОТХОДАМИ,НЕ ФАРМ. СУБСТАНЦИЯ, БЕЗ СОДЕРЖАНИЯ ЭТИЛОВОГО СПИРТА: | I30: =MIN(1,IFERROR(SEARCH(I$2,$H30),0)) -> 0 | J30: =MIN(1,IFERROR(SEARCH(J$2,$H30),0)) -> 0 | K30: =MIN(1,IFERROR(SEARCH(K$2,$H30),0)) -> 0 | L30: =IF(I30*J30=1,"Гороховый изолят",IF(I30*K30=1,"Гороховый концентрат",0)) -> 0 | M30: =$I30*J30 -> 0 | N30: =$I30*K30 -> 0 | O30: 24 | P30: 4152.09
B31: 4813.68 | C31: =YEAR(B31) -> 1913 | D31: =MONTH(B31) -> 3 | E31: ЭК | F31: ИТАЛЬЯНСКАЯ РЕСПУБЛИКА | H31: СПЕЦИАЛИЗИРОВАННЫЙ ПИЩЕВОЙ ПРОДУКТ ДЛЯ ДИЕТИЧЕСКОГО И ПРОФИЛАКТИЧЕСКОГО ПИТАНИЯ ФОРМУЛА 3 ПРОДУКТ БЕЛКОВЫЙ СПЕЦИАЛИЗИРОВАННЫЙ СУХОЙ ПОРОШКООБРАЗНЫЙ БЕЛКОВЫЙ ПРОДУКТ В УПАКОВКЕ ДЛЯ РОЗНИЧНОЙ ПРОДАЖИ НА ОСНОВЕ СОЕВОГО БЕЛКА С ДОБАВЛЕНИЕМ НЕЗНАЧИТЕЛЬН :СОСТАВ: ИЗОЛЯТ СОЕВОГО БЕЛКА, МОЛОЧНЫЙ БЕЛОК, ВАНИЛИН, АНТИСЛЕЖИВАЮЩИЙ АГЕНТ (КРЕМНИЯ ДИОКСИД), АРОМАТИЗАТОР (АРОМАТИЗАТОРЫ, СТАБИЛИЗАТОР: ГУММИАРАБИК). РАСФАСОВАНО В ПЛАСТИКОВЫЕ БАНКИ ПО 240ГР. (НЕТТО). ОГО КОЛИЧЕСТВА МОЛОЧНОГО БЕЛКА (СУММАРНЫМ СОДЕРЖАНИЕМ 82.2 МАС.%), СОДЕРЖАЩИЙ В СВОЕМ СОСТАВЕ ЖИРОВОЙ КОМПОНЕНТ 4,9 МАС.% ЛАКТОЗУ ИЗ СОСТАВА МОЛОЧНОГО СЫРЬЯ (1,0 МАС.%) , АРОМАТООБРАЗЮЩИЙ КОМПОНЕНТ (ВАНИЛИН) И ПРОЧИЕ ФУНКЦИОНАЛЬНЫЕ ДОБАВКИ (СОГЛАСНО ДАННЫМ С ЭТИКЕТКИ ТОВАРА- КРЕМНИЯ ДИОКСИД (АНТИСЛЕЖИВАЮЩИЙ АГЕНТ), ГУММИАРАБИК (СТАБИЛИЗАТОР), СОДЕРЖАНИЕ МОЛОЧНОГО ЖИРАИЗ СОСТАВА МОЛОЧНОГО СЫРЬЯ СОСТАВЛЯЕТ МЕНЕЕ 1,5 МАС. % (ФАКТИЧЕСКИ 0,5 МАС.%), НЕ СОДЕРЖИТ В СОСТАВЕ КРАХМАЛ И ПРОДУКТЫЕГО ГИДРОЛИ ЗА, ГЛЮКОЗУ, ФРУКТОЗУ, САХАРОЗУ. РАСФАСОВАНО В ПЛАСТИКОВЫЕ БАНКИ ПО 240ГР. (НЕТТО) FINE FOODS NTM S.P.A HERBALIFE ФОРМУЛА 3 ПРОДУКТ БЕЛКОВЫЙ СПЕЦИАЛИЗИРОВАННЫЙ 0242RS ОТСУТСТВУЕТ 15528 | I31: =MIN(1,IFERROR(SEARCH(I$2,$H31),0)) -> 0 | J31: =MIN(1,IFERROR(SEARCH(J$2,$H31),0)) -> 1 | K31: =MIN(1,IFERROR(SEARCH(K$2,$H31),0)) -> 0 | L31: =IF(I31*J31=1,"Гороховый изолят",IF(I31*K31=1,"Гороховый концентрат",0)) -> 0 | M31: =$I31*J31 -> 0 | N31: =$I31*K31 -> 0 | O31: 4813.68 | P31: 29504.56
B32: 04.05.2022 | C32: =YEAR(B32) -> 2022 | D32: =MONTH(B32) -> 5 | E32: ИМ | F32: СОЕДИНЕННЫЕ ШТАТЫ | G32: РОССИЯ | H32: BАСТО ТРИПТИЧЕСКИЙ ПЕПТОН ИЗ КАЗЕИНА (ТРИПТОН),ЛАБОРАТОРНЫЙРЕАГЕНТ ДЛЯ ПРОВЕДЕНИЯ ЛАБОРАТОРНЫХ И НАУЧНО-ИССЛЕДОВАТЕЛЬСКИХ РАБОТ, КАС № 91079-40-2, НЕ ДЛЯ МЕДИЦИНЫ, НЕ ДЛЯ ВЕТЕРИНАРИИ, НЕ ЯВЛЯЕТСЯ ОТХОДАМИ,НЕ ФАРМ. СУБСТАНЦИЯ, БЕЗ СОДЕРЖАНИЯ ЭТИЛОВОГО | I32: =MIN(1,IFERROR(SEARCH(I$2,$H32),0)) -> 0 | J32: =MIN(1,IFERROR(SEARCH(J$2,$H32),0)) -> 0 | K32: =MIN(1,IFERROR(SEARCH(K$2,$H32),0)) -> 0 | L32: =IF(I32*J32=1,"Гороховый изолят",IF(I32*K32=1,"Гороховый концентрат",0)) -> 0 | M32: =$I32*J32 -> 0 | N32: =$I32*K32 -> 0 | O32: 0.8 | P32: 247.61
B33: 17008 | C33: =YEAR(B33) -> 1946 | D33: =MONTH(B33) -> 7 | E33: ЭК | F33: РОССИЯ | H33: МУКА СОЕВАЯ ТЕКСТУРИРОВАННАЯ РОССТЕКС Ф 3-5/Р2, С СОДЕРЖАНИЕМ БЕЛКА НЕ МЕНЕЕ 47%, СЫРОГО ЖИРА НЕ БОЛЕЕ 2.0 %, ПРЕДНАЗНАЧЕННАЯ ДЛЯ ПРИГОТОВЛЕНИЯ ПИЩИ, А ТАК ЖЕ ДЛЯ ПЕРЕРАБОТКИ В ГОТОВЫЕ БЛЮДА - 17008 КГ (1063 МЕШКА ПО 16 КГ). : ЗАО ПАРТНЕР-М ОТСУТСТВУЕТ 0 | I33: =MIN(1,IFERROR(SEARCH(I$2,$H33),0)) -> 0 | J33: =MIN(1,IFERROR(SEARCH(J$2,$H33),0)) -> 0 | K33: =MIN(1,IFERROR(SEARCH(K$2,$H33),0)) -> 0 | L33: =IF(I33*J33=1,"Гороховый изолят",IF(I33*K33=1,"Гороховый концентрат",0)) -> 0 | M33: =$I33*J33 -> 0 | N33: =$I33*K33 -> 0 | O33: 17008 | P33: 13807.05
B34: 17008 | C34: =YEAR(B34) -> 1946 | D34: =MONTH(B34) -> 7 | E34: ЭК | F34: РОССИЯ | H34: МУКА СОЕВАЯ ТЕКСТУРИРОВАННАЯ РОССТЕКС Ф 3-5/Р2, С СОДЕРЖАНИЕМ БЕЛКА НЕ МЕНЕЕ 47%, СЫРОГО ЖИРА НЕ БОЛЕЕ 2.0 %, ПРЕДНАЗНАЧЕННАЯ ДЛЯ ПРИГОТОВЛЕНИЯ ПИЩИ, А ТАК ЖЕ ДЛЯ ПЕРЕРАБОТКИ В ГОТОВЫЕ БЛЮДА - 17008 КГ (1063 МЕШКА ПО 16 КГ). : ЗАО ПАРТНЕР-М ОТСУТСТВУЕТ 0 | I34: =MIN(1,IFERROR(SEARCH(I$2,$H34),0)) -> 0 | J34: =MIN(1,IFERROR(SEARCH(J$2,$H34),0)) -> 0 | K34: =MIN(1,IFERROR(SEARCH(K$2,$H34),0)) -> 0 | L34: =IF(I34*J34=1,"Гороховый изолят",IF(I34*K34=1,"Гороховый концентрат",0)) -> 0 | M34: =$I34*J34 -> 0 | N34: =$I34*K34 -> 0 | O34: 17008 | P34: 12811.27
B35: 16848 | C35: =YEAR(B35) -> 1946 | D35: =MONTH(B35) -> 2 | E35: ЭК | F35: РОССИЯ | H35: МУКА СОЕВАЯ ТЕКСТУРИРОВАННАЯ РОССТЕКС Ф 3-5/Р2, С СОДЕРЖАНИЕМ БЕЛКА НЕ МЕНЕЕ 47%, СЫРОГО ЖИРА НЕ БОЛЕЕ 2.0 %, ПРЕДНАЗНАЧЕННАЯ ДЛЯ ПРИГОТОВЛЕНИЯ ПИЩИ, А ТАК ЖЕ ДЛЯ ПЕРЕРАБОТКИ В ГОТОВЫЕ БЛЮДА - 16848 КГ (1053 МЕШКА ПО 16 КГ). : ЗАО ПАРТНЕР-М ОТСУТСТВУЕТ 0 | I35: =MIN(1,IFERROR(SEARCH(I$2,$H35),0)) -> 0 | J35: =MIN(1,IFERROR(SEARCH(J$2,$H35),0)) -> 0 | K35: =MIN(1,IFERROR(SEARCH(K$2,$H35),0)) -> 0 | L35: =IF(I35*J35=1,"Гороховый изолят",IF(I35*K35=1,"Гороховый концентрат",0)) -> 0 | M35: =$I35*J35 -> 0 | N35: =$I35*K35 -> 0 | O35: 16848 | P35: 13286.94
B36: 24.11.2022 | C36: =YEAR(B36) -> 2022 | D36: =MONTH(B36) -> 11 | E36: ИМ | F36: ФРАНЦИЯ | G36: РОССИЯ | H36: COLLAGENNA H - ВОДНЫЙ РАСТВОР МОРСКОГО ГИДРОЛИЗОВАННОГО КОЛЛАГЕНА, ЭКСТРАГИРОВАННОГО ИЗ КОЖИ РЫБЫ,ПРИМЕНЯЕТСЯ В КОСМЕТИЧЕСКОЙ ПРОМЫШЛЕННОСТИ В КАЧЕСТВЕ СЫРЬЯ ПРИ ПРОИЗВОДСТВЕ СРЕДСТВ ПО УХОДУ ЗА КОЖЕЙ: | I36: =MIN(1,IFERROR(SEARCH(I$2,$H36),0)) -> 0 | J36: =MIN(1,IFERROR(SEARCH(J$2,$H36),0)) -> 0 | K36: =MIN(1,IFERROR(SEARCH(K$2,$H36),0)) -> 0 | L36: =IF(I36*J36=1,"Гороховый изолят",IF(I36*K36=1,"Гороховый концентрат",0)) -> 0 | M36: =$I36*J36 -> 0 | N36: =$I36*K36 -> 0 | O36: 25 | P36: 444.76
B37: 30.06.2020 | C37: =YEAR(B37) -> 2020 | D37: =MONTH(B37) -> 6 | E37: ИМ | F37: СОЕДИНЕННОЕ КОРОЛЕВСТВО | G37: РОССИЯ | H37: CROTEIN C-PW-(WD).ГИДРОЛИЗОВАННЫЙ КОЛЛАГЕН. АРТИКУЛ IDH68292.1 МЕШОК ПО 25 КГ. ПРИМЕНЯЕТСЯ В КОСМЕТИЧЕСКОЙ ПРОМЫШЛЕННОСТИ. НЕ ДЛЯ ПИЩ., НЕ ДЛЯ ЛЕК., НЕ ДЛЯ ВЕТ. : CRODA EUROPE LIMITED ОТСУТСТВУЕТ IDH68292 25 | I37: =MIN(1,IFERROR(SEARCH(I$2,$H37),0)) -> 0 | J37: =MIN(1,IFERROR(SEARCH(J$2,$H37),0)) -> 0 | K37: =MIN(1,IFERROR(SEARCH(K$2,$H37),0)) -> 0 | L37: =IF(I37*J37=1,"Гороховый изолят",IF(I37*K37=1,"Гороховый концентрат",0)) -> 0 | M37: =$I37*J37 -> 0 | N37: =$I37*K37 -> 0 | O37: 25 | P37: 465.49
B38: 03.04.2020 | C38: =YEAR(B38) -> 2020 | D38: =MONTH(B38) -> 4 | E38: ИМ | F38: КИТАЙ | G38: РОССИЯ | H38: CYTOCHROME C FROM BOVINE HEART/ ЦИТОХРОМ С ИЗ БЫЧЬЕГО СЕРДЦА, НОМЕР ПАРТИИ (СЕРИЯ) DCY200201(P), CAS N 9007-43-6, ВСЕГО 1 УПАКОВКА (ДВОЙНОЙ ПОЛИЭТИЛЕНОВЫЙ ПАКЕТ В АЛЮМИНИЕВОМ ПАКЕТЕ): ВЕС ВЕЩЕСТВА 50 ГРАММ -СУБСТАНЦИЯ-ПОРОШОК В КАЧЕСТВЕ ОБРАЗЦА ДЛЯ И : CYTOCHROME C FROM BOVINE HEART/ ЦИТОХРОМ С ИЗ БЫЧЬЕГО СЕРДЦА, НОМЕР ПАРТИИ (СЕРИЯ) DCY200201(P), CAS N 9007-43-6, ВСЕГО 1 УПАКОВКА (ДВОЙНОЙ ПОЛИЭТИЛЕНОВЫЙ ПАКЕТ В АЛЮМИНИЕВОМ ПАКЕТЕ): ВЕС ВЕЩЕСТВА 50 ГРАММ -СУБСТАНЦИЯ-ПОРОШОК В КАЧЕСТВЕОБРАЗЦА ДЛЯ ИСПЫТАНИЙ, ИЗУЧЕНИЙ 15 ГРАММ - ИЗУЧЕНИЕ МИКРОБИОЛОГИЧЕСКИХ СВОЙСТВ ВЕЩЕСТВА 10 ГРАММ - ИЗУЧЕНИЕ ИЗМЕНЧИВОСТИ ФИЗИКО-ХИМИЧЕСКИХ ПАРАМЕТРОВ ВЕЩЕСТВА 25 ГРАММ - ИЗУЧЕНИЕ УСТОЙЧИВОСТИ И СТАБИЛЬНОСТИ ВЕЩЕСТВА В РАЗЛИЧНЫХ УСЛОВИЯХ СПЫТАНИЙ, ИЗУЧЕНИЙ, ЦЕЛЬ ВВОЗА: ИСПОЛЬЗОВАНИЕ В НАУЧНЫХ ЦЕЛЯХ В КАЧЕСТВЕ ЛАБОРАТОРНОГО РЕАКТИВА, НЕ ЯВЛЯЮТСЯ ЛЕКАРСТВЕННЫМИ СРЕДСТВАМИ И ФАРМАЦЕВТИЧЕСКИМИ СУБСТАНЦИЯМИ. НЕ ДЛЯ ВЕТЕРИНАРИИ. НЕ СОДЕРЖАТ ЭТИЛОВОГО СПИРТА. ЦЕЛЬ ИССЛЕДОВАНИЙ: ИССЛЕДОВАНИЕ ЭФФЕКТИВНОСТИ, БЕЗОПАСНОСТИ, МИКРОБИОЛОГИЧЕСКИХ СВОЙСТВ, ИЗМЕНЧИВОСТИ ФИЗИКО-ХИМИЧЕСКИХ ПАРАМЕТРОВ ВЕЩЕСТВА, УСТОЙЧИВОСТИ И СТАБИЛЬНОСТИ ВЕЩЕСТВА В РАЗЛИЧНЫХ УСЛОВИЯХ. НЕ БУДЕТ ПРИМЕНЕНО ДЛЯ ПРОИЗВОДСТВА ПРОДУКЦИИ. ZHEJIANG JIANFENG INTERNATIONAL TRADE CO., LTD ОТСУТСТВУЕТ ОТСУТСТВУЕТ ОТСУТСТВУЕТ ОТСУТСТВУЕТ 50 | I38: =MIN(1,IFERROR(SEARCH(I$2,$H38),0)) -> 0 | J38: =MIN(1,IFERROR(SEARCH(J$2,$H38),0)) -> 0 | K38: =MIN(1,IFERROR(SEARCH(K$2,$H38),0)) -> 0 | L38: =IF(I38*J38=1,"Гороховый изолят",IF(I38*K38=1,"Гороховый концентрат",0)) -> 0 | M38: =$I38*J38 -> 0 | N38: =$I38*K38 -> 0 | O38: 0.8 | P38: 3650
B39: 45367 | C39: =YEAR(B39) -> 2024 | D39: =MONTH(B39) -> 3 | E39: Им | F39: КИТАЙ | G39: РОССИЯ | H39: CПАРЖА СУХАЯ СОЕВАЯ, В УПАКОВКАХ ИЗ ПОЛИМЕРНЫХ МАТЕРИАЛОВ, В КАРТОННЫХ КОРОБКАХ МАССОЙ НЕТТО 9 КГ С МАРКИРОВКОЙ SUIFENHE DAYUAN GREEN FOOD CO., LTD. | I39: =MIN(1,IFERROR(SEARCH(I$2,$H39),0)) -> 0 | J39: =MIN(1,IFERROR(SEARCH(J$2,$H39),0)) -> 0 | K39: =MIN(1,IFERROR(SEARCH(K$2,$H39),0)) -> 0 | L39: =IF(I39*J39=1,"Гороховый изолят",IF(I39*K39=1,"Гороховый концентрат",0)) -> 0 | M39: =$I39*J39 -> 0 | N39: =$I39*K39 -> 0 | O39: 23400 | P39: 49893.7
B40: 25.09.2020 | C40: =YEAR(B40) -> 2020 | D40: =MONTH(B40) -> 9 | E40: ИМ | F40: ФЕДЕРАТИВНАЯ РЕСПУБЛИКА ГЕРМАНИЯ | G40: РОССИЯ | H40: DRK БЕЛКОВЫЕ ВЕЩЕСТВА (НЕ ПИЩ.ПРОДУКЦИЯ),ВЕС БРУТТО С С ПАЛЛ.502.600 КГ: BPIN | I40: =MIN(1,IFERROR(SEARCH(I$2,$H40),0)) -> 0 | J40: =MIN(1,IFERROR(SEARCH(J$2,$H40),0)) -> 0 | K40: =MIN(1,IFERROR(SEARCH(K$2,$H40),0)) -> 0 | L40: =IF(I40*J40=1,"Гороховый изолят",IF(I40*K40=1,"Гороховый концентрат",0)) -> 0 | M40: =$I40*J40 -> 0 | N40: =$I40*K40 -> 0 | O40: 435 | P40: 3970.13
...
