Workbook

Sheet Задание
B2: Домашнее задание №2
B4: Описание
C5: Исходные данные
C6: Таможенные декларации по импорту и экспорту кормов для домашних животных
C7: Объемы производства кормов для домашних животных (7 листов)
C8: Цены на корма для домашних животных
C9: Продажи Компании
B11: Задание
B12: 1 | C12: Провести анализ внешней торговли
B13: 1.1 | C13: Посчитать за 2023 г. импорт и экспорт кормов для домашних животных в тоннах и в рублях - по месяцам и суммарно по году
C14: Для расчета в рублях использовать столбец "46 Статистическая стоимость" с дальнейшим переводом в рубли по курсу доллара 90
B15: 1.2 | C15: Определить топ стран-поставщиков кормов в Россию по итогам годам 2023 г. (столбец - 16 Страна происхождения)
B17: 2 | C17: Посчитать объем рынка* кормов за 2023 г. в стоимостном и натуральном выражении - по месяцам и суммарно по году
C18: * Объем рынка = производство + импорт - экспорт
C19: * Проиводство в стоим. выражении = Проиводство выражении в тоннах * цены
B21: 3 | C21: Посчитать долю рынка Компании по месяцам и суммарно по году в стоимостном и натуральном выражении
C23: Обязательно:
C24: Аккуратно все структурировать и сгруппировать
C25: Использовать корректные форматы чисел
C26: Единообразный формат (ссылки, итоги и пр.)
B28: Hints
C30: Не нужно искать/использовать дополнительные данные
C31: В декларациях могут быть не только корма и не только 2023 г. Делайте поиск по слову "корм"
C32: Можно что-то изменять на листах исходных данных (например, разъединять ячейки, добавлять столбцы, делать расчеты и тд)
C34: Нужные столбцы на листе Декларации:
C35: D1 Дата выпуска груза
C36: 011 ИМ.ЭК - направление перемещения
C37: 16 Страна происхождения
C38: 31_1 Описание и характеристика товара
C39: 38 Вес нетто, кг
C40: 46 Статистическая стоимость

Sheet Sheet1
D1: янв | E1: фев | F1: мар | G1: апр | H1: май | I1: июн | J1: июл | K1: авг | L1: сен | M1: окт | N1: ноя | O1: дек | Q1: 2023 | S1: Вспом. столб.
A2: Номер месяца | D2: 1 | E2: 2 | F2: 3 | G2: 4 | H2: 5 | I2: 6 | J2: 7 | K2: 8 | L2: 9 | M2: 10 | N2: 11 | O2: 12
A4: Импорт | B4: т | D4: =SUMIFS(Декларации!$CI:$CI,Декларации!$C:$C,D$2,Декларации!$G:$G,$S4,Декларации!$BR:$BR,1)/1000 -> 939.79081 | E4: =SUMIFS(Декларации!$CI:$CI,Декларации!$C:$C,E$2,Декларации!$G:$G,$S4,Декларации!$BR:$BR,1)/1000 -> 665.98533 | F4: =SUMIFS(Декларации!$CI:$CI,Декларации!$C:$C,F$2,Декларации!$G:$G,$S4,Декларации!$BR:$BR,1)/1000 -> 1049.6604 | G4: =SUMIFS(Декларации!$CI:$CI,Декларации!$C:$C,G$2,Декларации!$G:$G,$S4,Декларации!$BR:$BR,1)/1000 -> 760.35202 | H4: =SUMIFS(Декларации!$CI:$CI,Декларации!$C:$C,H$2,Декларации!$G:$G,$S4,Декларации!$BR:$BR,1)/1000 -> 657.949 | I4: =SUMIFS(Декларации!$CI:$CI,Декларации!$C:$C,I$2,Декларации!$G:$G,$S4,Декларации!$BR:$BR,1)/1000 -> 853.88824 | J4: =SUMIFS(Декларации!$CI:$CI,Декларации!$C:$C,J$2,Декларации!$G:$G,$S4,Декларации!$BR:$BR,1)/1000 -> 1110.9289 | K4: =SUMIFS(Декларации!$CI:$CI,Декларации!$C:$C,K$2,Декларации!$G:$G,$S4,Декларации!$BR:$BR,1)/1000 -> 869.0245 | ... O4: =SUMIFS(Декларации!$CI:$CI,Декларации!$C:$C,O$2,Декларации!$G:$G,$S4,Декларации!$BR:$BR,1)/1000 -> 992.1899 | Q4: =SUM(D4:O4) -> 10832.678 | S4: ИМ
A5: Импорт | B5: тыс. руб. | D5: =SUMIFS(Декларации!$CR:$CR,Декларации!$C:$C,D$2,Декларации!$G:$G,$S5,Декларации!$BR:$BR,1)/1000*90 -> 264542.99 | E5: =SUMIFS(Декларации!$CR:$CR,Декларации!$C:$C,E$2,Декларации!$G:$G,$S5,Декларации!$BR:$BR,1)/1000*90 -> 181764.48 | F5: =SUMIFS(Декларации!$CR:$CR,Декларации!$C:$C,F$2,Декларации!$G:$G,$S5,Декларации!$BR:$BR,1)/1000*90 -> 290733.7 | G5: =SUMIFS(Декларации!$CR:$CR,Декларации!$C:$C,G$2,Декларации!$G:$G,$S5,Декларации!$BR:$BR,1)/1000*90 -> 209525.84 | H5: =SUMIFS(Декларации!$CR:$CR,Декларации!$C:$C,H$2,Декларации!$G:$G,$S5,Декларации!$BR:$BR,1)/1000*90 -> 181208.44 | I5: =SUMIFS(Декларации!$CR:$CR,Декларации!$C:$C,I$2,Декларации!$G:$G,$S5,Декларации!$BR:$BR,1)/1000*90 -> 240790.71 | J5: =SUMIFS(Декларации!$CR:$CR,Декларации!$C:$C,J$2,Декларации!$G:$G,$S5,Декларации!$BR:$BR,1)/1000*90 -> 309665.29 | K5: =SUMIFS(Декларации!$CR:$CR,Декларации!$C:$C,K$2,Декларации!$G:$G,$S5,Декларации!$BR:$BR,1)/1000*90 -> 241078.11 | ... O5: =SUMIFS(Декларации!$CR:$CR,Декларации!$C:$C,O$2,Декларации!$G:$G,$S5,Декларации!$BR:$BR,1)/1000*90 -> 274120.11 | Q5: =SUM(D5:O5) -> 3002127.1 | S5: ИМ
A7: Экспорт | B7: т | D7: =SUMIFS(Декларации!$CI:$CI,Декларации!$C:$C,D$2,Декларации!$G:$G,$S7,Декларации!$BR:$BR,1)/1000 -> 148.21436 | E7: =SUMIFS(Декларации!$CI:$CI,Декларации!$C:$C,E$2,Декларации!$G:$G,$S7,Декларации!$BR:$BR,1)/1000 -> 126.01284 | F7: =SUMIFS(Декларации!$CI:$CI,Декларации!$C:$C,F$2,Декларации!$G:$G,$S7,Декларации!$BR:$BR,1)/1000 -> 180.60737 | G7: =SUMIFS(Декларации!$CI:$CI,Декларации!$C:$C,G$2,Декларации!$G:$G,$S7,Декларации!$BR:$BR,1)/1000 -> 81.72427 | H7: =SUMIFS(Декларации!$CI:$CI,Декларации!$C:$C,H$2,Декларации!$G:$G,$S7,Декларации!$BR:$BR,1)/1000 -> 166.78133 | I7: =SUMIFS(Декларации!$CI:$CI,Декларации!$C:$C,I$2,Декларации!$G:$G,$S7,Декларации!$BR:$BR,1)/1000 -> 207.91249 | J7: =SUMIFS(Декларации!$CI:$CI,Декларации!$C:$C,J$2,Декларации!$G:$G,$S7,Декларации!$BR:$BR,1)/1000 -> 83.24303 | K7: =SUMIFS(Декларации!$CI:$CI,Декларации!$C:$C,K$2,Декларации!$G:$G,$S7,Декларации!$BR:$BR,1)/1000 -> 150.52447 | ... O7: =SUMIFS(Декларации!$CI:$CI,Декларации!$C:$C,O$2,Декларации!$G:$G,$S7,Декларации!$BR:$BR,1)/1000 -> 81.91393 | Q7: =SUM(D7:O7) -> 1495.1891 | S7: ЭК
A8: Экспорт | B8: тыс. руб. | D8: =SUMIFS(Декларации!$CR:$CR,Декларации!$C:$C,D$2,Декларации!$G:$G,$S8,Декларации!$BR:$BR,1)/1000*90 -> 42517.071 | E8: =SUMIFS(Декларации!$CR:$CR,Декларации!$C:$C,E$2,Декларации!$G:$G,$S8,Декларации!$BR:$BR,1)/1000*90 -> 35326.055 | F8: =SUMIFS(Декларации!$CR:$CR,Декларации!$C:$C,F$2,Декларации!$G:$G,$S8,Декларации!$BR:$BR,1)/1000*90 -> 49728.294 | G8: =SUMIFS(Декларации!$CR:$CR,Декларации!$C:$C,G$2,Декларации!$G:$G,$S8,Декларации!$BR:$BR,1)/1000*90 -> 23009.752 | H8: =SUMIFS(Декларации!$CR:$CR,Декларации!$C:$C,H$2,Декларации!$G:$G,$S8,Декларации!$BR:$BR,1)/1000*90 -> 46028.2 | I8: =SUMIFS(Декларации!$CR:$CR,Декларации!$C:$C,I$2,Декларации!$G:$G,$S8,Декларации!$BR:$BR,1)/1000*90 -> 55344.224 | J8: =SUMIFS(Декларации!$CR:$CR,Декларации!$C:$C,J$2,Декларации!$G:$G,$S8,Декларации!$BR:$BR,1)/1000*90 -> 21577.476 | K8: =SUMIFS(Декларации!$CR:$CR,Декларации!$C:$C,K$2,Декларации!$G:$G,$S8,Декларации!$BR:$BR,1)/1000*90 -> 40505.251 | ... O8: =SUMIFS(Декларации!$CR:$CR,Декларации!$C:$C,O$2,Декларации!$G:$G,$S8,Декларации!$BR:$BR,1)/1000*90 -> 22563.588 | Q8: =SUM(D8:O8) -> 408639.28 | S8: ЭК
A10: Производство | B10: т | D10: ='Росстат_Пр-во ЦФО'!D5+'Росстат_Пр-во СЗФО'!D5+'Росстат_Пр-во ЮФО'!D5+'Росстат_Пр-во ЮФО'!D5+'Росстат_Пр-во ЮФО'!D5+'Росстат_Пр-во ПФО'!D5+'Росстат_Пр-во УФО'!D5+'Росстат_Пр-во СФО'!D5+'Росстат_Пр-во ДФО'!D5 -> 5900.11 | E10: ='Росстат_Пр-во ЦФО'!E5+'Росстат_Пр-во СЗФО'!E5+'Росстат_Пр-во ЮФО'!E5+'Росстат_Пр-во ЮФО'!E5+'Росстат_Пр-во ЮФО'!E5+'Росстат_Пр-во ПФО'!E5+'Росстат_Пр-во УФО'!E5+'Росстат_Пр-во СФО'!E5+'Росстат_Пр-во ДФО'!E5 -> 6852.75 | F10: ='Росстат_Пр-во ЦФО'!F5+'Росстат_Пр-во СЗФО'!F5+'Росстат_Пр-во ЮФО'!F5+'Росстат_Пр-во ЮФО'!F5+'Росстат_Пр-во ЮФО'!F5+'Росстат_Пр-во ПФО'!F5+'Росстат_Пр-во УФО'!F5+'Росстат_Пр-во СФО'!F5+'Росстат_Пр-во ДФО'!F5 -> 7787.96 | G10: ='Росстат_Пр-во ЦФО'!G5+'Росстат_Пр-во СЗФО'!G5+'Росстат_Пр-во ЮФО'!G5+'Росстат_Пр-во ЮФО'!G5+'Росстат_Пр-во ЮФО'!G5+'Росстат_Пр-во ПФО'!G5+'Росстат_Пр-во УФО'!G5+'Росстат_Пр-во СФО'!G5+'Росстат_Пр-во ДФО'!G5 -> 7668.92 | H10: ='Росстат_Пр-во ЦФО'!H5+'Росстат_Пр-во СЗФО'!H5+'Росстат_Пр-во ЮФО'!H5+'Росстат_Пр-во ЮФО'!H5+'Росстат_Пр-во ЮФО'!H5+'Росстат_Пр-во ПФО'!H5+'Росстат_Пр-во УФО'!H5+'Росстат_Пр-во СФО'!H5+'Росстат_Пр-во ДФО'!H5 -> 8522.6 | I10: ='Росстат_Пр-во ЦФО'!I5+'Росстат_Пр-во СЗФО'!I5+'Росстат_Пр-во ЮФО'!I5+'Росстат_Пр-во ЮФО'!I5+'Росстат_Пр-во ЮФО'!I5+'Росстат_Пр-во ПФО'!I5+'Росстат_Пр-во УФО'!I5+'Росстат_Пр-во СФО'!I5+'Росстат_Пр-во ДФО'!I5 -> 8773.36 | J10: ='Росстат_Пр-во ЦФО'!J5+'Росстат_Пр-во СЗФО'!J5+'Росстат_Пр-во ЮФО'!J5+'Росстат_Пр-во ЮФО'!J5+'Росстат_Пр-во ЮФО'!J5+'Росстат_Пр-во ПФО'!J5+'Росстат_Пр-во УФО'!J5+'Росстат_Пр-во СФО'!J5+'Росстат_Пр-во ДФО'!J5 -> 8648.69 | K10: ='Росстат_Пр-во ЦФО'!K5+'Росстат_Пр-во СЗФО'!K5+'Росстат_Пр-во ЮФО'!K5+'Росстат_Пр-во ЮФО'!K5+'Росстат_Пр-во ЮФО'!K5+'Росстат_Пр-во ПФО'!K5+'Росстат_Пр-во УФО'!K5+'Росстат_Пр-во СФО'!K5+'Росстат_Пр-во ДФО'!K5 -> 8792.88 | ... O10: ='Росстат_Пр-во ЦФО'!O5+'Росстат_Пр-во СЗФО'!O5+'Росстат_Пр-во ЮФО'!O5+'Росстат_Пр-во ЮФО'!O5+'Росстат_Пр-во ЮФО'!O5+'Росстат_Пр-во ПФО'!O5+'Росстат_Пр-во УФО'!O5+'Росстат_Пр-во СФО'!O5+'Росстат_Пр-во ДФО'!O5 -> 9783.28 | Q10: =SUM(D10:O10) -> 100065.54
A11: Производство | B11: тыс. руб. | D11: =D10*Росстат_Цены!C5 -> 1807970.7 | E11: =E10*Росстат_Цены!D5 -> 2077205.6 | F11: =F10*Росстат_Цены!E5 -> 2359440.4 | G11: =G10*Росстат_Цены!F5 -> 2357426 | H11: =H10*Росстат_Цены!G5 -> 2617290.5 | I11: =I10*Росстат_Цены!H5 -> 2705528.8 | J11: =J10*Росстат_Цены!I5 -> 2720359 | K11: =K10*Росстат_Цены!J5 -> 2914312.1 | ... O11: =O10*Росстат_Цены!N5 -> 3373470.6 | Q11: =SUM(D11:O11) -> 32255963
A13: Объем рынка | B13: т | D13: =D10+D4-D7 -> 6691.6864 | E13: =E10+E4-E7 -> 7392.7225 | F13: =F10+F4-F7 -> 8657.0131 | G13: =G10+G4-G7 -> 8347.5478 | H13: =H10+H4-H7 -> 9013.7677 | I13: =I10+I4-I7 -> 9419.3358 | J13: =J10+J4-J7 -> 9676.3758 | K13: =K10+K4-K7 -> 9511.38 | ... O13: =O10+O4-O7 -> 10693.556 | Q13: =SUM(D13:O13) -> 109403.03
A14: Объем рынка | B14: тыс. руб. | D14: =D11+D5-D8 -> 2029996.6 | E14: =E11+E5-E8 -> 2223644 | F14: =F11+F5-F8 -> 2600445.8 | G14: =G11+G5-G8 -> 2543942.1 | H14: =H11+H5-H8 -> 2752470.7 | I14: =I11+I5-I8 -> 2890975.2 | J14: =J11+J5-J8 -> 3008446.8 | K14: =K11+K5-K8 -> 3114885 | ... O14: =O11+O5-O8 -> 3625027.1 | Q14: =SUM(D14:O14) -> 34849451
A16: Доля компании, нат. выраж. | B16: % | D16: ='Продажи Компании'!K22/D13 -> 0.29816536 | E16: ='Продажи Компании'!L22/E13 -> 0.2804771 | F16: ='Продажи Компании'!M22/F13 -> 0.30984334 | G16: ='Продажи Компании'!N22/G13 -> 0.29249056 | H16: ='Продажи Компании'!O22/H13 -> 0.26935293 | I16: ='Продажи Компании'!P22/I13 -> 0.21891335 | J16: ='Продажи Компании'!Q22/J13 -> 0.23176583 | K16: ='Продажи Компании'!R22/K13 -> 0.26537718 | ... O16: ='Продажи Компании'!V22/O13 -> 0.18971229 | Q16: ='Продажи Компании'!X22/Q13 -> 0.25493142
A17: Доля компании, стоим. выраж. | B17: % | D17: ='Продажи Компании'!K64*1000/D14 -> 0.25886615 | E17: ='Продажи Компании'!L64*1000/E14 -> 0.2411137 | F17: ='Продажи Компании'!M64*1000/F14 -> 0.25364764 | G17: ='Продажи Компании'!N64*1000/G14 -> 0.26663299 | H17: ='Продажи Компании'!O64*1000/H14 -> 0.25230022 | I17: ='Продажи Компании'!P64*1000/I14 -> 0.19598268 | J17: ='Продажи Компании'!Q64*1000/J14 -> 0.20227735 | K17: ='Продажи Компании'!R64*1000/K14 -> 0.21232977 | ... O17: ='Продажи Компании'!V64*1000/O14 -> 0.15244312 | Q17: ='Продажи Компании'!X64*1000/Q14 -> 0.21371817
A19: Топ импортеров в РФ
A20: =Sheet2!A17 -> БЕЛЬГИЯ
A21: =Sheet2!A18 -> ФРАНЦИЯ

Sheet Исходные данные→

Sheet Продажи Компании
B1: Показатель | G1: ед. изм. | H1: Предпосылка | K1: 44927 | L1: =EDATE(K1,1) -> 44958 | M1: =EDATE(L1,1) -> 44986 | N1: =EDATE(M1,1) -> 45017 | O1: =EDATE(N1,1) -> 45047 | P1: =EDATE(O1,1) -> 45078 | Q1: =EDATE(P1,1) -> 45108 | R1: =EDATE(Q1,1) -> 45139 | S1: =EDATE(R1,1) -> 45170 | ... V1: =EDATE(U1,1) -> 45261 | X1: 2023
B2: Продажи в натуральном выражении
B4: Корма для собак | G4: т | K4: =K5+K9 -> 919.94381 | L4: =L5+L9 -> 919.94381 | M4: =M5+M9 -> 919.94381 | N4: =N5+N9 -> 919.94381 | O4: =O5+O9 -> 919.94381 | P4: =P5+P9 -> 919.94381 | Q4: =Q5+Q9 -> 919.94381 | R4: =R5+R9 -> 919.94381 | ... V4: =V5+V9 -> 919.94381 | X4: =SUM(K4:V4) -> 11039.326
C5: Онлайн продажи | G5: т | K5: =K6+K7 -> 533.23056 | L5: =L6+L7 -> 533.23056 | M5: =M6+M7 -> 533.23056 | N5: =N6+N7 -> 533.23056 | O5: =O6+O7 -> 533.23056 | P5: =P6+P7 -> 533.23056 | Q5: =Q6+Q7 -> 533.23056 | R5: =R6+R7 -> 533.23056 | ... V5: =V6+V7 -> 533.23056 | X5: =SUM(K5:V5) -> 6398.7667
D6: Эконом сегмент | G6: т | K6: 221.90827 | L6: 221.90827 | M6: 221.90827 | N6: 221.90827 | O6: 221.90827 | P6: 221.90827 | Q6: 221.90827 | R6: 221.90827 | S6: 221.90827 | T6: 221.90827 | U6: 221.90827 | V6: 221.90827 | X6: =SUM(K6:V6) -> 2662.8993
D7: Премиум сегмент | G7: т | K7: 311.32228 | L7: 311.32228 | M7: 311.32228 | N7: 311.32228 | O7: 311.32228 | P7: 311.32228 | Q7: 311.32228 | R7: 311.32228 | S7: 311.32228 | T7: 311.32228 | U7: 311.32228 | V7: 311.32228 | X7: =SUM(K7:V7) -> 3735.8674
C9: Офлайн продажи | G9: т | K9: =K10+K11 -> 386.71326 | L9: =L10+L11 -> 386.71326 | M9: =M10+M11 -> 386.71326 | N9: =N10+N11 -> 386.71326 | O9: =O10+O11 -> 386.71326 | P9: =P10+P11 -> 386.71326 | Q9: =Q10+Q11 -> 386.71326 | R9: =R10+R11 -> 386.71326 | ... V9: =V10+V11 -> 386.71326 | X9: =SUM(K9:V9) -> 4640.5591
D10: Эконом сегмент | G10: т | K10: 193.7266 | L10: 193.7266 | M10: 193.7266 | N10: 193.7266 | O10: 193.7266 | P10: 193.7266 | Q10: 193.7266 | R10: 193.7266 | S10: 193.7266 | T10: 193.7266 | U10: 193.7266 | V10: 193.7266 | X10: =SUM(K10:V10) -> 2324.7192
D11: Премиум сегмент | G11: т | K11: 192.98665 | L11: 192.98665 | M11: 192.98665 | N11: 192.98665 | O11: 192.98665 | P11: 192.98665 | Q11: 192.98665 | R11: 192.98665 | S11: 192.98665 | T11: 192.98665 | U11: 192.98665 | V11: 192.98665 | X11: =SUM(K11:V11) -> 2315.8398
B13: Корма для кошек | G13: т | K13: =K14+K18 -> 1075.2853 | L13: =L14+L18 -> 1153.5455 | M13: =M14+M18 -> 1762.374 | N13: =N14+N18 -> 1521.6351 | O13: =O14+O18 -> 1507.9409 | P13: =P14+P18 -> 1142.0745 | Q13: =Q14+Q18 -> 1322.7094 | R13: =R14+R18 -> 1604.1594 | ... V13: =V14+V18 -> 1108.7552 | X13: =SUM(K13:V13) -> 16850.944
C14: Онлайн продажи | G14: т | K14: =K15+K16 -> 429.01237 | L14: =L15+L16 -> 521.78334 | M14: =M15+M16 -> 641.30919 | N14: =N15+N16 -> 531.86453 | O14: =O15+O16 -> 603.5511 | P14: =P15+P16 -> 441.30446 | Q14: =Q15+Q16 -> 535.61208 | R14: =R15+R16 -> 595.24076 | ... V14: =V15+V16 -> 452.46089 | X14: =SUM(K14:V14) -> 6589.1002
D15: Эконом сегмент | G15: т | K15: 164.50864 | L15: 238.58801 | M15: 323.25906 | N15: 196.03272 | O15: 344.96264 | P15: 204.67803 | Q15: 272.71168 | R15: 270.14438 | S15: 258.44967 | T15: 352.79026 | U15: 282.88535 | V15: 295.01213 | X15: =SUM(K15:V15) -> 3204.0226
D16: Премиум сегмент | G16: т | K16: 264.50373 | L16: 283.19533 | M16: 318.05013 | N16: 335.83181 | O16: 258.58846 | P16: 236.62643 | Q16: 262.9004 | R16: 325.09637 | S16: 283.05502 | T16: 355.81517 | U16: 303.96598 | V16: 157.44877 | X16: =SUM(K16:V16) -> 3385.0776
C18: Офлайн продажи | G18: т | K18: =K19+K20 -> 646.27288 | L18: =L19+L20 -> 631.76218 | M18: =M19+M20 -> 1121.0648 | N18: =N19+N20 -> 989.77061 | O18: =O19+O20 -> 904.38981 | P18: =P19+P20 -> 700.77005 | Q18: =Q19+Q20 -> 787.09735 | R18: =R19+R20 -> 1008.9186 | ... V18: =V19+V20 -> 656.29428 | X18: =SUM(K18:V18) -> 10261.844
D19: Эконом сегмент | G19: т | K19: 281.84381 | L19: 278.8877 | M19: 527.46729 | N19: 358.57814 | O19: 485.32985 | P19: 325.69236 | Q19: 447.45604 | R19: 496.91693 | S19: 310.41882 | T19: 621.47671 | U19: 462.13505 | V19: 418.87952 | X19: =SUM(K19:V19) -> 5015.0822
D20: Премиум сегмент | G20: т | K20: 364.42907 | L20: 352.87448 | M20: 593.59751 | N20: 631.19247 | O20: 419.05996 | P20: 375.07769 | Q20: 339.64131 | R20: 512.00168 | S20: 498.08946 | T20: 483.4758 | U20: 439.90733 | V20: 237.41476 | X20: =SUM(K20:V20) -> 5246.7615
B22: Всего | G22: т | K22: =K4+K13 -> 1995.2291 | L22: =L4+L13 -> 2073.4893 | M22: =M4+M13 -> 2682.3178 | N22: =N4+N13 -> 2441.5789 | O22: =O4+O13 -> 2427.8847 | P22: =P4+P13 -> 2062.0183 | Q22: =Q4+Q13 -> 2242.6532 | R22: =R4+R13 -> 2524.1032 | ... V22: =V4+V13 -> 2028.699 | X22: =X4+X13 -> 27890.27
B24: Цены реализации
B26: Корма для собак
C27: Онлайн продажи
D28: Эконом сегмент | G28: руб./кг | K28: 156.82142 | L28: 151.9801 | M28: 123.71241 | N28: 214.14255 | O28: 143.92073 | P28: 220.32397 | Q28: 310.21998 | R28: 184.65679 | S28: 210.24478 | T28: 256.07004 | U28: 157.76812 | V28: 203.15255
D29: Премиум сегмент | G29: руб./кг | K29: 357.15683 | L29: 253.52639 | M29: 275.29483 | N29: 252.21148 | O29: 353.6967 | P29: 255.5361 | Q29: 309.02673 | R29: 279.87634 | S29: 208.11919 | T29: 326.25212 | U29: 334.17688 | V29: 318.56159
C31: Офлайн продажи
D32: Эконом сегмент | G32: руб./кг | K32: 152.22934 | L32: 192.95474 | M32: 153.77688 | N32: 196.44314 | O32: 296.33762 | P32: 266.12095 | Q32: 241.60356 | R32: 187.19867 | S32: 108.0896 | T32: 149.23104 | U32: 308.67102 | V32: 217.70173
D33: Премиум сегмент | G33: руб./кг | K33: 334.64215 | L33: 453.72332 | M33: 276.7244 | N33: 424.20757 | O33: 678.93128 | P33: 479.74478 | Q33: 386.32654 | R33: 493.24091 | S33: 449.48909 | T33: 422.02649 | U33: 572.98116 | V33: 563.24297
B35: Корма для кошек
C36: Онлайн продажи
D37: Эконом сегмент | G37: руб./кг | K37: 167.1141 | L37: 171.17396 | M37: 174.57979 | N37: 142.18712 | O37: 137.72079 | P37: 149.05061 | Q37: 162.8598 | R37: 173.86068 | S37: 158.9307 | T37: 149.54754 | U37: 136.75411 | V37: 166.76807
D38: Премиум сегмент | G38: руб./кг | K38: 353.00794 | L38: 336.68402 | M38: 346.33538 | N38: 346.38452 | O38: 340.74052 | P38: 349.50971 | Q38: 357.1767 | R38: 329.41838 | S38: 360.99303 | T38: 336.02545 | U38: 341.4822 | V38: 356.45511
C40: Офлайн продажи
D41: Эконом сегмент | G41: руб./кг | K41: 135.2753 | L41: 144.85025 | M41: 161.85607 | N41: 162.49087 | O41: 150.18898 | P41: 152.79492 | Q41: 151.22624 | R41: 143.67777 | S41: 155.28266 | T41: 142.32903 | U41: 156.4147 | V41: 152.53764
D42: Премиум сегмент | G42: руб./кг | K42: 346.96488 | L42: 345.64591 | M42: 355.93752 | N42: 364.18564 | O42: 370.95805 | P42: 349.31821 | Q42: 341.97747 | R42: 344.45946 | S42: 342.26039 | T42: 351.71009 | U42: 363.7693 | V42: 371.77124
B44: Выручка
B46: Корма для собак | G46: млн руб. | K46: =K47+K51 -> 240.06319 | L46: =L47+L51 -> 237.59707 | M46: =M47+M51 -> 196.35301 | N46: =N47+N51 -> 245.96172 | O46: =O47+O51 -> 330.48402 | P46: =P47+P51 -> 272.58484 | Q46: =Q47+Q51 -> 286.40819 | R46: =R47+R51 -> 259.56289 | ... V46: =V47+V51 -> 295.12955 | X46: =SUM(K46:V46) -> 3161.4483
C47: Онлайн продажи | G47: млн руб. | K47: =K48+K49 -> 145.99085 | L47: =L48+L49 -> 112.65406 | M47: =M48+M49 -> 113.15822 | N47: =N48+N49 -> 126.03906 | O47: =O48+O49 -> 142.05086 | P47: =P48+P49 -> 128.4458 | Q47: =Q48+Q49 -> 165.04729 | R47: =R48+R49 -> 128.10861 | ... V47: =V48+V49 -> 144.25655 | X47: =SUM(K47:V47) -> 1614.6389
D48: Эконом сегмент | G48: млн руб. | K48: =K6*K28/1000 -> 34.79997 | L48: =L6*L28/1000 -> 33.725642 | M48: =M6*M28/1000 -> 27.452807 | N48: =N6*N28/1000 -> 47.520004 | O48: =O6*O28/1000 -> 31.9372 | P48: =P6*P28/1000 -> 48.891712 | Q48: =Q6*Q28/1000 -> 68.84038 | R48: =R6*R28/1000 -> 40.97687 | ... V48: =V6*V28/1000 -> 45.081233 | X48: =SUM(K48:V48) -> 517.71498
D49: Премиум сегмент | G49: млн руб. | K49: =K7*K29/1000 -> 111.19088 | L49: =L7*L29/1000 -> 78.928413 | M49: =M7*M29/1000 -> 85.705416 | N49: =N7*N29/1000 -> 78.519054 | O49: =O7*O29/1000 -> 110.11366 | P49: =P7*P29/1000 -> 79.554083 | Q49: =Q7*Q29/1000 -> 96.206907 | R49: =R7*R29/1000 -> 87.131741 | ... V49: =V7*V29/1000 -> 99.17532 | X49: =SUM(K49:V49) -> 1096.9239
C51: Офлайн продажи | G51: млн руб. | K51: =K52+K53 -> 94.072342 | L51: =L52+L53 -> 124.94301 | M51: =M52+M53 -> 83.194789 | N51: =N52+N53 -> 119.92266 | O51: =O52+O53 -> 188.43316 | P51: =P52+P53 -> 144.13905 | Q51: =Q52+Q53 -> 121.3609 | R51: =R52+R53 -> 131.45428 | ... V51: =V52+V53 -> 150.87299 | X51: =SUM(K51:V51) -> 1546.8094
D52: Эконом сегмент | G52: млн руб. | K52: =K10*K32/1000 -> 29.490874 | L52: =L10*L32/1000 -> 37.380467 | M52: =M10*M32/1000 -> 29.790673 | N52: =N10*N32/1000 -> 38.056262 | O52: =O10*O32/1000 -> 57.40848 | P52: =P10*P32/1000 -> 51.554707 | Q52: =Q10*Q32/1000 -> 46.805037 | R52: =R10*R32/1000 -> 36.265362 | ... V52: =V10*V32/1000 -> 42.174617 | X52: =SUM(K52:V52) -> 478.57412
D53: Премиум сегмент | G53: млн руб. | K53: =K11*K33/1000 -> 64.581468 | L53: =L11*L33/1000 -> 87.562544 | M53: =M11*M33/1000 -> 53.404116 | N53: =N11*N33/1000 -> 81.866398 | O53: =O11*O33/1000 -> 131.02468 | P53: =P11*P33/1000 -> 92.584339 | Q53: =Q11*Q33/1000 -> 74.555865 | R53: =R11*R33/1000 -> 95.188913 | ... V53: =V11*V33/1000 -> 108.69838 | X53: =SUM(K53:V53) -> 1068.2353
...

Sheet Sheet2
A1: 011 ИМ.ЭК - направление перемещения | B1: ИМ
A2: ДАТА2 | B2: (Multiple Items)
A3: Column1 | B3: 1
A5: Row Labels | B5: Sum of 46 Статистическая стоимость | C5: Sum of 38 Вес нетто, кг
A6: БЕЛЬГИЯ | B6: 31975558 | C6: 10445471
A7: ФРАНЦИЯ | B7: 972244.41 | C7: 256500.39
B8: 409165.53 | C8: 130705.82
A9: Grand Total | B9: 33356968 | C9: 10832678
A12: 011 ИМ.ЭК - направление перемещения | B12: ИМ
A13: ДАТА2 | B13: (Multiple Items)
A14: Column1 | B14: 1
A16: Row Labels | B16: Sum of 46 Статистическая стоимость | C16: Sum of 38 Вес нетто, кг
A17: БЕЛЬГИЯ | B17: 31975558 | C17: 10445471
A18: ФРАНЦИЯ | B18: 972244.41 | C18: 256500.39
B19: 409165.53 | C19: 130705.82
A20: Grand Total | B20: 33356968 | C20: 10832678

Sheet Декларации
BR1: корм
A2: STAT Учет в статистике 0/1 | B2: Дата | C2: ДАТА2 | D2: ND Номер декларации на товары | E2: 071 Таможня оформления ДТ | F2: 073 Порядковый № ДТ | G2: 011 ИМ.ЭК - направление перемещения | H2: 012 Основной таможенный режим | I2: 013 Дополнительный признак | J2: 020 ОГРН.ОГРНИП отправителя | K2: 021 ИНН отправителя | L2: 022 Наименование.ФИО отправителя | M2: 023 Адрес отправителя | N2: 024 ОКАТО отправителя | O2: 027 КПП отправителя | P2: 03 Листов ДТ | Q2: 04 Спецификаций ДТ | R2: 05 Товаров всего | S2: 06 Мест товара всего | T2: 080 ОГРН.ОГРНИП получателя | U2: 081 ИНН получателя | V2: 082 Наименование.ФИО получателя | W2: 083 Адрес получателя | X2: 084 ОКАТО получателя | Y2: 087 КПП получателя | Z2: 090 ОГРН.ОГРНИП контрактодержателя | AA2: 091 ИНН контрактодержателя | AB2: 092 Наименование.ФИО контрактодержателя | AC2: 093 Адрес контрактодержателя | AD2: 094 ОКАТО контрактодержателя | AE2: 097 КПП контрактодержателя | AF2: 11 Код торгующей страны | AG2: 11 Торгующая страна | AH2: 12 Общая таможенная стоимость | AI2: 140 ОГРН.ОГРНИП декларанта | AJ2: 141 ИНН контрактодержателя | AK2: 142 Наименование.ФИО декларанта | AL2: 143 Адрес контрактодержателя | AM2: 144 ОКАТО контрактодержателя | AN2: 147 КПП контрактодержателя | AO2: 15А Код страны отправления | AP2: 15 Страна отправления | AQ2: 16 Страна происхождения | AR2: 17А Код страны назначения | AS2: 17 Страна назначения | AT2: 18 Кол-во транспорта при отправлении | AU2: 19 Признак контейнерных перевозок 0ю1 | AV2: 202 Условие поставки | AW2: 2021 Пункт поставки товара | AX2: 21 Кол-во трансп на границе | AY2: 221 Валюта контракта | AZ2: 222 Общая фактурная стоимость | BA2: 2220 Общая фактурная стоимость, руб | BB2: 226 Статистическая стоимость суммарная | BC2: 23 Курс валюты | BD2: 24 Характер сделки | BE2: 25 Вид транспортного средства | BF2: 28 ОКПО банка.паспорт сделки | BG2: 29 Таможня на границе | BH2: 300 Тип информации | BI2: 301 № свидетельства СВХ.ТС | BJ2: 302 Вид документа.Вид ТС | BK2: 30POST Индекс места нахождения товара | BL2: 30SUBD Регион | BM2: 30CITY Населенный пункт | BN2: 30STREET Адрес местонахождения товара | BO2: 3012 Таможня в зоне которой склад | BP2: 3 Порядковый № листа ДТ | BQ2: 31_1 Описание и характеристика товара | BR2: Column1 | BS2: 31_11 Товарный знак | BT2: 31_12 Наименование фирмы изготовителя | BU2: 31_2 Кол-во мест товара | BV2: 31_3 Кол-во контейнеров | BW2: 31_7 Кол-во товара в доп ед. измерения | BX2: 31_71 Дополнительная единица | BY2: 31_8 Кол-во товара в доп единице | BZ2: 31_81 Дополнительная единица | CA2: 32 Номер товара по ДТ | CB2: 33 Код товара по ТН ВЭД РФ | CC2: 331 Признак нетарифного регулирования | CD2: 332 Признак объекта интеллект собственности | CE2: 34 Код страны происхождения | CF2: 35 Вес брутто, кг | CG2: 36 Преференции | CH2: 37 Процедура | CI2: 38 Вес нетто, кг | CJ2: 39 Квота | CK2: 391 Код валюты квоты | CL2: 392 Единица измерения квоты | CM2: 42 Фактурная стоимость | CN2: 420 Фактурная стоимость, руб | CO2: 43 Признак корректировки таможенной стоимости (КТС) | CP2: 431 Метод определения таможенной стоимости | CQ2: 45 Таможенная стоимость | CR2: 46 Статистическая стоимость | CS2: D0 Код завршения таможенного оформления | CT2: Стат сумма, долл | CU2: USD/KG Статистическая стоимость, USD/Dtc НЕТТО, кг | CV2: 541 Свидетельство таможенного брокера | CW2: 5411 Договор брокера с декларантом | CX2: 5441 ФИО заполнившего ДТ | CY2: ЛНП выпускающего инспектора | CZ2: ND_DEL Признак удаления декларации
A3: 1 | B3: 45117 | C3: =IF(YEAR(Таблица1[[#This Row],[Дата]])=2023,MONTH(Таблица1[[#This Row],[Дата]]),0) -> 7 | D3: 10805010/261222/3028298 | E3: 10805010 | F3: 3028298 | G3: ИМ | H3: 40 | L3: ITALTHERM S.P.A. | M3: 29010, , PONTENURE (PC), VIA SALVO D'ACQUISTO SNC, | P3: 1 | Q3: 0 | R3: 1 | S3: 62 | T3: 1212600005826 | U3: 2632117991 | V3: ООО ТЁПЛЫЙ РИМ | W3: 357502, СТАВРОПОЛЬСКИЙ КРАЙ, Г. ПЯТИГОРСК, Ш. ЧЕРКЕССКОЕ, Д. 56,ПОМЕЩ. 8 | X3: 07000 | Y3: 263201001 | Z3: 1212600005826 | AA3: 2632117991 | AB3: ООО ТЁПЛЫЙ РИМ | AC3: 357502, СТАВРОПОЛЬСКИЙ КРАЙ, Г. ПЯТИГОРСК, Ш. ЧЕРКЕССКОЕ, Д. 56,ПОМЕЩ. 8 | AD3: 07000 | AE3: 263201001 | AF3: IT | AG3: ИТАЛИЯ | AH3: 15361774 | AI3: 1212600005826 | AJ3: 2632117991 | AK3: ООО ТЁПЛЫЙ РИМ | AL3: 357502, СТАВРОПОЛЬСКИЙ КРАЙ, Г. ПЯТИГОРСК, Ш. ЧЕРКЕССКОЕ, Д. 56,ПОМЕЩ. 8 | AM3: 07000 | AN3: 263201001 | AO3: IT | AP3: ИТАЛИЯ | AQ3: ИТАЛИЯ | AR3: RU | AS3: РОССИЯ | AT3: 2 | AU3: 0 | AV3: FCA | AW3: PONTENURE (PIACENZA) | AX3: 1 | AY3: EUR | AZ3: 205407 | BA3: 15003071 | BB3: 223684.75 | BC3: 73.0407 | BD3: 010 | BE3: 30 | BF3: 21090222/1000/0081/2/1 | BG3: - | BH3: 99 | BL3: БРЯНСКАЯ ОБЛАСТЬ, Р-Н БРЯНСКИЙ | BM3: П. СВЕНЬ | BN3: УЛ. СОБОРНАЯ | BO3: 10102032 ОТО и ТК №2 т/п Брянский | BP3: 1 | BQ3: КОТЛЫ ОТОПИТЕЛЬНЫЕ ГАЗОВЫЕ (ВОДОГРЕЙНЫЕ) СТАЛЬНЫЕ. ПРЕДНАЗНАЧЕНЫ ДЛЯ ОТОПЛЕНИЯ ЖИЛЫХ ДОМОВ И ЗДАНИЙ КОММУНАЛЬНО-БЫТОВОГО НАЗНАЧЕНИЯ, ОБОРУДОВАННЫХ СИСТЕМАМИ ОТОПЛЕНИЯ НЕПРЕРЫВНОГО ДЕЙСТВИЯ С ЕСТЕСТВЕННОЙ ИЛИ ПРИНУДИТЕЛЬНОЙ ЦИРКУЛЯЦИЕЙ ТЕПЛОНОСИТЕЛЯ, | BR3: =ISNUMBER(SEARCH($BR$1,Таблица1[[#This Row],[31_1 Описание и характеристика товара]]))*1 -> 0 | BT3: ITALTHERM S.P.A. | BU3: 62 | BV3: 0 | BW3: 383 | BX3: ШТ | BY3: 0 | CA3: 1 | CB3: 8403109000 | CE3: IT | CF3: 15554.5 | CG3: ОООО-ОО | CH3: 4000000 | CI3: 13783.972 | CJ3: 0 | CM3: 205407 | CN3: 15003071 | CO3: 0 | CP3: 1 | CQ3: 15361774 | CR3: 223684.75 | CS3: 10 | CT3: 16.2279 | CU3: 1069 | CV3: 1069-21-54-1264 | CX3: ЖУРАВКОВ СЕРГЕЙ ИВАНОВИЧ | CY3: 1
A4: 1 | B4: 45200 | C4: =IF(YEAR(Таблица1[[#This Row],[Дата]])=2023,MONTH(Таблица1[[#This Row],[Дата]]),0) -> 10 | D4: 10720010/251222/3095701 | E4: 10720010 | F4: 3095701 | G4: ИМ | H4: 40 | L4: INNER MONGOLIA THE ERA OF BINHANG SUPPLY CHAIN MANAGEMENT CO, LTD | M4: , INNER MONGOLIA, MANZHOULI CITY, BICAO YUNTIAN 20,STREET, HUMAO DISTRICT, NO. 7 | P4: 1 | Q4: 0 | R4: 1 | S4: 2 | T4: 1227500001860 | U4: 7500002418 | V4: ООО ФРЕГАТ | W4: 672000, ЗАБАЙКАЛЬСКИЙ КРАЙ, Г.ЧИТА, УЛ. БАБУШКИНА, Д.42, КОРП. А, ОФИС 209 | X4: 76000 | Y4: 750001001 | Z4: 1227500001860 | AA4: 7500002418 | AB4: ООО ФРЕГАТ | AC4: 672000, ЗАБАЙКАЛЬСКИЙ КРАЙ, Г.ЧИТА, УЛ. БАБУШКИНА, Д.42, КОРП. А, ОФИС 209 | AD4: 76000 | AE4: 750001001 | AF4: CN | AG4: КИТАЙ | AH4: 27470.4 | AI4: 1227500001860 | AJ4: 7500002418 | AK4: ООО ФРЕГАТ | AL4: 672000, ЗАБАЙКАЛЬСКИЙ КРАЙ, Г.ЧИТА, УЛ. БАБУШКИНА, Д.42, КОРП. А, ОФИС 209 | AM4: 76000 | AN4: 750001001 | AO4: CN | AP4: КИТАЙ | AQ4: КИТАЙ | AR4: RU | AS4: РОССИЯ | AT4: 2 | AU4: 0 | AV4: DAP | AW4: ЗАБАЙКАЛЬСК | AX4: 1 | AY4: USD | AZ4: 400 | BA4: 27470 | BB4: 400 | BC4: 68.676 | BD4: 010 | BF4: 22050009/1481/1727/2/1 | BG4: - | BH4: 11 | BI4: 10719/291015/10027/8 | BL4: ЗАБАЙКАЛЬСКИЙ КРАЙ | BM4: ПГТ. ЗАБАЙКАЛЬСК | BN4: МКР.МАПП ЗАБАЙКАЛЬСК УЧАСТОК № 6 | BO4: 10719030 т/п Забайкальский | BP4: 1 | BQ4: ТВЕРДОТОПЛИВНЫЙ ВОДОГРЕЙНЫЙ ОТОПИТЕЛЬНЫЙ КОТЕЛ ТОРГОВОЙ МАРКИ CHENG CHENG, МОДЕЛЬ СС-2000W-01, ИЗГОТОВИТЕЛЬ ANHUI CHENGCHENG MACHINERY CO., LTD.В ЧАСТИЧНО РАЗОБРАННОМ ВИДЕ ДЛЯ УДОБСТВА ТРАНСПОРТИРОВКИ СОГЛАСНО УПАКОВОЧНОГО ЛИСТА:КАБЕЛЬ ПИТАНИЯ1 ШТ 1 | BR4: =ISNUMBER(SEARCH($BR$1,Таблица1[[#This Row],[31_1 Описание и характеристика товара]]))*1 -> 0 | BT4: ANHUI CHENGCHENG MACHINERY CO., LTD | BU4: 2 | BV4: 0 | BW4: 1 | BX4: ШТ | BY4: 0 | CA4: 1 | CB4: 8403109000 | CE4: CN | CF4: 232 | CG4: ОООО-ОО | CH4: 4000000 | CI4: 175 | CJ4: 0 | CM4: 400 | CN4: 27470 | CO4: 2 | CP4: 1 | CQ4: 27470.4 | CR4: 400 | CS4: 12 | CT4: 2.2857 | CX4: ЕКИМОВ ОЛЕГ ВАЛЕРЬЕВИЧ | CY4: 79
A5: 1 | B5: 44990 | C5: =IF(YEAR(Таблица1[[#This Row],[Дата]])=2023,MONTH(Таблица1[[#This Row],[Дата]]),0) -> 3 | D5: 10702070/211222/3458521 | E5: 10702070 | F5: 3458521 | G5: ИМ | H5: 40 | L5: HYDROSTA CO.,LTD | M5: , BUSAN, HAEUNDAE-GU,U-DONG, ACE HIGHTECH 1470,21, NO.1813, | P5: 6 | Q5: 0 | R5: 14 | S5: 215 | T5: 1042502960500 | U5: 2536144625 | V5: ООО ИМПОРТ-СЕРВИС | W5: 690001, ПРИМОРСКИЙ КРАЙ, ВЛАДИВОСТОК, УЛ.АБРЕКСКАЯ, ДОМ 8 В ОФ.6, | X5: 05000 | Y5: 253601001 | Z5: 1042502960500 | AA5: 2536144625 | AB5: ООО ИМПОРТ-СЕРВИС | AC5: 690001, ПРИМОРСКИЙ КРАЙ, ВЛАДИВОСТОК, УЛ.АБРЕКСКАЯ, ДОМ 8 В ОФ.6, | AD5: 05000 | AE5: 253601001 | AF5: KR | AG5: КОРЕЯ, РЕСПУБЛИКА | AH5: 4307880.3 | AI5: 1042502960500 | AJ5: 2536144625 | AK5: ООО ИМПОРТ-СЕРВИС | AL5: 690001, ПРИМОРСКИЙ КРАЙ, ВЛАДИВОСТОК, УЛ.АБРЕКСКАЯ, ДОМ 8 В ОФ.6, | AM5: 05000 | AN5: 253601001 | AO5: KR | AP5: КОРЕЯ, РЕСПУБЛИКА | AQ5: КОРЕЯ, РЕСПУБЛИКА | AR5: RU | AS5: РОССИЯ | AT5: 0 | AU5: 1 | AV5: CFR | AW5: ВЛАДИВОСТОК | AX5: 1 | AY5: USD | AZ5: 62429.7 | BA5: 4307880 | BB5: 62429.7 | BC5: 69.0037 | BD5: 010 | BE5: 10 | BF5: 15120005/2733/0000/2/1 | BG5: - | BH5: 99 | BJ5: 10702000/180322/00045/2 | BL5: ПРИМОРСКИЙ КРАЙ | BM5: Г. ВЛАДИВОСТОК | BN5: УЛ.СТРЕЛЬНИКОВА,9 ВМТП | BO5: 10702030 т/п Морской порт Владивосток | BP5: 2 | BQ5: КОТЛЫ МАРКИ OLYMPIA ВОДОГРЕЙНЫЕ:ДИЗЕЛЬНЫЕ,ГАЗОВЫЕ ДЛЯ ЦЕНТРАЛЬНОГО ОТОПЛЕНИЯ, С ГОРЕЛКАМИ БЛОЧНЫМИ НА ЖИДКОМ ТОПЛИВЕ И ГАЗОВЫМИ ГОРЕЛКАМИ. КОД ОКП 493112 OLYMPIA OIL BOILER/ДИЗЕЛЬНЫЕ КОТЛЫ ВОДОГЕЙНЫЕ OLB-250F-R(Q=25000KCAL/H)WITH OIL BURNER (T | BR5: =ISNUMBER(SEARCH($BR$1,Таблица1[[#This Row],[31_1 Описание и характеристика товара]]))*1 -> 0 | BT5: OLYMPIA INDUSTRIAL CO.,LTD | BU5: 23 | BV5: 1 | BW5: 16 | BX5: ШТ | BY5: 0 | CA5: 2 | CB5: 8403109000 | CE5: KR | CF5: 5290.7 | CG5: ОООО-ОО | CH5: 4000000 | CI5: 4697.3 | CJ5: 0 | CM5: 32981 | CN5: 2275811 | CO5: 0 | CP5: 1 | CQ5: 2275811 | CR5: 32981 | CS5: 10 | CT5: 7.0213 | CX5: СУЩИНСКАЯ ТАТЬЯНА ЭДУАРДОВНА | CY5: 621
A6: 1 | B6: 45041 | C6: =IF(YEAR(Таблица1[[#This Row],[Дата]])=2023,MONTH(Таблица1[[#This Row],[Дата]]),0) -> 4 | D6: 10702070/191222/3455568 | E6: 10702070 | F6: 3455568 | G6: ИМ | H6: 40 | L6: NINGBO FOURTH PARTY LOGISTICS CO.,LTD | M6: 315000, ., NINGBO, RM 1815 FIFTH AVENUE HUAHONG NO.719 ZHONGXING RD N, | P6: 1 | Q6: 0 | R6: 1 | S6: 200 | T6: 1213000003908 | U6: 3019030445 | V6: ООО САРМАТ + | W6: 414041, АСТРАХАНСКАЯ ОБЛ.,Г.О. ГОРОД АСТРАХАНЬ, Г АСТРАХАНЬ, УЛ ЕРЕВАНСКАЯ,Д. 3, | X6: 12000 | Y6: 301901001 | Z6: 1213000003908 | AA6: 3019030445 | AB6: ООО САРМАТ + | AC6: 414041, АСТРАХАНСКАЯ ОБЛ.,Г.О. ГОРОД АСТРАХАНЬ, Г АСТРАХАНЬ, УЛ ЕРЕВАНСКАЯ,Д. 3, | AD6: 12000 | AE6: 301901001 | AF6: CN | AG6: КИТАЙ | AH6: 3570761.5 | AI6: 1213000003908 | AJ6: 3019030445 | AK6: ООО САРМАТ + | AL6: 414041, АСТРАХАНСКАЯ ОБЛ.,Г.О. ГОРОД АСТРАХАНЬ, Г АСТРАХАНЬ, УЛ ЕРЕВАНСКАЯ,Д. 3, | AM6: 12000 | AN6: 301901001 | AO6: CN | AP6: КИТАЙ | AQ6: КИТАЙ | AR6: RU | AS6: РОССИЯ | AT6: 0 | AU6: 1 | AV6: FOB | AW6: NINGBO | AX6: 1 | AY6: CNY | AZ6: 364800 | BA6: 3465469 | BB6: 55268.27 | BC6: 92.4382 | BD6: 010 | BE6: 10 | BF6: 22050007/2272/0026/2/1 | BG6: - | BH6: 99 | BJ6: 10702000/180322/00045/2 | BL6: ПРИМОРСКИЙ КРАЙ | BM6: ВЛАДИВОСТОК Г | BN6: СТРЕЛЬНИКОВА УЛ, ДОМ № 9 | BO6: 10702030 т/п Морской порт Владивосток | BP6: 1 | BQ6: КОТЛЫ БЫТОВЫЕ ЦЕНТРАЛЬНОГО ОТОПЛЕНИЯ, ВОДОГРЕЙНЫЕ, ГАЗОВЫЕ В СТАЛЬНОМ КОРПУСЕ; ДВУХКОНТУРНЫЕ НАСТЕННЫЕ ГАЗОВЫЕ КОТЛЫ. | BR6: =ISNUMBER(SEARCH($BR$1,Таблица1[[#This Row],[31_1 Описание и характеристика товара]]))*1 -> 0 | BT6: JIANGSU SPRING THERMAL TECHNOLOGY CO., LTD | BU6: 200 | BV6: 1 | BW6: 200 | BX6: ШТ | BY6: 0 | CA6: 1 | CB6: 8403109000 | CE6: CN | CF6: 7785 | CG6: ОООО-ОО | CH6: 4000000 | CI6: 7325 | CJ6: 0 | CM6: 364800 | CN6: 3372146 | CO6: 0 | CP6: 1 | CQ6: 3570761.5 | CR6: 55268.27 | CS6: 10 | CT6: 7.5452 | CU6: 1027 | CV6: 1027/22/1002-01 | CX6: ДОРОФЕЕВА ЕЛЕНА АЛЕКСАНДРОВНА | CY6: 215
A7: 0 | B7: 45180 | C7: =IF(YEAR(Таблица1[[#This Row],[Дата]])=2023,MONTH(Таблица1[[#This Row],[Дата]]),0) -> 9 | D7: 10702070/191222/3454036 | E7: 10702070 | F7: 3454036 | G7: ИМ | H7: 78 | L7: HAINAN LITA IMPORT & EXPORT TRADE CO., LTD | M7: , , DISTRICT HAIKOU CITY, SAN XIAN HUI FU, NO.9 CHANG BIN 4TH ROAD, XIU YING, | P7: 3 | Q7: 0 | R7: 7 | S7: 9 | T7: 1024900953043 | U7: 4909021566 | V7: СП ЗАО ОМСУКЧАНСКАЯ ГОРНО-ГЕОЛОГИЧЕСКАЯ КОМПАНИЯ | W7: 685030```, `````МАГАДАНСКАЯ ОБЛАСТЬ, Г. МАГАДАН, УЛ. ПРОЛЕТАРСКАЯ, Д. 84, КОРП. | X7: 44000 | Y7: 490901001 | Z7: 1024900953043 | AA7: 4909021566 | AB7: СП ЗАО ОМСУКЧАНСКАЯ ГОРНО-ГЕОЛОГИЧЕСКАЯ КОМПАНИЯ | AC7: 685030```, `````МАГАДАНСКАЯ ОБЛАСТЬ, Г. МАГАДАН, УЛ. ПРОЛЕТАРСКАЯ, Д. 84, КОРП. | AD7: 44000 | AE7: 490901001 | AF7: CN | AG7: КИТАЙ | AH7: 2159726.1 | AI7: 1024900953043 | AJ7: 4909021566 | AK7: СП ЗАО ОМСУКЧАНСКАЯ ГОРНО-ГЕОЛОГИЧЕСКАЯ КОМПАНИЯ | AL7: 685030```, `````МАГАДАНСКАЯ ОБЛАСТЬ, Г. МАГАДАН, УЛ. ПРОЛЕТАРСКАЯ, Д. 84, КОРП. | AM7: 44000 | AN7: 490901001 | AO7: CN | AP7: КИТАЙ | AQ7: КИТАЙ | AR7: RU | AS7: РОССИЯ | AT7: 1 | AU7: 1 | AV7: CIF | AW7: MAGADAN | AX7: 1 | AY7: CNY | AZ7: 233640 | BA7: 2219496 | BB7: 33428.26 | BC7: 92.4382 | BD7: 010 | BE7: 10 | BG7: - | BH7: 99 | BJ7: 10707000/251122/00089/2 | BL7: МАГАДАНСКАЯ ОБЛ. | BM7: Г. МАГАДАН | BN7: ММТП | BO7: 10707160 т/п Морской порт Магадан | BP7: 3 | BQ7: БОЙЛЕР ЕМКОСТНОЙ НЕЭЛЕКТРИЧЕСКИЙ ВЕРТИКАЛЬНОГО ИСПОЛНЕНИЯ, ПРЕДНАЗНАЧЕН ДЛЯ ОТОПЛЕНИЯ КОМНАТ ФАБРИКИ, ОБЪЕМОМ 0.75 М3, РАСХОД ТОПЛИВА 10 КГ/Ч, ВЫХОДНАЯ МОЩНОСТЬ 120 КВТ, ПЛОЩАДЬ ОБОГРЕВА 1000 КВ.М., НАПРЯЖЕНИЕ 120 ВОЛЬТ, ОСНАЩЕН КОМПЛЕКТОМ | BR7: =ISNUMBER(SEARCH($BR$1,Таблица1[[#This Row],[31_1 Описание и характеристика товара]]))*1 -> 0 | BT7: DONGGUAN HENGSEN THERMAL ENERGY TECHNOLOGY CO.,LTD | BU7: 2 | BV7: 1 | BW7: 1 | BX7: ШТ | BY7: 0 | CA7: 7 | CB7: 8403109000 | CE7: CN | CF7: 338 | CG7: ООПП-ПП | CH7: 7800171 | CI7: 303 | CJ7: 0 | CM7: 40085 | CN7: 370539 | CO7: 0 | CP7: 1 | CQ7: 370538.52 | CR7: 5735.2 | CS7: 10 | CT7: 18.9281 | CU7: 860 | CV7: 0714/00-15-01 | CX7: БЕЛЬМАС ЭДУАРД ВЛАДИМИРОВИЧ | CY7: 483
A8: 1 | B8: 44943 | C8: =IF(YEAR(Таблица1[[#This Row],[Дата]])=2023,MONTH(Таблица1[[#This Row],[Дата]]),0) -> 1 | D8: 10702070/151222/3450013 | E8: 10702070 | F8: 3450013 | G8: ИМ | H8: 40 | L8: HEATMASTER (NANTONG) BOILER CO., LTD | M8: , JIANGSU PROVINCE, NANTONG CITY, XINGHE ROAD, GANGZHA ECONOMIC DEVELOPMENT ZONE | P8: 1 | Q8: 0 | R8: 1 | S8: 13 | T8: 1095190011333 | U8: 5190909506 | V8: АО НОРД ВЕСТ ФЛОТ КОМПАНИ | W8: 183039, МУРМАНСКАЯ ОБЛАСТЬ, МУРМАНСК, РОГОЗЕРСКАЯ, 15 | X8: 47000 | Y8: 519001001 | Z8: 1095190011333 | AA8: 5190909506 | AB8: АО НОРД ВЕСТ ФЛОТ КОМПАНИ | AC8: 183039, МУРМАНСКАЯ ОБЛАСТЬ, МУРМАНСК, РОГОЗЕРСКАЯ, 15 | AD8: 47000 | AE8: 519001001 | AF8: CN | AG8: КИТАЙ | AH8: 8357933.8 | AI8: 1095190011333 | AJ8: 5190909506 | AK8: АО НОРД ВЕСТ ФЛОТ КОМПАНИ | AL8: 183039, МУРМАНСКАЯ ОБЛАСТЬ, МУРМАНСК, РОГОЗЕРСКАЯ, 15 | AM8: 47000 | AN8: 519001001 | AO8: CN | AP8: КИТАЙ | AQ8: КИТАЙ | AR8: RU | AS8: РОССИЯ | AT8: 0 | AU8: 1 | AV8: FCA | AW8: NANTONG CITY | AX8: 1 | AY8: EUR | AZ8: 120850 | BA8: 8151067 | BB8: 131913.92 | BC8: 67.4478 | BD8: 010 | BE8: 10 | BF8: 21110073/1326/0002/2/1 | BG8: - | BH8: 99 | BJ8: 10702000/180322/00045/2 | BL8: ПРИМОРСКИЙ КРАЙ | BM8: Г.ВЛАДИВОСТОК | BN8: УЛ.СТРЕЛЬНИКОВА | BO8: 10702030 т/п Морской порт Владивосток | BP8: 1 | BQ8: СИСТЕМА ПОДОГРЕВА ВОДЫ НА СУДНЕ, ПОСТАВЛЯЕТСЯ В РАЗОБРАННОМ ВИДЕ ДЛЯ УДОБСТВА ТРАНСПОРТИРОВКИ. ВВОЗИТСЯ ДЛЯ СОБСТВЕННОГО ИСПОЛЬЗОВАНИЯ; ПРОДАЖЕ НЕ ПОДЛЕЖИТ | BR8: =ISNUMBER(SEARCH($BR$1,Таблица1[[#This Row],[31_1 Описание и характеристика товара]]))*1 -> 0 | BT8: HEATMASTER (NANTONG) BOILER CO., LTD | BU8: 13 | BV8: 1 | BW8: 1 | BX8: ШТ | BY8: 0 | CA8: 1 | CB8: 8403109000 | CC8: С | CE8: CN | CF8: 3760 | CG8: ОООО-ОО | CH8: 4000000 | CI8: 3500 | CJ8: 0 | CM8: 120850 | CN8: 8151067 | CO8: 0 | CP8: 1 | CQ8: 8357933.8 | CR8: 131913.92 | CS8: 10 | CT8: 37.6897 | CU8: 1067 | CV8: 202012/32 | CX8: РОССОЛОВ АРТЕМ НИКОЛАЕВИЧ | CY8: 0
A9: 1 | B9: 44772 | C9: =IF(YEAR(Таблица1[[#This Row],[Дата]])=2023,MONTH(Таблица1[[#This Row],[Дата]]),0) -> 0 | D9: 10511010/281222/3174551 | E9: 10511010 | F9: 3174551 | G9: ИМ | H9: 40 | L9: UNICAL A.G. S.P.A. | M9: 460033, , CASTEL D'ARIO (MN), VIA ROMA 123, | P9: 1 | Q9: 0 | R9: 1 | S9: 9 | T9: 1069674029050 | U9: 6674177799 | V9: ООО КОТЕЛЬНЫЕ СИСТЕМЫ УРАЛА | W9: 620076, СВЕРДЛОВСКАЯ ОБЛ, Г ЕКАТЕРИНБУРГ, ГОНЧАРНЫЙ ПЕР, ДОМ 4 | X9: 65000 | Y9: 667901001 | Z9: 1069674029050 | AA9: 6674177799 | AB9: ООО КОТЕЛЬНЫЕ СИСТЕМЫ УРАЛА | AC9: 620076, СВЕРДЛОВСКАЯ ОБЛ, Г ЕКАТЕРИНБУРГ, ГОНЧАРНЫЙ ПЕР, ДОМ 4 | AD9: 65000 | AE9: 667901001 | AF9: IT | AG9: ИТАЛИЯ | AH9: 2536832.6 | AI9: 1069674029050 | AJ9: 6674177799 | AK9: ООО КОТЕЛЬНЫЕ СИСТЕМЫ УРАЛА | AL9: 620076, СВЕРДЛОВСКАЯ ОБЛ, Г ЕКАТЕРИНБУРГ, ГОНЧАРНЫЙ ПЕР, ДОМ 4 | AM9: 65000 | AN9: 667901001 | AO9: IT | AP9: ИТАЛИЯ | AQ9: ИТАЛИЯ | AR9: RU | AS9: РОССИЯ | AT9: 2 | AU9: 0 | AV9: FCA | AW9: BORGOCАRBONARA (MN) | AX9: 1 | AY9: EUR | AZ9: 29757 | BA9: 2207461 | BB9: 36274.36 | BC9: 74.1829 | BD9: 010 | BF9: 21110008/1481/0373/2/1 | BG9: - | BH9: 11 | BI9: 10113/160611/10039/6 | BL9: СМОЛЕНСКАЯ ОБЛАСТЬ | BM9: КРАСНИНСКИЙ РАЙОН | BN9: В 250 М ЗАПАДНЕЕ Д.БУДА И СЕВЕРНЕЕ (В 650 М) ЖЕЛЕ | BO9: 10113090 т/п Краснинский | BP9: 1 | BQ9: КОТЛЫ СТАЛЬНЫЕ,ВОДОГРЕЙНЫЕ,ДЫМОГАРНЫЕ,ДВУХХОДОВЫЕ ПРОМЫШЛЕННЫЕ: АРТ.102258RU/UNICAL ELLPREX 970-7ШТ. ПРЕДНАЗНАЧЕНЫ ДЛЯ РАБОТЫ НА ГАЗООБРАЗНОМ И ЖИДКОМ ТОПЛИВЕ И ПРИМЕНЕНИЯ В СИСТЕМАХ ЦЕНТРАЛЬНОГО ОТОПЛЕНИЯ С ТЕМПЕРАТУРОЙ ДО 100С | BR9: =ISNUMBER(SEARCH($BR$1,Таблица1[[#This Row],[31_1 Описание и характеристика товара]]))*1 -> 0 | BT9: UNICAL AG S.P.A. | BU9: 9 | BV9: 0 | BW9: 7 | BX9: ШТ | BY9: 0 | CA9: 1 | CB9: 8403109000 | CE9: IT | CF9: 11797 | CG9: ОООО-ОО | CH9: 4000000 | CI9: 11767 | CJ9: 0 | CM9: 29757 | CN9: 2207461 | CO9: 0 | CP9: 1 | CQ9: 2536832.6 | CR9: 36274.36 | CS9: 10 | CT9: 3.0827 | CX9: ФАЙЗУЛИНА ДАРЬЯ ВИТАЛЬЕВНА | CY9: 0
A10: 1 | B10: 45243 | C10: =IF(YEAR(Таблица1[[#This Row],[Дата]])=2023,MONTH(Таблица1[[#This Row],[Дата]]),0) -> 11 | D10: 10418010/221222/3235079 | E10: 10418010 | F10: 3235079 | G10: ИМ | H10: 40 | L10: VARMECOM INDUSTRY INC. | M10: , ESKISEHIR, ODUNPAZAR, 75TH YEAR OSB DISTRICT, STREET 104, 12 | P10: 1 | Q10: 0 | R10: 1 | S10: 595 | T10: 1060278101982 | U10: 0278122273 | V10: ООО ГАЗСТРОЙИНВЕСТ | W10: 450006, РЕСПУБЛИКА БАШКОРТОСТАН, УФА, УЛ. 50-ЛЕТИЯ ОКТЯБРЯ, 15 | X10: 80000 | Y10: 027801001 | Z10: 1060278101982 | AA10: 0278122273 | AB10: ООО ГАЗСТРОЙИНВЕСТ | AC10: 450006, РЕСПУБЛИКА БАШКОРТОСТАН, УФА, УЛ. 50-ЛЕТИЯ ОКТЯБРЯ, 15 | AD10: 80000 | AE10: 027801001 | AF10: TR | AG10: ТУРЦИЯ | AH10: 12796878 | AI10: 1060278101982 | AJ10: 0278122273 | AK10: ООО ГАЗСТРОЙИНВЕСТ | AL10: 450006, РЕСПУБЛИКА БАШКОРТОСТАН, УФА, УЛ. 50-ЛЕТИЯ ОКТЯБРЯ, 15 | AM10: 80000 | AN10: 027801001 | AO10: TR | AP10: ТУРЦИЯ | AQ10: ТУРЦИЯ | AR10: RU | AS10: РОССИЯ | AT10: 2 | AU10: 0 | AV10: EXW | AW10: ESKISEHIR | AX10: 1 | AY10: EUR | AZ10: 165890.25 | BA10: 12456931 | BB10: 181450.12 | BC10: 75.0914 | BD10: 010 | BF10: 22110036/3292/0006/2/1 | BG10: - | BH10: 11 | BI10: 10413/070318/10059/1 | BL10: САРАТОВСКАЯ ОБЛ. | BM10: Г. САРАТОВ | BN10: УЛ. ТАМОЖЕННЫЙ ПР-Д, Д. 6 | BO10: 10413070 т/п Саратовский | BP10: 1 | BQ10: ГАЗОВЫЙ НАСТЕННЫЙ КОТЕЛ КОНВЕКЦИОННОГО ТИПА FEDERICA BUGATTI VARME ПРЕДНАЗНАЧЕН ДЛЯ ОТОПЛЕНИЯ И ПРИГОТОВЛЕНИЯ ГОРЯЧЕЙ ВОДЫ В КОТТЕДЖАХ, В КВАРТИРАХ МНОГОЭТАЖНЫХ ДОМОВ С КОЛЛЕКТИВНЫМИ ДЫМОХОДАМИ И ДРУГИХ ЗДАНИЯХ ПЛОЩАДЬЮ ДО 360 М2. | BR10: =ISNUMBER(SEARCH($BR$1,Таблица1[[#This Row],[31_1 Описание и характеристика товара]]))*1 -> 0 | BT10: VARMECOM INDUSTRY | BU10: 595 | BV10: 0 | BW10: 595 | BX10: ШТ | BY10: 0 | CA10: 1 | CB10: 8403109000 | CE10: TR | CF10: 19367 | CG10: ОООО-ОО | CH10: 4000000 | CI10: 17498 | CJ10: 0 | CM10: 165890.25 | CN10: 12456931 | CO10: 0 | CP10: 1 | CQ10: 12796878 | CR10: 181450.12 | CS10: 10 | CT10: 10.3698 | CU10: 696 | CV10: ТБ696/18/06/15/3 | CX10: ДАВИТАШВИЛИ ДЖАМАЛ РОЛАНДОВИЧ | CY10: 113
A11: 1 | B11: 45136 | C11: =IF(YEAR(Таблица1[[#This Row],[Дата]])=2023,MONTH(Таблица1[[#This Row],[Дата]]),0) -> 7 | D11: 10323010/161222/3178880 | E11: 10323010 | F11: 3178880 | G11: ИМ | H11: 40 | L11: S PLUSZ K TECHNIK KFT | M11: 4400, HUNGARY, NYIREGYHAZA, VAY ADAM KRT.4-6. 2/208, | P11: 5 | Q11: 0 | R11: 11 | S11: 383 | T11: 1026102578017 | U11: 6154001478 | V11: ООО ЛЕМАКС | W11: 347913, ОБЛАСТЬ РОСТОВСКАЯ, ТАГАНРОГ, УЛИЦА НИКОЛАЕВСКОЕ ШОССЕ, Д0М.10, КОРПУС В | X11: 60000 | Y11: 615401001 | Z11: 1026102578017 | AA11: 6154001478 | AB11: ООО ЛЕМАКС | AC11: 347913, ОБЛАСТЬ РОСТОВСКАЯ, ТАГАНРОГ, УЛИЦА НИКОЛАЕВСКОЕ ШОССЕ, Д0М.10, КОРПУС В | AD11: 60000 | AE11: 615401001 | AF11: HU | AG11: ВЕНГРИЯ | AH11: 22359773 | AI11: 1026102578017 | AJ11: 6154001478 | AK11: ООО ЛЕМАКС | AL11: 347913, ОБЛАСТЬ РОСТОВСКАЯ, ТАГАНРОГ, УЛИЦА НИКОЛАЕВСКОЕ ШОССЕ, Д0М.10, КОРПУС В | AM11: 60000 | AN11: 615401001 | AO11: HU | AP11: ВЕНГРИЯ | AQ11: ВЕНГРИЯ | AR11: RU | AS11: РОССИЯ | AT11: 2 | AU11: 0 | AV11: EXW | AW11: ZSURK | AX11: 1 | AY11: EUR | AZ11: 321360.06 | BA11: 21996132 | BB11: 347733.27 | BC11: 68.447 | BD11: 010 | BE11: 31 | BF11: 19060035/1481/1898/2/1 | BG11: - | BH11: 99 | BJ11: 1237 | BK11: 197761 | BL11: САНКТ-ПЕТЕРБУРГ | BM11: КРОНШТАДТ | BN11: КРОНШТАДТСКОЕ Ш., Д.33, ЛИТЕР А | BO11: 10210040 т/п Котлинский | BP11: 1 | BQ11: КОТЛЫ ОТОПИТЕЛЬНЫЕ ЭЛЕКТРИЧЕСКИЕ , ПРЕДНАЗНАЧЕНЫ ДЛЯ ОТОПЛЕНИЯ ПОМЕЩЕНИЙ ТОРГОВОЙ МАРКИ LEMАХ | BR11: =ISNUMBER(SEARCH($BR$1,Таблица1[[#This Row],[31_1 Описание и характеристика товара]]))*1 -> 0 | BT11: S PLUSZ K TECHNIK KFT. | BU11: 368 | BV11: 0 | BW11: 420 | BX11: ШТ | BY11: 0 | CA11: 1 | CB11: 8403109000 | CC11: С | CE11: HU | CF11: 9487.075 | CG11: ОООО-ОО | CH11: 4000000 | CI11: 8750.825 | CJ11: 0 | CM11: 133189.06 | CN11: 9116392 | CO11: 0 | CP11: 1 | CQ11: 9389407.4 | CR11: 146021.59 | CS11: 10 | CT11: 16.6866 | CU11: 1117 | CV11: 0149/01-173 | CX11: АНТРОПОВА ОЛЬГА ВЕНИАМИНОВНА | CY11: 92
A12: 1 | B12: 44995 | C12: =IF(YEAR(Таблица1[[#This Row],[Дата]])=2023,MONTH(Таблица1[[#This Row],[Дата]]),0) -> 3 | D12: 10317120/301222/3176625 | E12: 10317120 | F12: 3176625 | G12: ИМ | H12: 40 | L12: VARMECOM INDUSTRY(VARMECOM ENDUSTRIYEL SANAYI VE TICARET ANONIM SIRKETI) | M12: 49308, ODUNPAZARI, ESKISEHIR, KOBI ORGANIZE SANAYI BOLGESI 75 YIL OSB MAH. 104 C | P12: 2 | Q12: 0 | R12: 4 | S12: 496 | T12: 1131650002494 | U12: 1650258175 | V12: ООО ТД ГИГАЗ | W12: 450000, РЕСПУБЛИКА БАШКОРТОСТАН, Г. УФА, УЛ. 50-ЛЕТИЯ ОКТЯБРЯ, 15 | X12: 80000 | Y12: 027801001 | Z12: 1131650002494 | AA12: 1650258175 | AB12: ООО ТД ГИГАЗ | AC12: 450000, РЕСПУБЛИКА БАШКОРТОСТАН, Г. УФА, УЛ. 50-ЛЕТИЯ ОКТЯБРЯ, 15 | AD12: 80000 | AE12: 027801001 | AF12: TR | AG12: ТУРЦИЯ | AH12: 11038148 | AI12: 1131650002494 | AJ12: 1650258175 | AK12: ООО ТД ГИГАЗ | AL12: 450000, РЕСПУБЛИКА БАШКОРТОСТАН, Г. УФА, УЛ. 50-ЛЕТИЯ ОКТЯБРЯ, 15 | AM12: 80000 | AN12: 027801001 | AO12: TR | AP12: ТУРЦИЯ | AQ12: ТУРЦИЯ | AR12: RU | AS12: РОССИЯ | AT12: 0 | AU12: 1 | AV12: EXW | AW12: ESKISEHIR | AX12: 1 | AY12: EUR | AZ12: 139586.16 | BA12: 10619227 | BB12: 153354.9 | BC12: 76.0765 | BD12: 010 | BF12: 22080001/0067/0000/2/1 | BG12: - | BH12: 99 | BJ12: 10317000/031221/00006/2 | BL12: КРАСНОДАРСКИЙ КРАЙ | BM12: НОВОРОССИЙСК | BN12: УЛ. СУХУМСКОЕ ШОССЕ, ПЗТК ООО НУТЭП | BO12: 10317110 т/п Новороссийский юго-восточный | BP12: 1 | BQ12: КОТЕЛЬНАЯ АВТОМАТИЗИРОВАННАЯ ИЗ МЕТАЛЛА(НЕ ИЗ ЧУГУНА), НОМИНАЛЬНОЙ ТЕПЛОПРОИЗВОДИТЕЛЬНОСТЬЮ ДО 33 КВТ. ПРЕДНАЗНАЧЕНА ДЛЯ ИСПОЛЬЗОВАНИЯ В КАЧЕСТВЕ ИСТОЧНИКА ТЕПЛОНОСИТЕЛЯ И ГОРЯЧЕЙ ВОДЫ ДЛЯ ЗДАНИЙ И СООРУЖЕНИЙ РАЗЛИЧНОГО НАЗНАЧЕНИЯ. КОТЕЛЬНАЯ | BR12: =ISNUMBER(SEARCH($BR$1,Таблица1[[#This Row],[31_1 Описание и характеристика товара]]))*1 -> 0 | BT12: VARMECOM INDUSTRY | BU12: 486 | BV12: 1 | BW12: 486 | BX12: ШТ | BY12: 0 | CA12: 1 | CB12: 8403109000 | CE12: TR | CF12: 15217.3 | CG12: ОООО-ОО | CH12: 4000000 | CI12: 14354.1 | CJ12: 0 | CM12: 133319 | CN12: 10142443 | CO12: 0 | CP12: 1 | CQ12: 10555046 | CR12: 146643.08 | CS12: 10 | CT12: 10.2161 | CU12: 727 | CV12: 0491/01-15/009 | CX12: ЗАРИПОВ ЭДУАРД КАМИЛЬЕВИЧ | CY12: 0
A13: 1 | B13: 44940 | C13: =IF(YEAR(Таблица1[[#This Row],[Дата]])=2023,MONTH(Таблица1[[#This Row],[Дата]]),0) -> 1 | D13: 10317120/301222/3176508 | E13: 10317120 | F13: 3176508 | G13: ИМ | H13: 40 | L13: VARMECOM INDUSTRY(VARMECOM ENDUSTRIYEL SANAYI VE TICARET ANONIM SIRKETI) | M13: 49308, ODUNPAZARI, ESKISEHIR, KOBI ORGANIZE SANAYI BOLGESI 75 YIL OSB MAH. 104 C | P13: 1 | Q13: 0 | R13: 1 | S13: 490 | T13: 1131650002494 | U13: 1650258175 | V13: ООО ТД ГИГАЗ | W13: 450000, РЕСПУБЛИКА БАШКОРТОСТАН, Г. УФА, УЛ. 50-ЛЕТИЯ ОКТЯБРЯ, 15 | X13: 80000 | Y13: 027801001 | Z13: 1131650002494 | AA13: 1650258175 | AB13: ООО ТД ГИГАЗ | AC13: 450000, РЕСПУБЛИКА БАШКОРТОСТАН, Г. УФА, УЛ. 50-ЛЕТИЯ ОКТЯБРЯ, 15 | AD13: 80000 | AE13: 027801001 | AF13: TR | AG13: ТУРЦИЯ | AH13: 10222790 | AI13: 1131650002494 | AJ13: 1650258175 | AK13: ООО ТД ГИГАЗ | AL13: 450000, РЕСПУБЛИКА БАШКОРТОСТАН, Г. УФА, УЛ. 50-ЛЕТИЯ ОКТЯБРЯ, 15 | AM13: 80000 | AN13: 027801001 | AO13: TR | AP13: ТУРЦИЯ | AQ13: ТУРЦИЯ | AR13: RU | AS13: РОССИЯ | AT13: 0 | AU13: 1 | AV13: EXW | AW13: ESKISEHIR | AX13: 1 | AY13: EUR | AZ13: 129000 | BA13: 9813869 | BB13: 142026.98 | BC13: 76.0765 | BD13: 010 | BF13: 22080001/0067/0000/2/1 | BG13: - | BH13: 99 | BJ13: 10317000/031221/00006/2 | BL13: КРАСНОДАРСКИЙ КРАЙ | BM13: НОВОРОССИЙСК | BN13: УЛ. СУХУМСКОЕ ШОССЕ, ПЗТК ООО НУТЭП | BO13: 10317110 т/п Новороссийский юго-восточный | BP13: 1 | BQ13: КОТЕЛЬНАЯ АВТОМАТИЗИРОВАННАЯ ИЗ МЕТАЛЛА(НЕ ИЗ ЧУГУНА), НОМИНАЛЬНОЙ ТЕПЛОПРОИЗВОДИТЕЛЬНОСТЬЮ ДО 33 КВТ. ПРЕДНАЗНАЧЕНА ДЛЯ ИСПОЛЬЗОВАНИЯ В КАЧЕСТВЕ ИСТОЧНИКА ТЕПЛОНОСИТЕЛЯ И ГОРЯЧЕЙ ВОДЫ ДЛЯ ЗДАНИЙ И СООРУЖЕНИЙ РАЗЛИЧНОГО НАЗНАЧЕНИЯ. КОТЕЛЬНАЯ | BR13: =ISNUMBER(SEARCH($BR$1,Таблица1[[#This Row],[31_1 Описание и характеристика товара]]))*1 -> 0 | BT13: VARMECOM INDUSTRY | BU13: 490 | BV13: 1 | BW13: 490 | BX13: ШТ | BY13: 0 | CA13: 1 | CB13: 8403109000 | CE13: TR | CF13: 15034 | CG13: ОООО-ОО | CH13: 4000000 | CI13: 14207 | CJ13: 0 | CM13: 129000 | CN13: 9813869 | CO13: 0 | CP13: 1 | CQ13: 10222790 | CR13: 142026.98 | CS13: 10 | CT13: 9.997 | CU13: 727 | CV13: 0491/01-15/009 | CX13: ЗАРИПОВ ЭДУАРД КАМИЛЬЕВИЧ | CY13: 0
A14: 1 | B14: 44610 | C14: =IF(YEAR(Таблица1[[#This Row],[Дата]])=2023,MONTH(Таблица1[[#This Row],[Дата]]),0) -> 0 | D14: 10317120/261222/3173190 | E14: 10317120 | F14: 3173190 | G14: ИМ | H14: 40 | L14: ELEKS DIS TICARET A.S. | M14: 34394, SISLI, ISTANBUL, ESENTERE MAH.KASAR SK. ELGINKAN HOLDING BLOK NO:15, | P14: 2 | Q14: 0 | R14: 4 | S14: 471 | T14: 1197746381986 | U14: 7720470130 | V14: ООО ВЕССЕН | W14: 109518, ЮВАО РАЙОН ТЕКСТИЛЬЩИКИ, Г. МОСКВА, 1-Й ГРАЙВОРОНОВСКИЙ ПРОЕЗД, Д. 20, С | X14: 45000 | Y14: 772201001 | Z14: 1197746381986 | AA14: 7720470130 | AB14: ООО ВЕССЕН | AC14: 109518, ЮВАО РАЙОН ТЕКСТИЛЬЩИКИ, Г. МОСКВА, 1-Й ГРАЙВОРОНОВСКИЙ ПРОЕЗД, Д. 20, С | AD14: 45000 | AE14: 772201001 | AF14: TR | AG14: ТУРЦИЯ | AH14: 9189223.9 | AI14: 1197746381986 | AJ14: 7720470130 | AK14: ООО ВЕССЕН | AL14: 109518, ЮВАО РАЙОН ТЕКСТИЛЬЩИКИ, Г. МОСКВА, 1-Й ГРАЙВОРОНОВСКИЙ ПРОЕЗД, Д. 20, С | AM14: 45000 | AN14: 772201001 | AO14: TR | AP14: ТУРЦИЯ | AQ14: ТУРЦИЯ | AR14: RU | AS14: РОССИЯ | AT14: 0 | AU14: 1 | AV14: FCA | AW14: MANISA (ТУРЦИЯ) | AX14: 1 | AY14: USD | AZ14: 131226.62 | BA14: 9012119 | BB14: 133805.46 | BC14: 68.676 | BD14: 010 | BF14: 20050760/1326/0000/2/1 | BG14: - | BH14: 95 | BJ14: 10317000/021222/00006/2 | BL14: КРАСНОДАРСКИЙ КРАЙ | BM14: Г. НОВОРОССИЙСК | BN14: СУХУМСКОЕ ШОССЕ, Д.17А | BO14: 10317110 т/п Новороссийский юго-восточный | BP14: 1 | BQ14: КОТЛЫ БЫТОВЫЕ, ЦЕНТРАЛЬНОГО ОТОПЛЕНИЯ, ГАЗОВЫЕ, ОДНОКОНТУРНЫЕ, НАСТЕННЫЕ. ТОРГОВАЯ МАРКА Е.С.А., ИЗГОТОВЛЕНЫ ИЗ КОМПОЗИТНЫХ МАТЕРИАЛОВ, ЛАТУННЫХ И МЕТАЛЛИЧЕСКИХ ЧАСТЕЙ, В КОМПЛЕКТЕ С ИНСТРУКЦИЕЙ ПО УСТАНОВКЕ И ЭКСПЛУАТАЦИИ И КРЕПЕЖНОЙ ФУРНИТУРОЙ. | BR14: =ISNUMBER(SEARCH($BR$1,Таблица1[[#This Row],[31_1 Описание и характеристика товара]]))*1 -> 0 | BT14: EMAS MAKINA SANAYI A.S. | BU14: 305 | BV14: 1 | BW14: 305 | BX14: ШТ | BY14: 0 | CA14: 1 | CB14: 8403109000 | CE14: TR | CF14: 10190 | CG14: ОООО-ОО | CH14: 4000000 | CI14: 9677 | CJ14: 0 | CM14: 111308.47 | CN14: 7644220 | CO14: 0 | CP14: 1 | CQ14: 7811476.8 | CR14: 113743.91 | CS14: 10 | CT14: 11.754 | CU14: 1405 | CV14: 140 | CX14: КОЛЕСНИКОВА ЕКАТЕРИНА ИВАНОВНА | CY14: 308
A15: 1 | B15: 44860 | C15: =IF(YEAR(Таблица1[[#This Row],[Дата]])=2023,MONTH(Таблица1[[#This Row],[Дата]]),0) -> 0 | D15: 10317120/261222/3173172 | E15: 10317120 | F15: 3173172 | G15: ИМ | H15: 40 | L15: KATRE ISI SANAYI TICARET A. S. | M15: 34394, ZEYTINBURNU/, ISTANBUL, SEYITNIZAM MAH. DEMIRCILER SITESI 1 YOL NO:73/75, | P15: 2 | Q15: 0 | R15: 2 | S15: 11 | T15: 1197746381986 | U15: 7720470130 | V15: ООО ВЕССЕН | W15: 109518, ВН.ТЕР.Г. МУНИЦИПАЛЬНЫЙ ОКРУГ ТЕКСТИЛЬЩИКИ, МОСКВА, 1-Й ГРАЙВОРОНОВСКИЙ | X15: 45000 | Y15: 772201001 | Z15: 1197746381986 | AA15: 7720470130 | AB15: ООО ВЕССЕН | AC15: 109518, ВН.ТЕР.Г. МУНИЦИПАЛЬНЫЙ ОКРУГ ТЕКСТИЛЬЩИКИ, МОСКВА, 1-Й ГРАЙВОРОНОВСКИЙ | AD15: 45000 | AE15: 772201001 | AF15: TR | AG15: ТУРЦИЯ | AH15: 2934124.7 | AI15: 1197746381986 | AJ15: 7720470130 | AK15: ООО ВЕССЕН | AL15: 109518, ВН.ТЕР.Г. МУНИЦИПАЛЬНЫЙ ОКРУГ ТЕКСТИЛЬЩИКИ, МОСКВА, 1-Й ГРАЙВОРОНОВСКИЙ | AM15: 45000 | AN15: 772201001 | AO15: TR | AP15: ТУРЦИЯ | AQ15: ТУРЦИЯ | AR15: RU | AS15: РОССИЯ | AT15: 0 | AU15: 1 | AV15: FCA | AW15: ISTANBUL | AX15: 1 | AY15: USD | AZ15: 41551.64 | BA15: 2853600 | BB15: 42724.17 | BC15: 68.676 | BD15: 010 | BF15: 20081050/1326/0000/2/1 | BG15: - | BH15: 95 | BJ15: 10317000/021222/00006/2 | BL15: КРАСНОДАРСКИЙ КРАЙ | BM15: Г. НОВОРОССИЙСК | BN15: СУХУМСКОЕ ШОССЕ, Д.17А | BO15: 10317110 т/п Новороссийский юго-восточный | BP15: 1 | BQ15: КОТЛЫ БЫТОВЫЕ, ЦЕНТРАЛЬНОГО ОТОПЛЕНИЯ, ГАЗОВЫЕ, ОДНОКОНТУРНЫЕ, НАСТЕННЫЕ. ТОРГОВАЯ МАРКА Е.С.А., ИЗГОТОВЛЕНЫ ИЗ КОМПОЗИТНЫХ МАТЕРИАЛОВ, ЛАТУННЫХ И МЕТАЛЛИЧЕСКИХ ЧАСТЕЙ, В КОМПЛЕКТЕ С ИНСТРУКЦИЕЙ ПО УСТАНОВКЕ И ЭКСПЛУАТАЦИИ И КРЕПЕЖНОЙ ФУРНИТУРОЙ. С | BR15: =ISNUMBER(SEARCH($BR$1,Таблица1[[#This Row],[31_1 Описание и характеристика товара]]))*1 -> 0 | BT15: ЕМАS MAKINA SANAYI A.S. | BU15: 10 | BV15: 1 | BW15: 10 | BX15: ШТ | BY15: 0 | CA15: 1 | CB15: 8403109000 | CE15: TR | CF15: 1815 | CG15: ОООО-ОО | CH15: 4000000 | CI15: 1794 | CJ15: 0 | CM15: 13718.04 | CN15: 942100 | CO15: 0 | CP15: 1 | CQ15: 971889.59 | CR15: 14151.81 | CS15: 10 | CT15: 7.8884 | CU15: 1405 | CV15: 140 | CX15: КОЛЕСНИКОВА ЕКАТЕРИНА ИВАНОВНА | CY15: 145
A16: 1 | B16: 45112 | C16: =IF(YEAR(Таблица1[[#This Row],[Дата]])=2023,MONTH(Таблица1[[#This Row],[Дата]]),0) -> 7 | D16: 10317120/261222/3173152 | E16: 10317120 | F16: 3173152 | G16: ИМ | H16: 40 | L16: VESSEN DIS TICARET A. S. | M16: , ZEYTINBURNU, ISTANBUL, SEYITNIZAM MAH. DEMIRCILER SITESI 1 YOL NO:75, | P16: 1 | Q16: 0 | R16: 1 | S16: 1 | T16: 1197746381986 | U16: 7720470130 | V16: ООО ВЕССЕН | W16: 109518, ЮВАО РАЙОН ТЕКСТИЛЬЩИКИ, Г. МОСКВА, 1-Й ГРАЙВОРОНОВСКИЙ ПРОЕЗД, Д. 20, С | X16: 45000 | Y16: 772201001 | Z16: 1197746381986 | AA16: 7720470130 | AB16: ООО ВЕССЕН | AC16: 109518, ЮВАО РАЙОН ТЕКСТИЛЬЩИКИ, Г. МОСКВА, 1-Й ГРАЙВОРОНОВСКИЙ ПРОЕЗД, Д. 20, С | AD16: 45000 | AE16: 772201001 | AF16: TR | AG16: ТУРЦИЯ | AH16: 323452.87 | AI16: 1197746381986 | AJ16: 7720470130 | AK16: ООО ВЕССЕН | AL16: 109518, ЮВАО РАЙОН ТЕКСТИЛЬЩИКИ, Г. МОСКВА, 1-Й ГРАЙВОРОНОВСКИЙ ПРОЕЗД, Д. 20, С | AM16: 45000 | AN16: 772201001 | AO16: TR | AP16: ТУРЦИЯ | AQ16: ТУРЦИЯ | AR16: RU | AS16: РОССИЯ | AT16: 0 | AU16: 1 | AV16: FCA | AW16: ISTANBUL | AX16: 1 | AY16: TRY | AZ16: 85900 | BA16: 314829 | BB16: 4709.84 | BC16: 36.7861 | BD16: 010 | BF16: 22110090/3311/0000/2/1 | BG16: - | BH16: 95 | BJ16: 10317000/021222/00006/2 | BL16: КРАСНОДАРСКИЙ КРАЙ | BM16: Г. НОВОРОССИЙСК | BN16: СУХУМСКОЕ ШОССЕ, Д.17А | BO16: 10317110 т/п Новороссийский юго-восточный | BP16: 1 | BQ16: КОТЛЫ БЫТОВЫЕ, ЦЕНТРАЛЬНОГО ОТОПЛЕНИЯ, ГАЗОВЫЕ, ИЗГОТОВЛЕНЫ ИЗ КОМПОЗИТНЫХ МАТЕРИАЛОВ, ЛАТУННЫХ И МЕТАЛЛИЧЕСКИХ ЧАСТЕЙ. ОДНОКОНТУРНЫЕ, НАСТЕННЫЕ КОНДЕНСАЦИОННЫЕ, НА НАПРЯЖЕНИЕ 220-240 В. В КОМПЛЕКТЕ С ДЫМОХОДОМ. ПРЕДНАЗНАЧЕНЫ ДЛЯ ОТОПЛЕНИЯ ЧАСТНЫХ | BR16: =ISNUMBER(SEARCH($BR$1,Таблица1[[#This Row],[31_1 Описание и характеристика товара]]))*1 -> 0 | BT16: TERMO ISI SISTEMLERI TIC. VE SAN. A.S. | BU16: 1 | BV16: 1 | BW16: 5 | BX16: ШТ | BY16: 0 | CA16: 1 | CB16: 8403109000 | CE16: TR | CF16: 444 | CG16: ОООО-ОО | CH16: 4000000 | CI16: 415 | CJ16: 0 | CM16: 85900 | CN16: 314829 | CO16: 0 | CP16: 1 | CQ16: 323452.87 | CR16: 4709.84 | CS16: 10 | CT16: 11.349 | CU16: 1405 | CV16: 140 | CX16: КОЛЕСНИКОВА ЕКАТЕРИНА ИВАНОВНА | CY16: 151
A17: 1 | B17: 44931 | C17: =IF(YEAR(Таблица1[[#This Row],[Дата]])=2023,MONTH(Таблица1[[#This Row],[Дата]]),0) -> 1 | D17: 10317120/221222/5000957 | E17: 10317120 | F17: 5000957 | G17: ИМ | H17: 40 | L17: BAYMAK MAKINA SANAYI VE TICARET A.S. | M17: 34959, , ORHANLI-TUZLA/ISTANBUL, ORHANLI BELDESI ORTA MAH. AKDENIZ SOK.NO:8, | P17: 1 | R17: 1 | S17: 28 | T17: 1087746423005 | U17: 7717615508 | V17: ООО БДР ТЕРМИЯ РУС | W17: 129164, , Г.МОСКВА, ЗУБАРЕВ ПЕР., Д.15, К.1, ЭТ.3, ПОМ.1, КОМ.67Г, | X17: 45000 | Y17: 771701001 | Z17: 1087746423005 | AA17: 7717615508 | AB17: ООО БДР ТЕРМИЯ РУС | AC17: 129164, , Г.МОСКВА, ЗУБАРЕВ ПЕР., Д.15, К.1, ЭТ.3, ПОМ.1, КОМ.67Г, | AD17: 45000 | AE17: 771701001 | AF17: TR | AG17: ТУРЦИЯ | AH17: 7119229.7 | AI17: 1087746423005 | AJ17: 7717615508 | AK17: ООО БДР ТЕРМИЯ РУС | AL17: 129164, , Г.МОСКВА, ЗУБАРЕВ ПЕР., Д.15, К.1, ЭТ.3, ПОМ.1, КОМ.67Г, | AM17: 45000 | AN17: 771701001 | AO17: TR | AP17: ТУРЦИЯ | AQ17: ТУРЦИЯ | AR17: RU | AS17: РОССИЯ | AU17: 1 | AV17: EXW | AW17: TUZLA | AX17: 1 | AY17: EUR | AZ17: 91116.48 | BA17: 6842064 | BB17: 100945.33 | BC17: 75.0914 | BD17: 010 | BE17: 30 | BF17: 16080084/0001/0000/2/1 | BG17: - | BH17: 99 | BJ17: 10317000/021222/00006/2 | BL17: КРАСНОДАРСКИЙ КРАЙ | BM17: Г. НОВОРОССИЙСК | BN17: СУХУМСКОЕ ШОССЕ, Д. 17А ПЗТК ООО НУТЭП | BO17: 10317110 т/п Новороссийский юго-восточный | BP17: 1 | BQ17: КОТЛЫ ГАЗОВЫЕ ЦЕНТРАЛЬНОГО ОТОПЛЕНИЯ, СТАЛЬНЫЕ: | BR17: =ISNUMBER(SEARCH($BR$1,Таблица1[[#This Row],[31_1 Описание и характеристика товара]]))*1 -> 0 | BT17: BAYMAK MAKINA SANAYI VE TICARET A.S. | BU17: 28 | BV17: 1 | BW17: 336 | BX17: ШТ | CA17: 1 | CB17: 8403109000 | CE17: TR | CF17: 10836 | CG17: ОООО-ОО | CH17: 4000000 | CI17: 10416 | CM17: 91116.48 | CN17: 6842064 | CO17: 0 | CP17: 1 | CQ17: 7119229.7 | CR17: 100945.33 | CS17: 10 | CT17: 9.6914 | CU17: 1168 | CV17: ЛС-БДРТР/220/07/2022 | CX17: ДАВЫДОВА СВЕТЛАНА АЛЕКСАНДРОВНА | CY17: 0
A18: 1 | B18: 45164 | C18: =IF(YEAR(Таблица1[[#This Row],[Дата]])=2023,MONTH(Таблица1[[#This Row],[Дата]]),0) -> 8 | D18: 10317120/221222/3169345 | E18: 10317120 | F18: 3169345 | G18: ИМ | H18: 40 | L18: BAYMAK MAKINA SANAYI VE TICARET A.S. | M18: 34959, ORHANLI/TUZLA, ISTANBUL, ORHANLI BELDESI, ORTA MAHALLE, AKDENIZ SOK.NO:8, | P18: 1 | Q18: 0 | R18: 1 | S18: 28 | T18: 1087746423005 | U18: 7717615508 | V18: ООО БДР ТЕРМИЯ РУС | W18: 129164, , Г.МОСКВА, ЗУБАРЕВ ПЕР., Д.15, К.1, ЭТ.3, ПОМ.1, КОМ.67Г, | X18: 45000 | Y18: 771701001 | Z18: 1087746423005 | AA18: 7717615508 | AB18: ООО БДР ТЕРМИЯ РУС | AC18: 129164, , Г.МОСКВА, ЗУБАРЕВ ПЕР., Д.15, К.1, ЭТ.3, ПОМ.1, КОМ.67Г, | AD18: 45000 | AE18: 771701001 | AF18: TR | AG18: ТУРЦИЯ | AH18: 7084237.1 | AI18: 1087746423005 | AJ18: 7717615508 | AK18: ООО БДР ТЕРМИЯ РУС | AL18: 129164, , Г.МОСКВА, ЗУБАРЕВ ПЕР., Д.15, К.1, ЭТ.3, ПОМ.1, КОМ.67Г, | AM18: 45000 | AN18: 771701001 | AO18: TR | AP18: ТУРЦИЯ | AQ18: ТУРЦИЯ | AR18: RU | AS18: РОССИЯ | AT18: 0 | AU18: 1 | AV18: EXW | AW18: TUZLA | AX18: 1 | AY18: EUR | AZ18: 90650.48 | BA18: 6807071 | BB18: 100449.16 | BC18: 75.0914 | BD18: 010 | BE18: 30 | BF18: 16080084/0001/0000/2/1 | BG18: - | BH18: 99 | BJ18: 10317000/021222/00006/2 | BL18: КРАСНОДАРСКИЙ КРАЙ | BM18: Г. НОВОРОССИЙСК | BN18: СУХУМСКОЕ ШОССЕ, Д. 17 А. ПЗТК ООО НУТЭП | BO18: 10317110 т/п Новороссийский юго-восточный | BP18: 1 | BQ18: КОТЛЫ ЦЕНТРАЛЬНОГО ОТОПЛЕНИЯ ГАЗОВЫЕ СТАЛЬНЫЕ | BR18: =ISNUMBER(SEARCH($BR$1,Таблица1[[#This Row],[31_1 Описание и характеристика товара]]))*1 -> 0 | BT18: BAYMAK MAKINA SANAYI VE TICARET A.S. | BU18: 28 | BV18: 1 | BW18: 336 | BX18: ШТ | BY18: 0 | CA18: 1 | CB18: 8403109000 | CE18: TR | CF18: 10836 | CG18: ОООО-ОО | CH18: 4000000 | CI18: 10416 | CJ18: 0 | CM18: 90650.48 | CN18: 6807071 | CO18: 0 | CP18: 1 | CQ18: 7084237.1 | CR18: 100449.16 | CS18: 10 | CT18: 9.6437 | CU18: 1168 | CV18: ЛС-БДРТР/220/07/2022 | CX18: СЛЮСАРЬ ЕГОР ВИТАЛЬЕВИЧ | CY18: 0
A19: 1 | B19: 45048 | C19: =IF(YEAR(Таблица1[[#This Row],[Дата]])=2023,MONTH(Таблица1[[#This Row],[Дата]]),0) -> 5 | D19: 10317120/211222/3168635 | E19: 10317120 | F19: 3168635 | G19: ИМ | H19: 40 | L19: BAYMAK MAK SAN VE TIC. AS. | M19: 34959, ISTANBUL, ORHANLI-TUZLA, ORHANLI BELDESI ORTA MAH. AKDENIZ, SOK.NO:8 | P19: 1 | Q19: 0 | R19: 1 | S19: 28 | T19: 1087746423005 | U19: 7717615508 | V19: ООО БДР ТЕРМИЯ РУС | W19: 129164, , Г. МОСКВА, ЗУБАРЕВ ПЕРЕУЛОК, Д. 15, КОРП.1, ЭТАЖ 3, ПОМ.1, КО, | X19: 45000 | Y19: 771701001 | Z19: 1087746423005 | AA19: 7717615508 | AB19: ООО БДР ТЕРМИЯ РУС | AC19: 129164, , Г. МОСКВА, ЗУБАРЕВ ПЕРЕУЛОК, Д. 15, КОРП.1, ЭТАЖ 3, ПОМ.1, КО, | AD19: 45000 | AE19: 771701001 | AF19: TR | AG19: ТУРЦИЯ | AH19: 6935230.4 | AI19: 1087746423005 | AJ19: 7717615508 | AK19: ООО БДР ТЕРМИЯ РУС | AL19: 129164, , Г. МОСКВА, ЗУБАРЕВ ПЕРЕУЛОК, Д. 15, КОРП.1, ЭТАЖ 3, ПОМ.1, КО, | AM19: 45000 | AN19: 771701001 | AO19: TR | AP19: ТУРЦИЯ | AQ19: ТУРЦИЯ | AR19: RU | AS19: РОССИЯ | AT19: 0 | AU19: 1 | AV19: EXW | AW19: TUZLA | AX19: 1 | AY19: EUR | AZ19: 91116.48 | BA19: 6682382 | BB19: 100505.2 | BC19: 73.3389 | BD19: 010 | BE19: 30 | BF19: 16080084/0001/0000/2/1 | BG19: - | BH19: 99 | BJ19: 10317000/021222/00006/2 | BL19: КРАСНОДАРСКИЙ КРАЙ | BM19: Г. НОВОРОССИЙСК | BN19: УЛ.СУХУМСКОЕ ШОССЕ | BO19: 10317110 т/п Новороссийский юго-восточный | BP19: 1 | BQ19: КОТЛЫ ЦЕНТРАЛЬНОГО ОТОПЛЕНИЯ | BR19: =ISNUMBER(SEARCH($BR$1,Таблица1[[#This Row],[31_1 Описание и характеристика товара]]))*1 -> 0 | BT19: BAYMAK MAKINA SANAYI VE TICARET A.S. | BU19: 28 | BV19: 1 | BW19: 336 | BX19: ШТ | BY19: 0 | CA19: 1 | CB19: 8403109000 | CE19: TR | CF19: 10836 | CG19: ОООО-ОО | CH19: 4000000 | CI19: 10836 | CJ19: 0 | CM19: 91116.48 | CN19: 6682382 | CO19: 0 | CP19: 1 | CQ19: 6935230.4 | CR19: 100505.2 | CS19: 10 | CT19: 9.2751 | CU19: 897 | CV19: 0897/00-2022-078 | CX19: ПАСЛЕН АННА ПЕТРОВНА | CY19: 0
