Workbook

Sheet Задание
B2: Домашнее задание №1
B4: Описание
C5: Компания осуществляет продажи кормов для домашних животных
C7: Продукция компании:
C8: По видам животных: собаки и кошки
C9: По каналам продаж: онлайн и офлайн
C10: По сегментам: эконом и премиум
C11: Всего 80 продуктов (по 10 каждого типа)
C13: На листах приведены следующие данные:
C14: 1. Объем продаж (тонн)
C15: 2. Цены реализации - два листа (руб./кг)
C16: 3. Расходы на единицу товара (руб./кг)
B18: Задание
C19: 1. Свести* все данные (продажи, цены и расходы) на лист "Фин.результат" - обязательно, чтобы были ссылки на исходные данные цифры
C20: 2. Рассчитать следующие показатели по каждому продукту и по всем уровням (виды животных, каналы, сегменты) - по месяцам и просуммировать по годам
C21: Выручка
C22: Себестоимость
C23: Валовая прибыль (выручка - себестоимость)
C24: Валовая маржа (1 - себестоимость/выручка)
C26: * На сводном листе должно быть все залинковано на исходные листы
C27: * Аккуратно все структурировать и сгруппировать, закрепить столбцы/строки
C28: * Использовать корректные форматы чисел
C29: * Единообразный формат (заголовки, ссылки, итоги и пр.)
B31: Hints
C33: На всех исходных листах данные идут по порядку и имеют одинаковую структуру - не надо менять порядок!!!
C34: Можно ничего не менять на исходных листах
C35: Не нужно использовать никакие формулы, кроме "СУММ"

Sheet Фин.результат
D1: янв | E1: фев | F1: мар | G1: апр | H1: май | I1: июн | J1: июл | K1: авг | L1: сен | M1: окт | N1: ноя | O1: дек
A3: Объем продаж, т | D3: =D5+D53 -> 1995.2291 | E3: =E5+E53 -> 2151.5813 | F3: =F5+F53 -> 2571.5083 | G3: =G5+G53 -> 2578.5664 | H3: =H5+H53 -> 2821.3366 | I3: =I5+I53 -> 2231.9478 | J3: =J5+J53 -> 2546.578 | K3: =K5+K53 -> 2607.2525 | ... O3: =O5+O53 -> 2320.8746
A5: Корма для собак | D5: =D6+D29 -> 919.94381 | E5: =E6+E29 -> 998.03579 | F5: =F6+F29 -> 809.13426 | G5: =G6+G29 -> 1056.9313 | H5: =H6+H29 -> 1313.3957 | I5: =I6+I29 -> 1089.8733 | J5: =J6+J29 -> 1223.8686 | K5: =K6+K29 -> 1003.0931 | ... O5: =O6+O29 -> 1212.1195
A6: Онлайн продажи | D6: =D7+D18 -> 533.23056 | E6: =E7+E18 -> 455.27274 | F6: =F7+F18 -> 429.03799 | G6: =G7+G18 -> 582.84872 | H6: =H7+H18 -> 543.47727 | I6: =I7+I18 -> 551.11623 | J6: =J7+J18 -> 686.88686 | K6: =K7+K18 -> 485.73849 | ... O6: =O7+O18 -> 618.56699
A7: Эконом сегмент | D7: =SUM(D8:D17) -> 221.90827 | E7: =SUM(E8:E17) -> 224.12759 | F7: =SUM(F8:F17) -> 187.02007 | G7: =SUM(G8:G17) -> 355.95477 | H7: =SUM(H8:H17) -> 232.46749 | I7: =SUM(I8:I17) -> 330.94173 | J7: =SUM(J8:J17) -> 408.81103 | K7: =SUM(K8:K17) -> 226.63795 | ... O7: =SUM(O8:O17) -> 319.43778
A8: Бренд 1 | D8: ='продажи натураль.'!C7 -> 2.9205887 | E8: ='продажи натураль.'!D7 -> 9.5115027 | F8: ='продажи натураль.'!E7 -> 2.9569522 | G8: ='продажи натураль.'!F7 -> 29.085696 | H8: ='продажи натураль.'!G7 -> 3.7609401 | I8: ='продажи натураль.'!H7 -> 11.350544 | J8: ='продажи натураль.'!I7 -> 3.8941279 | K8: ='продажи натураль.'!J7 -> 3.6616761 | ... O8: ='продажи натураль.'!N7 -> 53.665164
A9: Бренд 2 | D9: ='продажи натураль.'!C8 -> 63.328307 | E9: ='продажи натураль.'!D8 -> 4.0526806 | F9: ='продажи натураль.'!E8 -> 27.224039 | G9: ='продажи натураль.'!F8 -> 83.106754 | H9: ='продажи натураль.'!G8 -> 22.786039 | I9: ='продажи натураль.'!H8 -> 19.789918 | J9: ='продажи натураль.'!I8 -> 6.3226629 | K9: ='продажи натураль.'!J8 -> 5.2214759 | ... O9: ='продажи натураль.'!N8 -> 7.1655691
A10: Бренд 3 | D10: ='продажи натураль.'!C9 -> 16.518393 | E10: ='продажи натураль.'!D9 -> 36.923947 | F10: ='продажи натураль.'!E9 -> 15.942065 | G10: ='продажи натураль.'!F9 -> 20.3666 | H10: ='продажи натураль.'!G9 -> 16.145601 | I10: ='продажи натураль.'!H9 -> 78.158713 | J10: ='продажи натураль.'!I9 -> 1.4517819 | K10: ='продажи натураль.'!J9 -> 34.545601 | ... O10: ='продажи натураль.'!N9 -> 44.390783
A11: Бренд 4 | D11: ='продажи натураль.'!C10 -> 12.874416 | E11: ='продажи натураль.'!D10 -> 1.2416532 | F11: ='продажи натураль.'!E10 -> 2.1283363 | G11: ='продажи натураль.'!F10 -> 12.025692 | H11: ='продажи натураль.'!G10 -> 33.936827 | I11: ='продажи натураль.'!H10 -> 15.260464 | J11: ='продажи натураль.'!I10 -> 62.370072 | K11: ='продажи натураль.'!J10 -> 69.458365 | ... O11: ='продажи натураль.'!N10 -> 26.896586
A12: Бренд 5 | D12: ='продажи натураль.'!C11 -> 47.452926 | E12: ='продажи натураль.'!D11 -> 9.6306634 | F12: ='продажи натураль.'!E11 -> 35.649551 | G12: ='продажи натураль.'!F11 -> 47.427644 | H12: ='продажи натураль.'!G11 -> 43.393758 | I12: ='продажи натураль.'!H11 -> 16.977001 | J12: ='продажи натураль.'!I11 -> 81.981773 | K12: ='продажи натураль.'!J11 -> 41.966994 | ... O12: ='продажи натураль.'!N11 -> 91.405769
A13: Бренд 6 | D13: ='продажи натураль.'!C12 -> 44.872531 | E13: ='продажи натураль.'!D12 -> 30.26307 | F13: ='продажи натураль.'!E12 -> 15.036106 | G13: ='продажи натураль.'!F12 -> 74.064884 | H13: ='продажи натураль.'!G12 -> 21.725135 | I13: ='продажи натураль.'!H12 -> 34.962944 | J13: ='продажи натураль.'!I12 -> 34.955475 | K13: ='продажи натураль.'!J12 -> 8.5644655 | ... O13: ='продажи натураль.'!N12 -> 1.9500381
A14: Бренд 7 | D14: ='продажи натураль.'!C13 -> 0.69506707 | E14: ='продажи натураль.'!D13 -> 53.460415 | F14: ='продажи натураль.'!E13 -> 39.073368 | G14: ='продажи натураль.'!F13 -> 23.516107 | H14: ='продажи натураль.'!G13 -> 47.78267 | I14: ='продажи натураль.'!H13 -> 17.272478 | J14: ='продажи натураль.'!I13 -> 20.560933 | K14: ='продажи натураль.'!J13 -> 21.882708 | ... O14: ='продажи натураль.'!N13 -> 62.349359
A15: Бренд 8 | D15: ='продажи натураль.'!C14 -> 4.149572 | E15: ='продажи натураль.'!D14 -> 39.488109 | F15: ='продажи натураль.'!E14 -> 25.265471 | G15: ='продажи натураль.'!F14 -> 22.456329 | H15: ='продажи натураль.'!G14 -> 15.648039 | I15: ='продажи натураль.'!H14 -> 35.713431 | J15: ='продажи натураль.'!I14 -> 52.085634 | K15: ='продажи натураль.'!J14 -> 17.240299 | ... O15: ='продажи натураль.'!N14 -> 11.967719
A16: Бренд 9 | D16: ='продажи натураль.'!C15 -> 21.640559 | E16: ='продажи натураль.'!D15 -> 7.17299 | F16: ='продажи натураль.'!E15 -> 8.3276978 | G16: ='продажи натураль.'!F15 -> 14.920891 | H16: ='продажи натураль.'!G15 -> 19.478847 | I16: ='продажи натураль.'!H15 -> 33.763382 | J16: ='продажи натураль.'!I15 -> 55.733841 | K16: ='продажи натураль.'!J15 -> 11.74505 | ... O16: ='продажи натураль.'!N15 -> 1.7100472
A17: Бренд 10 | D17: ='продажи натураль.'!C16 -> 7.4559148 | E17: ='продажи натураль.'!D16 -> 32.382564 | F17: ='продажи натураль.'!E16 -> 15.416481 | G17: ='продажи натураль.'!F16 -> 28.984176 | H17: ='продажи натураль.'!G16 -> 7.8096338 | I17: ='продажи натураль.'!H16 -> 67.692854 | J17: ='продажи натураль.'!I16 -> 89.454724 | K17: ='продажи натураль.'!J16 -> 12.351313 | ... O17: ='продажи натураль.'!N16 -> 17.936745
A18: Премиум сегмент | D18: =SUM(D19:D28) -> 311.32228 | E18: =SUM(E19:E28) -> 231.14514 | F18: =SUM(F19:F28) -> 242.01792 | G18: =SUM(G19:G28) -> 226.89395 | H18: =SUM(H19:H28) -> 311.00977 | I18: =SUM(I19:I28) -> 220.17451 | J18: =SUM(J19:J28) -> 278.07584 | K18: =SUM(K19:K28) -> 259.10054 | ... O18: =SUM(O19:O28) -> 299.12921
A19: Бренд 1 | D19: ='продажи натураль.'!C18 -> 49.34092 | E19: ='продажи натураль.'!D18 -> 27.1361 | F19: ='продажи натураль.'!E18 -> 28.929057 | G19: ='продажи натураль.'!F18 -> 7.7460073 | H19: ='продажи натураль.'!G18 -> 37.374258 | I19: ='продажи натураль.'!H18 -> 14.232158 | J19: ='продажи натураль.'!I18 -> 6.5901463 | K19: ='продажи натураль.'!J18 -> 11.201432 | ... O19: ='продажи натураль.'!N18 -> 35.091958
A20: Бренд 2 | D20: ='продажи натураль.'!C19 -> 34.835538 | E20: ='продажи натураль.'!D19 -> 7.6167736 | F20: ='продажи натураль.'!E19 -> 27.338799 | G20: ='продажи натураль.'!F19 -> 20.663425 | H20: ='продажи натураль.'!G19 -> 43.786375 | I20: ='продажи натураль.'!H19 -> 40.777536 | J20: ='продажи натураль.'!I19 -> 17.846269 | K20: ='продажи натураль.'!J19 -> 40.983693 | ... O20: ='продажи натураль.'!N19 -> 2.1408773
A21: Бренд 3 | D21: ='продажи натураль.'!C20 -> 7.1933052 | E21: ='продажи натураль.'!D20 -> 22.143705 | F21: ='продажи натураль.'!E20 -> 34.839175 | G21: ='продажи натураль.'!F20 -> 53.946326 | H21: ='продажи натураль.'!G20 -> 43.407642 | I21: ='продажи натураль.'!H20 -> 22.774957 | J21: ='продажи натураль.'!I20 -> 25.866388 | K21: ='продажи натураль.'!J20 -> 7.1072508 | ... O21: ='продажи натураль.'!N20 -> 4.726733
A22: Бренд 4 | D22: ='продажи натураль.'!C21 -> 21.465348 | E22: ='продажи натураль.'!D21 -> 21.72355 | F22: ='продажи натураль.'!E21 -> 47.151725 | G22: ='продажи натураль.'!F21 -> 16.708365 | H22: ='продажи натураль.'!G21 -> 37.951666 | I22: ='продажи натураль.'!H21 -> 21.451109 | J22: ='продажи натураль.'!I21 -> 39.646347 | K22: ='продажи натураль.'!J21 -> 36.89337 | ... O22: ='продажи натураль.'!N21 -> 34.133603
A23: Бренд 5 | D23: ='продажи натураль.'!C22 -> 33.786433 | E23: ='продажи натураль.'!D22 -> 6.7048856 | F23: ='продажи натураль.'!E22 -> 7.8109237 | G23: ='продажи натураль.'!F22 -> 9.5761729 | H23: ='продажи натураль.'!G22 -> 62.906628 | I23: ='продажи натураль.'!H22 -> 6.5363034 | J23: ='продажи натураль.'!I22 -> 30.893022 | K23: ='продажи натураль.'!J22 -> 36.132962 | ... O23: ='продажи натураль.'!N22 -> 32.355809
A24: Бренд 6 | D24: ='продажи натураль.'!C23 -> 55.979469 | E24: ='продажи натураль.'!D23 -> 38.047686 | F24: ='продажи натураль.'!E23 -> 5.0233745 | G24: ='продажи натураль.'!F23 -> 6.7465642 | H24: ='продажи натураль.'!G23 -> 29.972787 | I24: ='продажи натураль.'!H23 -> 11.702264 | J24: ='продажи натураль.'!I23 -> 39.868941 | K24: ='продажи натураль.'!J23 -> 21.674293 | ... O24: ='продажи натураль.'!N23 -> 5.2571401
A25: Бренд 7 | D25: ='продажи натураль.'!C24 -> 69.83957 | E25: ='продажи натураль.'!D24 -> 14.504757 | F25: ='продажи натураль.'!E24 -> 10.975808 | G25: ='продажи натураль.'!F24 -> 46.648343 | H25: ='продажи натураль.'!G24 -> 18.155249 | I25: ='продажи натураль.'!H24 -> 24.906214 | J25: ='продажи натураль.'!I24 -> 21.569305 | K25: ='продажи натураль.'!J24 -> 10.884708 | ... O25: ='продажи натураль.'!N24 -> 91.335335
A26: Бренд 8 | D26: ='продажи натураль.'!C25 -> 13.139919 | E26: ='продажи натураль.'!D25 -> 53.04678 | F26: ='продажи натураль.'!E25 -> 20.000865 | G26: ='продажи натураль.'!F25 -> 7.0201954 | H26: ='продажи натураль.'!G25 -> 23.132122 | I26: ='продажи натураль.'!H25 -> 35.823762 | J26: ='продажи натураль.'!I25 -> 17.871672 | K26: ='продажи натураль.'!J25 -> 26.530391 | ... O26: ='продажи натураль.'!N25 -> 14.863445
A27: Бренд 9 | D27: ='продажи натураль.'!C26 -> 25.143286 | E27: ='продажи натураль.'!D26 -> 21.046982 | F27: ='продажи натураль.'!E26 -> 31.331629 | G27: ='продажи натураль.'!F26 -> 38.340069 | H27: ='продажи натураль.'!G26 -> 1.6143339 | I27: ='продажи натураль.'!H26 -> 15.122471 | J27: ='продажи натураль.'!I26 -> 45.607641 | K27: ='продажи натураль.'!J26 -> 39.004328 | ... O27: ='продажи натураль.'!N26 -> 10.436922
A28: Бренд 10 | D28: ='продажи натураль.'!C27 -> 0.59849322 | E28: ='продажи натураль.'!D27 -> 19.173924 | F28: ='продажи натураль.'!E27 -> 28.616565 | G28: ='продажи натураль.'!F27 -> 19.498483 | H28: ='продажи натураль.'!G27 -> 12.708715 | I28: ='продажи натураль.'!H27 -> 26.847733 | J28: ='продажи натураль.'!I27 -> 32.316105 | K28: ='продажи натураль.'!J27 -> 28.688112 | ... O28: ='продажи натураль.'!N27 -> 68.787389
A29: Офлайн продажи | D29: =D30+D41 -> 386.71326 | E29: =E30+E41 -> 542.76305 | F29: =F30+F41 -> 380.09627 | G29: =G30+G41 -> 474.08254 | H29: =H30+H41 -> 769.91844 | I29: =I30+I41 -> 538.75702 | J29: =J30+J41 -> 536.98171 | K29: =K30+K41 -> 517.35461 | ... O29: =O30+O41 -> 593.55247
A30: Эконом сегмент | D30: =SUM(D31:D40) -> 193.7266 | E30: =SUM(E31:E40) -> 285.48051 | F30: =SUM(F31:F40) -> 223.86192 | G30: =SUM(G31:G40) -> 242.80089 | H30: =SUM(H31:H40) -> 392.93314 | I30: =SUM(I31:I40) -> 292.45625 | J30: =SUM(J31:J40) -> 311.66475 | K30: =SUM(K31:K40) -> 235.8898 | ... O30: =SUM(O31:O40) -> 282.71654
A31: Бренд 1 | D31: ='продажи натураль.'!C30 -> 49.917382 | E31: ='продажи натураль.'!D30 -> 19.496222 | F31: ='продажи натураль.'!E30 -> 52.013128 | G31: ='продажи натураль.'!F30 -> 68.587236 | H31: ='продажи натураль.'!G30 -> 42.340018 | I31: ='продажи натураль.'!H30 -> 8.4116198 | J31: ='продажи натураль.'!I30 -> 84.294354 | K31: ='продажи натураль.'!J30 -> 44.322938 | ... O31: ='продажи натураль.'!N30 -> 58.237276
A32: Бренд 2 | D32: ='продажи натураль.'!C31 -> 16.233441 | E32: ='продажи натураль.'!D31 -> 59.924532 | F32: ='продажи натураль.'!E31 -> 19.90603 | G32: ='продажи натураль.'!F31 -> 4.555899 | H32: ='продажи натураль.'!G31 -> 4.2701581 | I32: ='продажи натураль.'!H31 -> 22.937889 | J32: ='продажи натураль.'!I31 -> 31.466098 | K32: ='продажи натураль.'!J31 -> 42.510945 | ... O32: ='продажи натураль.'!N31 -> 63.376672
A33: Бренд 3 | D33: ='продажи натураль.'!C32 -> 18.987399 | E33: ='продажи натураль.'!D32 -> 44.326874 | F33: ='продажи натураль.'!E32 -> 26.350137 | G33: ='продажи натураль.'!F32 -> 31.989536 | H33: ='продажи натураль.'!G32 -> 28.4583 | I33: ='продажи натураль.'!H32 -> 40.816891 | J33: ='продажи натураль.'!I32 -> 31.239174 | K33: ='продажи натураль.'!J32 -> 4.7939377 | ... O33: ='продажи натураль.'!N32 -> 46.102108
A34: Бренд 4 | D34: ='продажи натураль.'!C33 -> 16.364334 | E34: ='продажи натураль.'!D33 -> 15.335892 | F34: ='продажи натураль.'!E33 -> 8.404687 | G34: ='продажи натураль.'!F33 -> 32.038149 | H34: ='продажи натураль.'!G33 -> 34.607624 | I34: ='продажи натураль.'!H33 -> 3.5539546 | J34: ='продажи натураль.'!I33 -> 31.802753 | K34: ='продажи натураль.'!J33 -> 28.20108 | ... O34: ='продажи натураль.'!N33 -> 38.167434
A35: Бренд 5 | D35: ='продажи натураль.'!C34 -> 13.637636 | E35: ='продажи натураль.'!D34 -> 48.57449 | F35: ='продажи натураль.'!E34 -> 42.490845 | G35: ='продажи натураль.'!F34 -> 2.9217132 | H35: ='продажи натураль.'!G34 -> 38.029841 | I35: ='продажи натураль.'!H34 -> 7.0081389 | J35: ='продажи натураль.'!I34 -> 15.693008 | K35: ='продажи натураль.'!J34 -> 63.979767 | ... O35: ='продажи натураль.'!N34 -> 9.5405538
A36: Бренд 6 | D36: ='продажи натураль.'!C35 -> 7.0767586 | E36: ='продажи натураль.'!D35 -> 30.799148 | F36: ='продажи натураль.'!E35 -> 12.222888 | G36: ='продажи натураль.'!F35 -> 1.526901 | H36: ='продажи натураль.'!G35 -> 95.014158 | I36: ='продажи натураль.'!H35 -> 70.066664 | J36: ='продажи натураль.'!I35 -> 17.469463 | K36: ='продажи натураль.'!J35 -> 2.107023 | ... O36: ='продажи натураль.'!N35 -> 16.13428
A37: Бренд 7 | D37: ='продажи натураль.'!C36 -> 43.727239 | E37: ='продажи натураль.'!D36 -> 13.241526 | F37: ='продажи натураль.'!E36 -> 1.1989395 | G37: ='продажи натураль.'!F36 -> 15.734061 | H37: ='продажи натураль.'!G36 -> 3.27422 | I37: ='продажи натураль.'!H36 -> 12.604854 | J37: ='продажи натураль.'!I36 -> 41.284093 | K37: ='продажи натураль.'!J36 -> 9.5499197 | ... O37: ='продажи натураль.'!N36 -> 2.9616219
A38: Бренд 8 | D38: ='продажи натураль.'!C37 -> 0.30706464 | E38: ='продажи натураль.'!D37 -> 5.7483139 | F38: ='продажи натураль.'!E37 -> 41.47568 | G38: ='продажи натураль.'!F37 -> 42.531873 | H38: ='продажи натураль.'!G37 -> 34.90155 | I38: ='продажи натураль.'!H37 -> 29.544549 | J38: ='продажи натураль.'!I37 -> 6.5543441 | K38: ='продажи натураль.'!J37 -> 12.867844 | ... O38: ='продажи натураль.'!N37 -> 31.537033
A39: Бренд 9 | D39: ='продажи натураль.'!C38 -> 16.641579 | E39: ='продажи натураль.'!D38 -> 8.4269745 | F39: ='продажи натураль.'!E38 -> 1.4194516 | G39: ='продажи натураль.'!F38 -> 33.023209 | H39: ='продажи натураль.'!G38 -> 48.384809 | I39: ='продажи натураль.'!H38 -> 16.690174 | J39: ='продажи натураль.'!I38 -> 33.292311 | K39: ='продажи натураль.'!J38 -> 8.1760036 | ... O39: ='продажи натураль.'!N38 -> 1.8249762
A40: Бренд 10 | D40: ='продажи натураль.'!C39 -> 10.83377 | E40: ='продажи натураль.'!D39 -> 39.606537 | F40: ='продажи натураль.'!E39 -> 18.380132 | G40: ='продажи натураль.'!F39 -> 9.8923086 | H40: ='продажи натураль.'!G39 -> 63.652466 | I40: ='продажи натураль.'!H39 -> 80.821517 | J40: ='продажи натураль.'!I39 -> 18.569153 | K40: ='продажи натураль.'!J39 -> 19.380344 | ... O40: ='продажи натураль.'!N39 -> 14.834584
A41: Премиум сегмент | D41: =SUM(D42:D51) -> 192.98665 | E41: =SUM(E42:E51) -> 257.28255 | F41: =SUM(F42:F51) -> 156.23436 | G41: =SUM(G42:G51) -> 231.28165 | H41: =SUM(H42:H51) -> 376.98529 | I41: =SUM(I42:I51) -> 246.30077 | J41: =SUM(J42:J51) -> 225.31696 | K41: =SUM(K42:K51) -> 281.46481 | ... O41: =SUM(O42:O51) -> 310.83593
A42: Бренд 1 | D42: ='продажи натураль.'!C41 -> 68.509687 | E42: ='продажи натураль.'!D41 -> 23.31188 | F42: ='продажи натураль.'!E41 -> 10.848903 | G42: ='продажи натураль.'!F41 -> 6.7080718 | H42: ='продажи натураль.'!G41 -> 25.10333 | I42: ='продажи натураль.'!H41 -> 37.586809 | J42: ='продажи натураль.'!I41 -> 13.732025 | K42: ='продажи натураль.'!J41 -> 1.3284248 | ... O42: ='продажи натураль.'!N41 -> 34.096283
...

Sheet Исходные данные→

Sheet продажи натураль.
B2: Продажи тонн
C3: 44927 | D3: 44958 | E3: 44986 | F3: 45017 | G3: 45047 | H3: 45078 | I3: 45108 | J3: 45139 | K3: 45170 | L3: 45200 | M3: 45231 | N3: 45261
B4: Корма для собак
B5: Онлайн продажи
B6: Эконом сегмент
B7: Бренд 1 | C7: 2.9205887 | D7: 9.5115027 | E7: 2.9569522 | F7: 29.085696 | G7: 3.7609401 | H7: 11.350544 | I7: 3.8941279 | J7: 3.6616761 | K7: 27.888846 | L7: 14.370095 | M7: 8.5289763 | N7: 53.665164
B8: Бренд 2 | C8: 63.328307 | D8: 4.0526806 | E8: 27.224039 | F8: 83.106754 | G8: 22.786039 | H8: 19.789918 | I8: 6.3226629 | J8: 5.2214759 | K8: 61.946695 | L8: 10.410475 | M8: 19.6122 | N8: 7.1655691
B9: Бренд 3 | C9: 16.518393 | D9: 36.923947 | E9: 15.942065 | F9: 20.3666 | G9: 16.145601 | H9: 78.158713 | I9: 1.4517819 | J9: 34.545601 | K9: 22.466362 | L9: 25.188829 | M9: 25.722622 | N9: 44.390783
B10: Бренд 4 | C10: 12.874416 | D10: 1.2416532 | E10: 2.1283363 | F10: 12.025692 | G10: 33.936827 | H10: 15.260464 | I10: 62.370072 | J10: 69.458365 | K10: 34.454465 | L10: 64.081954 | M10: 20.966734 | N10: 26.896586
B11: Бренд 5 | C11: 47.452926 | D11: 9.6306634 | E11: 35.649551 | F11: 47.427644 | G11: 43.393758 | H11: 16.977001 | I11: 81.981773 | J11: 41.966994 | K11: 58.527007 | L11: 44.811048 | M11: 24.305595 | N11: 91.405769
B12: Бренд 6 | C12: 44.872531 | D12: 30.26307 | E12: 15.036106 | F12: 74.064884 | G12: 21.725135 | H12: 34.962944 | I12: 34.955475 | J12: 8.5644655 | K12: 1.6553661 | L12: 3.5663248 | M12: 3.2240895 | N12: 1.9500381
B13: Бренд 7 | C13: 0.69506707 | D13: 53.460415 | E13: 39.073368 | F13: 23.516107 | G13: 47.78267 | H13: 17.272478 | I13: 20.560933 | J13: 21.882708 | K13: 19.384256 | L13: 2.0989694 | M13: 81.819257 | N13: 62.349359
B14: Бренд 8 | C14: 4.149572 | D14: 39.488109 | E14: 25.265471 | F14: 22.456329 | G14: 15.648039 | H14: 35.713431 | I14: 52.085634 | J14: 17.240299 | K14: 38.592293 | L14: 38.510077 | M14: 22.929858 | N14: 11.967719
B15: Бренд 9 | C15: 21.640559 | D15: 7.17299 | E15: 8.3276978 | F15: 14.920891 | G15: 19.478847 | H15: 33.763382 | I15: 55.733841 | J15: 11.74505 | K15: 12.234241 | L15: 82.824652 | M15: 17.504139 | N15: 1.7100472
B16: Бренд 10 | C16: 7.4559148 | D16: 32.382564 | E16: 15.416481 | F16: 28.984176 | G16: 7.8096338 | H16: 67.692854 | I16: 89.454724 | J16: 12.351313 | K16: 53.710928 | L16: 74.86404 | M16: 6.2341435 | N16: 17.936745
B17: Премиум сегмент
B18: Бренд 1 | C18: 49.34092 | D18: 27.1361 | E18: 28.929057 | F18: 7.7460073 | G18: 37.374258 | H18: 14.232158 | I18: 6.5901463 | J18: 11.201432 | K18: 63.302371 | L18: 5.2848462 | M18: 79.377562 | N18: 35.091958
B19: Бренд 2 | C19: 34.835538 | D19: 7.6167736 | E19: 27.338799 | F19: 20.663425 | G19: 43.786375 | H19: 40.777536 | I19: 17.846269 | J19: 40.983693 | K19: 24.381705 | L19: 9.0669676 | M19: 18.389933 | N19: 2.1408773
B20: Бренд 3 | C20: 7.1933052 | D20: 22.143705 | E20: 34.839175 | F20: 53.946326 | G20: 43.407642 | H20: 22.774957 | I20: 25.866388 | J20: 7.1072508 | K20: 2.9107977 | L20: 33.000407 | M20: 22.67471 | N20: 4.726733
B21: Бренд 4 | C21: 21.465348 | D21: 21.72355 | E21: 47.151725 | F21: 16.708365 | G21: 37.951666 | H21: 21.451109 | I21: 39.646347 | J21: 36.89337 | K21: 2.8911094 | L21: 59.050529 | M21: 3.7947341 | N21: 34.133603
B22: Бренд 5 | C22: 33.786433 | D22: 6.7048856 | E22: 7.8109237 | F22: 9.5761729 | G22: 62.906628 | H22: 6.5363034 | I22: 30.893022 | J22: 36.132962 | K22: 16.605613 | L22: 50.664063 | M22: 6.1071165 | N22: 32.355809
B23: Бренд 6 | C23: 55.979469 | D23: 38.047686 | E23: 5.0233745 | F23: 6.7465642 | G23: 29.972787 | H23: 11.702264 | I23: 39.868941 | J23: 21.674293 | K23: 8.3589443 | L23: 78.722464 | M23: 18.49092 | N23: 5.2571401
B24: Бренд 7 | C24: 69.83957 | D24: 14.504757 | E24: 10.975808 | F24: 46.648343 | G24: 18.155249 | H24: 24.906214 | I24: 21.569305 | J24: 10.884708 | K24: 14.689034 | L24: 2.8803547 | M24: 45.574424 | N24: 91.335335
B25: Бренд 8 | C25: 13.139919 | D25: 53.04678 | E25: 20.000865 | F25: 7.0201954 | G25: 23.132122 | H25: 35.823762 | I25: 17.871672 | J25: 26.530391 | K25: 22.215708 | L25: 30.223977 | M25: 49.356443 | N25: 14.863445
B26: Бренд 9 | C26: 25.143286 | D26: 21.046982 | E26: 31.331629 | F26: 38.340069 | G26: 1.6143339 | H26: 15.122471 | I26: 45.607641 | J26: 39.004328 | K26: 0.76205963 | L26: 13.370408 | M26: 41.16635 | N26: 10.436922
B27: Бренд 10 | C27: 0.59849322 | D27: 19.173924 | E27: 28.616565 | F27: 19.498483 | G27: 12.708715 | H27: 26.847733 | I27: 32.316105 | J27: 28.688112 | K27: 28.224056 | L27: 9.9606261 | M27: 29.573414 | N27: 68.787389
B28: Офлайн продажи
B29: Эконом сегмент
B30: Бренд 1 | C30: 49.917382 | D30: 19.496222 | E30: 52.013128 | F30: 68.587236 | G30: 42.340018 | H30: 8.4116198 | I30: 84.294354 | J30: 44.322938 | K30: 3.8462412 | L30: 19.041216 | M30: 22.478554 | N30: 58.237276
B31: Бренд 2 | C31: 16.233441 | D31: 59.924532 | E31: 19.90603 | F31: 4.555899 | G31: 4.2701581 | H31: 22.937889 | I31: 31.466098 | J31: 42.510945 | K31: 3.193302 | L31: 34.584155 | M31: 67.847532 | N31: 63.376672
B32: Бренд 3 | C32: 18.987399 | D32: 44.326874 | E32: 26.350137 | F32: 31.989536 | G32: 28.4583 | H32: 40.816891 | I32: 31.239174 | J32: 4.7939377 | K32: 40.316188 | L32: 19.694182 | M32: 18.248065 | N32: 46.102108
B33: Бренд 4 | C33: 16.364334 | D33: 15.335892 | E33: 8.404687 | F33: 32.038149 | G33: 34.607624 | H33: 3.5539546 | I33: 31.802753 | J33: 28.20108 | K33: 3.425136 | L33: 1.9040393 | M33: 45.417472 | N33: 38.167434
B34: Бренд 5 | C34: 13.637636 | D34: 48.57449 | E34: 42.490845 | F34: 2.9217132 | G34: 38.029841 | H34: 7.0081389 | I34: 15.693008 | J34: 63.979767 | K34: 34.424048 | L34: 9.4484185 | M34: 40.043731 | N34: 9.5405538
B35: Бренд 6 | C35: 7.0767586 | D35: 30.799148 | E35: 12.222888 | F35: 1.526901 | G35: 95.014158 | H35: 70.066664 | I35: 17.469463 | J35: 2.107023 | K35: 7.6002283 | L35: 20.227803 | M35: 55.755778 | N35: 16.13428
B36: Бренд 7 | C36: 43.727239 | D36: 13.241526 | E36: 1.1989395 | F36: 15.734061 | G36: 3.27422 | H36: 12.604854 | I36: 41.284093 | J36: 9.5499197 | K36: 20.84999 | L36: 20.330541 | M36: 45.138563 | N36: 2.9616219
B37: Бренд 8 | C37: 0.30706464 | D37: 5.7483139 | E37: 41.47568 | F37: 42.531873 | G37: 34.90155 | H37: 29.544549 | I37: 6.5543441 | J37: 12.867844 | K37: 12.890696 | L37: 34.535341 | M37: 22.366368 | N37: 31.537033
B38: Бренд 9 | C38: 16.641579 | D38: 8.4269745 | E38: 1.4194516 | F38: 33.023209 | G38: 48.384809 | H38: 16.690174 | I38: 33.292311 | J38: 8.1760036 | K38: 5.4364535 | L38: 7.6269869 | M38: 13.804761 | N38: 1.8249762
B39: Бренд 10 | C39: 10.83377 | D39: 39.606537 | E39: 18.380132 | F39: 9.8923086 | G39: 63.652466 | H39: 80.821517 | I39: 18.569153 | J39: 19.380344 | K39: 28.456452 | L39: 21.460883 | M39: 5.7222552 | N39: 14.834584
B40: Премиум сегмент
B41: Бренд 1 | C41: 68.509687 | D41: 23.31188 | E41: 10.848903 | F41: 6.7080718 | G41: 25.10333 | H41: 37.586809 | I41: 13.732025 | J41: 1.3284248 | K41: 55.606627 | L41: 23.004259 | M41: 79.496722 | N41: 34.096283
...

Sheet цены 1 полуг
B1: 44927 | C1: 44958 | D1: 44986 | E1: 45017 | F1: 45047 | G1: 45078
A3: Цены
A4: Рублей/кило
A5: 1 полугодие
A19: Корма для собак
A20: Онлайн продажи
A21: Эконом сегмент
A22: Бренд 1 | B22: 113 | C22: 110 | D22: 104 | E22: 164 | F22: 162 | G22: 136
A23: Бренд 2 | B23: 114 | C23: 181 | D23: 126 | E23: 113 | F23: 156 | G23: 144
A24: Бренд 3 | B24: 157 | C24: 129 | D24: 120 | E24: 111 | F24: 124 | G24: 177
A25: Бренд 4 | B25: 153 | C25: 190 | D25: 186 | E25: 124 | F25: 164 | G25: 112
A26: Бренд 5 | B26: 182 | C26: 174 | D26: 171 | E26: 186 | F26: 104 | G26: 187
A27: Бренд 6 | B27: 190 | C27: 130 | D27: 162 | E27: 120 | F27: 143 | G27: 101
A28: Бренд 7 | B28: 193 | C28: 196 | D28: 138 | E28: 162 | F28: 131 | G28: 112
A29: Бренд 8 | B29: 139 | C29: 130 | D29: 200 | E29: 102 | F29: 130 | G29: 156
A30: Бренд 9 | B30: 157 | C30: 130 | D30: 101 | E30: 103 | F30: 155 | G30: 166
A31: Бренд 10 | B31: 190 | C31: 148 | D31: 103 | E31: 147 | F31: 163 | G31: 135
A32: Премиум сегмент
A33: Бренд 1 | B33: 388 | C33: 318 | D33: 345 | E33: 311 | F33: 383 | G33: 383
A34: Бренд 2 | B34: 323 | C34: 364 | D34: 333 | E34: 331 | F34: 301 | G34: 386
A35: Бренд 3 | B35: 372 | C35: 300 | D35: 314 | E35: 383 | F35: 331 | G35: 383
A36: Бренд 4 | B36: 365 | C36: 399 | D36: 375 | E36: 329 | F36: 395 | G36: 364
A37: Бренд 5 | B37: 344 | C37: 354 | D37: 374 | E37: 380 | F37: 366 | G37: 303
A38: Бренд 6 | B38: 335 | C38: 338 | D38: 382 | E38: 398 | F38: 335 | G38: 391
A39: Бренд 7 | B39: 381 | C39: 327 | D39: 338 | E39: 306 | F39: 369 | G39: 306
A40: Бренд 8 | B40: 339 | C40: 336 | D40: 397 | E40: 330 | F40: 393 | G40: 324
A41: Бренд 9 | B41: 344 | C41: 336 | D41: 344 | E41: 332 | F41: 336 | G41: 383
A42: Бренд 10 | B42: 327 | C42: 383 | D42: 375 | E42: 383 | F42: 304 | G42: 382
A43: Офлайн продажи
A44: Эконом сегмент
A45: Бренд 1 | B45: 199 | C45: 107 | D45: 115 | E45: 196 | F45: 149 | G45: 148
A46: Бренд 2 | B46: 164 | C46: 115 | D46: 133 | E46: 119 | F46: 150 | G46: 116
A47: Бренд 3 | B47: 114 | C47: 150 | D47: 114 | E47: 107 | F47: 104 | G47: 193
A48: Бренд 4 | B48: 106 | C48: 117 | D48: 167 | E48: 197 | F48: 122 | G48: 178
A49: Бренд 5 | B49: 119 | C49: 138 | D49: 101 | E49: 110 | F49: 153 | G49: 140
A50: Бренд 6 | B50: 166 | C50: 121 | D50: 175 | E50: 127 | F50: 138 | G50: 195
A51: Бренд 7 | B51: 156 | C51: 183 | D51: 180 | E51: 141 | F51: 144 | G51: 100
A52: Бренд 8 | B52: 120 | C52: 156 | D52: 162 | E52: 114 | F52: 152 | G52: 171
A53: Бренд 9 | B53: 105 | C53: 140 | D53: 199 | E53: 156 | F53: 197 | G53: 179
A54: Бренд 10 | B54: 147 | C54: 127 | D54: 169 | E54: 162 | F54: 142 | G54: 188
...

Sheet цены 2 полуг
I3: Цены
I4: Рублей/кило
I5: 2 полугодие
M9: 45108 | N9: 45139 | O9: 45170 | P9: 45200 | Q9: 45231 | R9: 45261
H10: Корма для собак | I10: Онлайн продажи
I11: Эконом сегмент
I12: Бренд 1 | M12: 117 | N12: 198 | O12: 118 | P12: 147 | Q12: 159 | R12: 118
I13: Бренд 2 | M13: 137 | N13: 183 | O13: 124 | P13: 158 | Q13: 168 | R13: 188
I14: Бренд 3 | M14: 117 | N14: 189 | O14: 150 | P14: 136 | Q14: 121 | R14: 113
I15: Бренд 4 | M15: 162 | N15: 190 | O15: 153 | P15: 139 | Q15: 165 | R15: 196
I16: Бренд 5 | M16: 177 | N16: 193 | O16: 198 | P16: 137 | Q16: 176 | R16: 166
I17: Бренд 6 | M17: 149 | N17: 152 | O17: 174 | P17: 124 | Q17: 128 | R17: 138
I18: Бренд 7 | M18: 134 | N18: 169 | O18: 156 | P18: 126 | Q18: 141 | R18: 108
I19: Бренд 8 | M19: 153 | N19: 168 | O19: 113 | P19: 155 | Q19: 179 | R19: 126
I20: Бренд 9 | M20: 200 | N20: 135 | O20: 153 | P20: 178 | Q20: 144 | R20: 149
I21: Бренд 10 | M21: 175 | N21: 161 | O21: 110 | P21: 176 | Q21: 150 | R21: 177
I22: Премиум сегмент
I23: Бренд 1 | M23: 318 | N23: 326 | O23: 390 | P23: 318 | Q23: 313 | R23: 344
I24: Бренд 2 | M24: 347 | N24: 320 | O24: 313 | P24: 313 | Q24: 385 | R24: 365
I25: Бренд 3 | M25: 343 | N25: 314 | O25: 381 | P25: 389 | Q25: 303 | R25: 320
I26: Бренд 4 | M26: 362 | N26: 340 | O26: 349 | P26: 362 | Q26: 378 | R26: 308
I27: Бренд 5 | M27: 370 | N27: 308 | O27: 311 | P27: 387 | Q27: 340 | R27: 382
I28: Бренд 6 | M28: 300 | N28: 381 | O28: 365 | P28: 320 | Q28: 311 | R28: 328
I29: Бренд 7 | M29: 373 | N29: 343 | O29: 376 | P29: 352 | Q29: 343 | R29: 333
I30: Бренд 8 | M30: 349 | N30: 319 | O30: 326 | P30: 311 | Q30: 356 | R30: 352
I31: Бренд 9 | M31: 331 | N31: 386 | O31: 301 | P31: 326 | Q31: 304 | R31: 304
I32: Бренд 10 | M32: 369 | N32: 312 | O32: 324 | P32: 328 | Q32: 347 | R32: 311
I33: Офлайн продажи
I34: Эконом сегмент
I35: Бренд 1 | M35: 126 | N35: 113 | O35: 102 | P35: 103 | Q35: 200 | R35: 162
I36: Бренд 2 | M36: 182 | N36: 129 | O36: 179 | P36: 189 | Q36: 198 | R36: 180
I37: Бренд 3 | M37: 173 | N37: 194 | O37: 104 | P37: 138 | Q37: 191 | R37: 110
I38: Бренд 4 | M38: 156 | N38: 147 | O38: 125 | P38: 111 | Q38: 187 | R38: 165
I39: Бренд 5 | M39: 161 | N39: 199 | O39: 123 | P39: 176 | Q39: 137 | R39: 119
I40: Бренд 6 | M40: 114 | N40: 132 | O40: 149 | P40: 172 | Q40: 156 | R40: 108
I41: Бренд 7 | M41: 195 | N41: 116 | O41: 169 | P41: 118 | Q41: 183 | R41: 161
I42: Бренд 8 | M42: 100 | N42: 149 | O42: 121 | P42: 176 | Q42: 185 | R42: 149
I43: Бренд 9 | M43: 107 | N43: 108 | O43: 138 | P43: 138 | Q43: 165 | R43: 193
I44: Бренд 10 | M44: 178 | N44: 195 | O44: 146 | P44: 131 | Q44: 180 | R44: 105
I45: Премиум сегмент
...

Sheet Расходы
B3: Затраты рублей на 1 кило
E9: 44927 | F9: 44958 | G9: 44986 | H9: 45017 | I9: 45047 | J9: 45078 | K9: 45108 | L9: 45139 | M9: 45170 | N9: 45200 | O9: 45231 | P9: 45261
B12: Корма для собак | C12: Онлайн продажи
B13: Корма для собак | C13: Эконом сегмент
B14: Корма для собак | C14: Бренд 1 | E14: 73.68745 | F14: 96.479189 | G14: 68.053013 | H14: 103.55351 | I14: 142.55331 | J14: 103.99019 | K14: 98.324176 | L14: 202.1684 | M14: 133.82838 | N14: 125.52615 | O14: 121.55107 | P14: 103.99419
B15: Корма для собак | C15: Бренд 2 | E15: 113.76376 | F15: 207.54996 | G15: 145.7709 | H15: 71.269187 | I15: 107.8372 | J15: 146.08756 | K15: 77.642335 | L15: 201.0971 | M15: 93.040861 | N15: 178.52564 | O15: 189.41568 | P15: 174.32709
B16: Корма для собак | C16: Бренд 3 | E16: 158.97745 | F16: 136.04412 | G16: 96.337489 | H16: 126.77373 | I16: 110.30804 | J16: 166.15905 | K16: 131.00135 | L16: 218.93305 | M16: 158.91509 | N16: 109.72604 | O16: 90.082491 | P16: 101.0503
B17: Корма для собак | C17: Бренд 4 | E17: 155.74072 | F17: 178.35061 | G17: 164.67512 | H17: 136.72686 | I17: 186.01308 | J17: 94.705678 | K17: 200.86377 | L17: 116.97876 | M17: 156.91925 | N17: 117.63249 | O17: 123.22341 | P17: 206.23773
B18: Корма для собак | C18: Бренд 5 | E18: 160.15559 | F18: 163.15784 | G18: 204.79837 | H18: 200.77033 | I18: 118.04719 | J18: 144.23594 | K18: 197.3595 | L18: 238.44965 | M18: 157.12074 | N18: 97.938732 | O18: 214.69738 | P18: 115.2591
B19: Корма для собак | C19: Бренд 6 | E19: 164.14089 | F19: 95.730857 | G19: 181.95688 | H19: 86.898666 | I19: 88.794245 | J19: 95.290166 | K19: 135.05312 | L19: 96.741904 | M19: 113.02344 | N19: 79.407619 | O19: 119.13425 | P19: 154.55379
B20: Корма для собак | C20: Бренд 7 | E20: 162.09985 | F20: 120.17278 | G20: 139.56107 | H20: 203.54711 | I20: 119.55518 | J20: 117.75781 | K20: 147.0249 | L20: 115.81659 | M20: 130.16139 | N20: 136.87862 | O20: 99.149188 | P20: 115.62319
B21: Корма для собак | C21: Бренд 8 | E21: 150.83837 | F21: 120.31677 | G21: 159.67742 | H21: 70.829999 | I21: 144.88447 | J21: 193.27453 | K21: 121.07124 | L21: 122.54206 | M21: 80.615686 | N21: 168.81613 | O21: 105.31913 | P21: 152.85991
B22: Корма для собак | C22: Бренд 9 | E22: 105.48649 | F22: 108.08928 | G22: 73.041405 | H22: 103.92511 | I22: 160.55824 | J22: 132.37691 | K22: 135.13362 | L22: 110.33458 | M22: 124.1447 | N22: 220.68534 | O22: 177.64252 | P22: 161.51689
B23: Корма для собак | C23: Бренд 10 | E23: 174.86751 | F23: 175.65337 | G23: 68.705118 | H23: 135.47936 | I23: 157.90157 | J23: 81.245845 | K23: 215.42402 | L23: 142.9234 | M23: 128.8738 | N23: 187.46531 | O23: 98.222373 | P23: 211.4416
B24: Корма для собак | C24: Премиум сегмент
B25: Корма для собак | C25: Бренд 1 | E25: 318.04236 | F25: 194.28134 | G25: 292.28776 | H25: 338.40309 | I25: 308.02895 | J25: 343.80431 | K25: 308.9503 | L25: 245.88654 | M25: 242.71475 | N25: 364.2034 | O25: 330.42763 | P25: 324.46537
B26: Корма для собак | C26: Бренд 2 | E26: 349.1158 | F26: 422.37055 | G26: 261.51466 | H26: 368.00175 | I26: 190.9169 | J26: 329.23245 | K26: 293.62121 | L26: 220.23785 | M26: 291.26588 | N26: 322.80878 | O26: 468.05382 | P26: 384.59304
B27: Корма для собак | C27: Бренд 3 | E27: 385.25811 | F27: 289.449 | G27: 247.74055 | H27: 356.77754 | I27: 345.66587 | J27: 487.31145 | K27: 237.52911 | L27: 228.236 | M27: 437.00437 | N27: 313.49308 | O27: 305.16539 | P27: 337.74911
B28: Корма для собак | C28: Бренд 4 | E28: 454.10057 | F28: 334.66836 | G28: 431.68525 | H28: 388.8117 | I28: 503.37686 | J28: 241.40188 | K28: 276.91418 | L28: 273.32948 | M28: 253.51119 | N28: 401.79119 | O28: 384.87516 | P28: 204.66064
B29: Корма для собак | C29: Бренд 5 | E29: 213.2344 | F29: 428.03714 | G29: 465.25805 | H29: 236.45591 | I29: 445.18789 | J29: 244.10273 | K29: 441.08362 | L29: 188.30985 | M29: 289.6656 | N29: 344.09025 | O29: 212.38752 | P29: 425.7026
B30: Корма для собак | C30: Бренд 6 | E30: 210.06079 | F30: 356.48582 | G30: 377.18258 | H30: 339.09655 | I30: 340.87676 | J30: 342.60847 | K30: 218.37071 | L30: 434.78276 | M30: 431.20241 | N30: 246.59351 | O30: 307.54743 | P30: 383.79567
B31: Корма для собак | C31: Бренд 7 | E31: 310.78739 | F31: 339.21064 | G31: 254.5262 | H31: 219.61278 | I31: 377.19852 | J31: 321.38588 | K31: 379.36661 | L31: 210.91472 | M31: 379.6618 | N31: 435.45123 | O31: 259.49138 | P31: 406.2916
B32: Корма для собак | C32: Бренд 8 | E32: 417.0995 | F32: 269.1926 | G32: 448.63306 | H32: 304.83838 | I32: 451.70717 | J32: 407.3209 | K32: 295.29847 | L32: 351.74158 | M32: 298.32096 | N32: 346.1413 | O32: 260.60401 | P32: 243.15838
B33: Корма для собак | C33: Бренд 9 | E33: 437.27158 | F33: 289.64618 | G33: 269.8525 | H33: 393.13713 | I33: 338.36746 | J33: 458.44533 | K33: 200.47071 | L33: 260.58486 | M33: 188.71336 | N33: 228.23642 | O33: 363.81138 | P33: 363.78906
B34: Корма для собак | C34: Бренд 10 | E34: 283.64791 | F34: 419.55597 | G34: 301.71083 | H34: 364.81955 | I34: 355.8404 | J34: 487.00844 | K34: 361.48353 | L34: 273.89843 | M34: 385.27589 | N34: 381.412 | O34: 408.98232 | P34: 344.47202
B35: Корма для собак | C35: Офлайн продажи
B36: Корма для собак | C36: Эконом сегмент
B37: Корма для собак | C37: Бренд 1 | E37: 184.16612 | F37: 122.03036 | G37: 84.722494 | H37: 211.27503 | I37: 156.20408 | J37: 170.26838 | K37: 144.96684 | L37: 82.985005 | M37: 116.62329 | N37: 78.533897 | O37: 125.91311 | P37: 99.407262
B38: Корма для собак | C38: Бренд 2 | E38: 164.33684 | F38: 116.19355 | G38: 150.0347 | H38: 87.884076 | I38: 181.20593 | J38: 143.44436 | K38: 159.22875 | L38: 120.54979 | M38: 220.02778 | N38: 198.50371 | O38: 122.97078 | P38: 168.85938
B39: Корма для собак | C39: Бренд 3 | E39: 75.629036 | F39: 128.88708 | G39: 80.538869 | H39: 88.606197 | I39: 91.837729 | J39: 235.04846 | K39: 118.82072 | L39: 226.19385 | M39: 116.71605 | N39: 142.56228 | O39: 134.83121 | P39: 88.520554
B40: Корма для собак | C40: Бренд 4 | E40: 88.728991 | F40: 98.526549 | G40: 144.38917 | H40: 199.85067 | I40: 111.96823 | J40: 165.11171 | K40: 131.03599 | L40: 114.00599 | M40: 124.00132 | N40: 115.56181 | O40: 126.14651 | P40: 158.87787
B41: Корма для собак | C41: Бренд 5 | E41: 91.008058 | F41: 131.06764 | G41: 89.618347 | H41: 75.117436 | I41: 148.03825 | J41: 106.07047 | K41: 107.09507 | L41: 162.92789 | M41: 79.348443 | N41: 192.84124 | O41: 166.5302 | P41: 67.641891
B42: Корма для собак | C42: Бренд 6 | E42: 134.0535 | F42: 135.80404 | G42: 134.53014 | H42: 84.635586 | I42: 124.42487 | J42: 197.58153 | K42: 71.527287 | L42: 88.368091 | M42: 149.25693 | N42: 207.94649 | O42: 126.06782 | P42: 100.04975
B43: Корма для собак | C43: Бренд 7 | E43: 103.82094 | F43: 158.70384 | G43: 143.88852 | H43: 134.03357 | I43: 143.42611 | J43: 121.36934 | K43: 203.91216 | L43: 97.830053 | M43: 140.62658 | N43: 89.547117 | O43: 160.99019 | P43: 156.29051
B44: Корма для собак | C44: Бренд 8 | E44: 106.7347 | F44: 132.30623 | G44: 191.5468 | H44: 106.98027 | I44: 182.62534 | J44: 188.92956 | K44: 114.53096 | L44: 181.48952 | M44: 74.55201 | N44: 218.6157 | O44: 135.67613 | P44: 111.08505
B45: Корма для собак | C45: Бренд 9 | E45: 101.64479 | F45: 149.91605 | G45: 173.37976 | H45: 108.29716 | I45: 233.71648 | J45: 119.49897 | K45: 73.817034 | L45: 122.55082 | M45: 94.64609 | N45: 149.32553 | O45: 170.08912 | P45: 151.3485
B46: Корма для собак | C46: Бренд 10 | E46: 98.467517 | F46: 94.862657 | G46: 134.27103 | H46: 131.43991 | I46: 100.87855 | J46: 152.38879 | K46: 125.56006 | L46: 165.2232 | M46: 149.34794 | N46: 140.12549 | O46: 143.24325 | P46: 115.10837
B47: Корма для собак | C47: Премиум сегмент
B48: Корма для собак | C48: Бренд 1 | E48: 249.5694 | F48: 434.77049 | G48: 393.29677 | H48: 198.39662 | I48: 423.31136 | J48: 379.73971 | K48: 411.50809 | L48: 246.64605 | M48: 283.54433 | N48: 354.12168 | O48: 249.32139 | P48: 423.89901
B49: Корма для собак | C49: Бренд 2 | E49: 407.69364 | F49: 421.44733 | G49: 221.89942 | H49: 306.87305 | I49: 327.17368 | J49: 329.27777 | K49: 258.18296 | L49: 249.08761 | M49: 474.35356 | N49: 386.85206 | O49: 340.16368 | P49: 382.71267
...
