Workbook

Sheet Содержание
B3: Тренинг «Навыки работы в Excel»
B6: Содержание
B7: Блок 1
B8: ='Настройки Excel'!$A$1 -> Настройки Excel
B9: =HotKeys!$A$1 -> HotKeys
B10: ='Плохие примеры'!$A$1 -> Плохие примеры оформления
B11: ='Форматы ячеек'!A1 -> Форматы ячеек
B12: ='Структура и оформление'!$A$1 -> Структура и оформление
B14: Блок 2
B15: ='Текст по столбцам'!$A$1 -> Текст по столбцам
B16: ='Анализ деклараций'!$A$1 -> Анализ таможенных деклараций
B17: ='Анализ чувствительности'!$A$1 -> Анализ чувствительности
B18: ='Консолидация данных'!$A$1 -> Консолидация данных
B20: Блок 3
B21: =Архитектура!A1 -> Архитектура
B22: =Дубликаты!A1 -> Дубликаты и ссылки на другие листы

Sheet Блок 1->

Sheet Настройки Excel
A1: Настройки Excel
B3: Настройка параметров Excel
C5: Убрать галочку в "разрешить редактировать в ячейках"
C7: Позволяет переходить на влияющую ячейку, если два раза на ячейку левой кнопкой мыши
C8: Если форула ссылается на несколько ячеек - то при нажатии пеходит на первую ссылку
Y10: Нажать 2 раза
C27: Пример | D27: =Y10 -> Нажать 2 раза
B30: Настройка ленты
C32: Вывести на панель быстрого доступа: влияющие ячейки, зависимые ячейки и убрать стрелки
C44: Влияющие ячейки: показывает, какие ячейки участвуют в расчете этой ячейки
C46: Пример | D46: =F46*G46-H46 -> 59 | F46: 12 | G46: 5 | H46: 1
C48: Зависимые ячейки: показывает, где используется данная ячейка
C50: Пример | D50: 14 | F50: =D50*2-1 -> 27 | G50: =F50*7-D46 -> 130 | H50: =D50-7 -> 7
C52: Убрать стрелки: убирает синие стрелки
C54: Показывать зависимые/влияющие ячейки можно через Alt+"цифра"
C65: Если влияющие ячейки на одном листе - можно нажать F2 - и ячейки будут подсвечиваться
J67: Пример
J68: =F46*G46-H46 -> 59
C74: Если влияющие/зависимые ячейки на разных листа - нужно нажать два раза ЛКМ на синию пунктирную линию
J79: Пример
J80: =Содержание!B9 -> HotKeys

Sheet HotKeys
A1: HotKeys
B2: HotKeys | C2: Описание
B3: Навигация
B4: Перемещение
B6: Стрелка | C6: перемещение на одной ячейку | E6: Продукт | F6: 2018 | G6: =F6+1 -> 2019 | H6: =G6+1 -> 2020 | I6: =H6+1 -> 2021 | J6: =I6+1 -> 2022 | K6: =J6+1 -> 2023 | L6: =K6+1 -> 2024 | O6: 2030
B7: Ctrl+Стрелка | C7: перемещение до конца непустых ячеек или до первой непустой ячейки | E7: Пр.1 | F7: 1 | G7: =F7*2 -> 2 | H7: =G7*2 -> 4 | I7: =H7*2 -> 8 | J7: =I7*2 -> 16 | K7: =J7*2 -> 32 | L7: =K7*2 -> 64 | O7: =L7*2 -> 128
B8: Ctrl+Home | C8: переход в ячейку A1 | E8: Пр.5 | F8: =F7+2 -> 3 | G8: =G7+2 -> 4 | H8: =H7+2 -> 6 | I8: =I7+2 -> 10 | J8: =J7+2 -> 18 | K8: =K7+2 -> 34 | L8: =L7+2 -> 66 | O8: =L8+2 -> 68
B9: Ctrl+Page Up (Page Down) | C9: переход на следующий лист (предыдущий) | E9: Пр.3 | F9: =F8+2 -> 5 | G9: =G8+2 -> 6 | H9: =H8+2 -> 8 | I9: =I8+2 -> 12 | J9: =J8+2 -> 20 | K9: =K8+2 -> 36 | L9: =L8+2 -> 68 | O9: =L9+2 -> 70
B10: F5 | C10: переход на прошлую редактируемую ячейку | E10: Пр.2 | F10: =F9*F7 -> 5 | G10: =G9*G7 -> 12 | H10: =H9*H7 -> 32 | I10: =I9*I7 -> 96 | J10: =J9*J7 -> 320 | K10: =K9*K7 -> 1152 | L10: =L9*L7 -> 4352 | O10: =L10+2 -> 4354
B11: Ctrl+[ | C11: проваливание во влияющую ячейку (работает, только если книга запущена при английской раскладке) | O11: =L11+2 -> 2
B12: Ctrl+] | C12: проваливание в зависимую ячейку (работает, только если книга запущена при английской раскладке)
B13: Enter | C13: на 1 ячейку вниз. Shift+Enter - вверх
B14: Tab | C14: на 1 ячейку вправо. Shift+Tab - вниз
B16: Выделение
B18: Shift+Стрелка | C18: выделение одной ячейки за каждое нажатие
B19: Ctrl+Shift+Стрелка | C19: выделение диапазона ячеек – до конца
B20: Shift+Пробел | C20: выделение строки
B21: Ctrl+Пробел | C21: выделение столбца
B22: Ctrl+Shift+Пробел (или Ctrl+A) | C22: выделение всей таблицы (если несколько раз нажать)
B24: Растягивание формул и копирование ячеек
B25: Растягивание формул
B27: Ctrl+R | C27: растягивание формулы по вправо
B28: Ctrl+D | C28: растягивание формулы по вниз
B30: Копирование ячеек
B32: Ctrl+С | C32: копировать
B33: Ctrl+X | C33: вырезать (аккуратно с этим действие)
B34: Ctrl+V | C34: вставить (вставляются формулы и форматирование)
B35: Ctrl+Alt+V | C35: специальная вставка
B36: Ctrl+«+» | C36: вставить ячейку со смещением (если выделен столбец/строка + добавляется целиком)
B37: Ctrl+«-» | C37: удалить ячейку (если выделен столбец/строка + добавляется целиком)
B39: Прочие
B41: F2 | C41: перейти в редактирование формулы. Показывает влияющие ячейки
B42: Tab (в момент редактирования формулы) | C42: дозаполняет формулу: пример если после ввода "=су" - нажать Tab - выберется формула СУММ. Выбор нужной формулу - через стрелки
B43: Alt+F1 | C43: быстрое построение столбчатое диаграммы
B44: Ctrl+Shift+L | C44: поставить/снять фильтр (важно выделять всю таблицу)
B45: Alt+стрелка вниз (на заголовке фильтра) | C45: параметры фильтрации
B46: Alt+Shift+Вправо (Влево) | C46: oгруппировать (разгруппировать) строки/столбцы (нужно выделить строку/столбец целиком)
B47: F4 | C47: повторение прошлого действия
B48: F4 (в редактировании формулы) | C48: фиксирование ячейки
B49: Alt,… | C49: огромное количество действий
...

Sheet Плохие примеры
A1: Плохие примеры оформления
B3: Основное
B5: → | C5: Отсутствие структуры
B7: → | C7: Харды вместо ссылок
B9: → | C9: Отсутствие источников
B11: Общий формат чисел
D13: Bad | E13: Good
C14: Выручка | D14: 158910.11 | E14: =D14 -> 158910.11
C15: Себестоимость | D15: -174801.49 | E15: =D15 -> -174801.49
C16: EBITDA | D16: =SUM(D14:D15) -> -15891.378 | E16: =SUM(E14:E15) -> -15891.378
C17: EBITDA margin | D17: =D16/D14 -> -0.10000231 | E17: =E16/E14 -> -0.10000231
B19: Объединение ячеек в таблицах
C21: Bad
C22: Показатель | D22: 2021 | E22: 2022
C23: Выручка | D23: 200 | E23: 250
C24: Себестоимость | D24: -200
C25: EBITDA | D25: =SUM(D23:D24) -> 0 | E25: =SUM(E23:E24) -> 250
B27: Разная ширина/высота (в тч на разных листах)
C29: Выручка | D29: 158910 | E29: Bad
C30: Себестоимость | D30: =-D29*1.1 -> -174801 | E30: Bad
C31: EBITDA | D31: =D29+D30 -> -15891
B33: Весь лист одним форматом
C35: Bad | F35: Good
C37: Компания 1 | F37: Компания 1
C38: Выручка | D38: =SUM(D39:D42) -> 750 | F38: Выручка | G38: =SUM(G39:G42) -> 750
C39: Продукт 1 | D39: 50 | F39: Продукт 1 | G39: 50
C40: Продукт 2 | D40: =D39*2 -> 100 | F40: Продукт 2 | G40: =G39*2 -> 100
C41: Продукт 3 | D41: =D40*2 -> 200 | F41: Продукт 3 | G41: =G40*2 -> 200
C42: Продукт 4 | D42: =D41*2 -> 400 | F42: Продукт 4 | G42: =G41*2 -> 400
C43: Себестоимость | D43: -200 | F43: Себестоимость | G43: -200
C44: EBITDA | D44: =D38+D43 -> 550 | F44: EBITDA | G44: =G38+G43 -> 550
C46: Компания 2 | F46: Компания 2
C47: Выручка | D47: =SUM(D48:D51) -> 750 | F47: Выручка | G47: =SUM(G48:G51) -> 750
C48: Продукт 1 | D48: 50 | F48: Продукт 1 | G48: 50
C49: Продукт 2 | D49: =D48*2 -> 100 | F49: Продукт 2 | G49: =G48*2 -> 100
C50: Продукт 3 | D50: =D49*2 -> 200 | F50: Продукт 3 | G50: =G49*2 -> 200
C51: Продукт 4 | D51: =D50*2 -> 400 | F51: Продукт 4 | G51: =G50*2 -> 400
C52: Себестоимость | D52: -200 | F52: Себестоимость | G52: -200
C53: EBITDA | D53: =D47+D52 -> 550 | F53: EBITDA | G53: =G47+G52 -> 550
C55: Всего выручка | D55: =D38+D47 -> 1500 | F55: Всего выручка | G55: =G38+G47 -> 1500
...

Sheet Структура и оформление
A1: Структура и оформление | J1: 2018 | K1: =J1+1 -> 2019 | L1: =K1+1 -> 2020 | M1: =L1+1 -> 2021 | N1: =M1+1 -> 2022 | O1: =N1+1 -> 2023 | P1: =O1+1 -> 2024 | Q1: =P1+1 -> 2025 | R1: =Q1+1 -> 2026 | ... V1: =U1+1 -> 2030
B2: Показатель | F2: ед. изм. | G2: Константа | H2: Источник
B4: Структурирование данных на листе и в книге
B6: Структурирование данных
C7: Данные на листе надо структурировать по блокам (выручка, расходы и тд)
C8: Большие блоки информации лучше группировать
C9: И крайне нежелательно скрывать столбцы/строки
C10: Закрепление строк и столбцов
B12: Листы в книге
C13: Название листа – соответствует тому, что там есть
C14: Крайне желательно, чтобы на разных листах находились одинаковые периоды по столбцам
C15: Листы должны содержать схожую информацию - если много листов в книге
B17: Выделение ячеек
C19: Стиль выделения должен быть единым во всей книге
C20: Желательно приводить легенду
C22: Что выделяется:
D23: Харды | G23: 100
D24: Ссылки на другие листы | G24: 100
D25: Изменение формулы в строке | G25: 100
D26: Переключатели | G26: 100 | J26: 561161
D27: Предварительные итоги | G27: 100
D28: Итоги | G28: 100
C30: Как выделяется:
D31: Заливка
D32: Границы
D33: Жирный/курсив
B35: HotKeys
E37: Ctrl+Shift+→ | F37: Группировать
E38: Ctrl+Shift+← | F38: Разгруппировать
B40: Пример
B42: Выручка
C43: Производство
D44: Мощности производства
E45: Линия 1 | F45: т/год | G45: 20 | H45: Клиент
E46: Линия 2 | F46: т/год | G46: 30 | H46: Клиент
D48: Загрузка производства
E49: Линия 1 | F49: % | H49: Клиент | J49: 0 | K49: 0 | L49: 0.1 | M49: 0.3 | N49: 0.7 | O49: 1 | P49: 1 | Q49: 1 | R49: 1 | S49: 1 | T49: 1 | U49: 1 | V49: 1
E50: Линия 2 | F50: % | H50: Клиент | J50: 0 | K50: 0 | L50: 0 | M50: 0.5 | N50: 0.7 | O50: 1 | P50: 1 | Q50: 1 | R50: 1 | S50: 1 | T50: 1 | U50: 1 | V50: 1
D52: Структура производства
D53: Линия 1
...

Sheet Форматы ячеек
A1: Форматы ячеек
B3: Форматы чисел
C5: Формат | D5: Положительное | E5: Отрицательное | F5: Ноль
C6: Базовый | D6: 100500 | E6: -100500 | F6: 0 | G6: Плохо
C7: Базовый | D7: 1.05 | E7: -1.05 | F7: 0 | G7: Плохо
C8: # ##0;(# ##0);- | D8: 100500 | E8: -100500 | F8: 0 | G8: Хорошо
C9: # ##0%;(# ##0%);- | D9: 1.05 | E9: -1.05 | F9: 0 | G9: Хорошо
C10: # ##0x;(# ##0x);- | D10: 105 | E10: -105 | F10: 0 | G10: Хорошо
B13: Форматы дат
C15: Формат | D15: Дата
C16: ДД.ММ.ГГГГ (базовый) | D16: =TODAY() -> 46078
C17: МММ.ГГ | D17: =TODAY() -> 46078
C18: МММ. ГГ | D18: =TODAY() -> 46078
C19: МММ.ГГГГ | D19: =TODAY() -> 46078
C20: ДД.МММ.ГГ | D20: =TODAY() -> 46078
C21: [$-x-sysdate]ДДДД, ММММ ДД, ГГГГ | D21: =TODAY() -> 46078
B23: HotKeys
C25: Ctrl+1 | D25: Меню формата ячеек
C26: Ctrl+Shift+1 | D26: Числовой формат с разделителями
C27: Ctrl+Shift+5 | D27: Проценты
C28: Alt - Z - 9 | D28: Убрать один разряд
C29: Alt - Z - 01 | D29: Добавить один разряд

Sheet Блок 2->

Sheet Формулы
A1: Формулы
B2: Формула | C2: Описание | D2: Пример 1 | E2: Пример 2 | F2: Комментарий | H2: Исходные данные
B3: Условия. Логические операторы
B5: И | D5: =AND(H5>=100,I5>=100) -> TRUE | E5: =AND(H5>=200,I5>=100) -> FALSE | H5: 100 | I5: 200
B6: ИЛИ | D6: =OR(H6>=100,I6>=100) -> TRUE | E6: =OR(H6>200,I6>200) -> FALSE | H6: 100 | I6: 200
B8: ЕСЛИ | D8: =IF(H8>0,1,0) -> 1 | E8: =IF(H8<0,1,0) -> 0 | H8: 100
B9: ЕСЛИ | D9: =IF(H9>0,"Верно","Не верно") -> Верно | E9: =IF(H9<0,"Верно","Не верно") -> Не верно | H9: 100
B10: ЕСЛИ(И…) | C10: С несколькими условиями вар.1 | D10: =IF(AND(H10>0,I10>0),1,0) -> 1 | E10: =IF(AND(H10<0,I10<0),1,0) -> 0 | H10: 100 | I10: 200
B11: ЕСЛИ(ЕСЛИ...) | C11: С несколькими условиями вар.2 | D11: =IF(H11>0,IF(I11>0,1,0),0) -> 1 | E11: =IF(H11<0,IF(I11<0,1,0),0) -> 0 | H11: 100 | I11: 200
B13: ЕСЛИОШИБКА | D13: =IFERROR(H13,0) -> 0 | E13: =IFERROR(H13,"Ошибка") -> Ошибка | H13: =ыва/2 -> #NAME?
B14: ЕСЛИОШИБКА | D14: =IFERROR(H14,0) -> 0 | E14: =IFERROR(H14,"Ошибка") -> Ошибка | H14: ="ыва"/2 -> #VALUE!
B15: ЕСЛИОШИБКА | D15: =IFERROR(H15,0) -> 0 | E15: =IFERROR(H15,"Ошибка") -> Ошибка | H15: =2/0 -> #DIV/0!
B16: ЕСЛИОШИБКА | D16: =IFERROR(H16,0) -> 0 | E16: =IFERROR(H16,"Ошибка") -> Ошибка | H16: =#REF! -> #REF!
B18: СУММЕСЛИ. СРЗНАЧЕСЛИ. СЧЕТЕСЛИ
B20: СУММЕСЛИ | C20: Суммирование по 1 условию | D20: =SUMIF($H$20:$H$24,"Продукт 1",$K$20:$K$24) -> 1 | H20: Продукт 1 | I20: Категория А | J20: Москва | K20: 1
B21: СУММЕСЛИ | C21: Суммирование, если больше/меньше/равно(не) | D21: =SUMIF($K$20:$K$24,">3") -> 4 | E21: =SUMIF($K$20:$K$25,"<>0") -> 11 | H21: Продукт 2 | I21: Категория А | J21: Тверь | K21: -2
B22: СУММЕСЛИ | C22: Суммирование по частичному совпадению условия | D22: =SUMIF($J$20:$J$24,"Моск" & "*",$K$20:$K$24) -> 5 | F22: Учитывается только совпадение текста с самого начала | H22: Продукт 3 | I22: Категория А | J22: Екб | K22: 3
B23: СУММЕСЛИМН | C23: Суммирование по нескольким условиям | D23: =SUMIFS($K$20:$K$24,$H$20:$H$24,"Продукт 1",$I$20:$I$24,"Категория А") -> 1 | H23: Продукт 4 | I23: Категория А | J23: Московская обл. | K23: 4
H24: Продукт 1 | I24: Категория Б | J24: Сочи | K24: 0
B25: СЧЁТЕСЛИ | C25: Счет, если больше/меньше/равно(не) | D25: =COUNTIF(K20:K25,"<>0") -> 5 | H25: Продукт 1 | J25: Сбб | K25: 5
B26: СЧЁТЕСЛИМН | D26: =COUNTIFS($K$20:$K$25,">0",$I$20:$I$25,"<>0") -> 4
B28: СРЗНАЧЕСЛИ | D28: =AVERAGEIF($H$20:$H$25,"Продукт 1",$K$20:$K$25) -> 2
B29: СРЗНАЧЕСЛИМН | D29: =AVERAGEIFS($K$20:$K$25,$I$20:$I$25,"Категория А",$J$20:$J$25,"Моск" & "*") -> 2.5
B31: Важно !
B32: Обязательно должна быть одинаковая длина диапазонов
B33: Не забывай фиксировать ячейки (F4)
B35: Извлечение значений из таблиц
B37: ВПР | D37: Продукт 5 | E37: =VLOOKUP($D$37,$H$37:$I$42,2,FALSE) -> Томаты | H37: Продукт 1 | I37: Две мясных котлеты гриль | J37: 200 ккал | L37: 1 кв. | M37: 2 кв. | N37: 3 кв. | O37: 4 кв.
B38: ГПР | D38: 3 кв. | E38: =HLOOKUP($D$38,$L$37:$O$38,2,FALSE) -> 15 | H38: Продукт 2 | I38: Спец.соус | J38: 100 ккал | L38: 5 | M38: 10 | N38: 15 | O38: 20
H39: Продукт 3 | I39: Сыр | J39: 50 ккал
B40: ИНДЕКС(ПОИСКПОЗ…) | D40: Продукт 5 | E40: =INDEX($J$37:$J$42,MATCH($D$40,$H$37:$H$42,0)) -> 15 ккал | H40: Продукт 4 | I40: Огурцы | J40: 10 ккал
H41: Продукт 5 | I41: Томаты | J41: 15 ккал
H42: Продукт 6 | I42: Лук | J42: 5 ккал
B43: Важно !
B44: ВПР и ГПР позволяют работать только с одним условием
B45: ВПР и ГПР искомое значения обязательно должно быть в первом столбце/строке
B46: Индекс+ПоискПоз - не имеет значение положением строк/столбоц
B47: Для всех функций - обязательно проверять единственность искомого значения (функции берут только первое)
B49: Извлечение значения по интервалам | I49: Выручка | J49: Тип фирмы
B50: ВПР | D50: 21 | E50: =VLOOKUP($D$50,$I$50:$J$54,2,TRUE) -> Маленькая | I50: 0 | J50: Микро
...

Sheet Текст по столбцам
A1: Текст по столбцам
B2: Текст по столбцам
B4: Исходные данные | E4: Разделение текста | H4: Готовые данные
B5: Domain Code,Domain,Area Code (M49),Area,Element Code,Element,Item Code (CPC),Item,Year Code,Year,Unit,Value,Flag,Flag Description,Note | H5: Domain Code | I5: Domain | J5: Area Code (M49) | K5: Area | L5: Element Code | M5: Element | N5: Item Code (CPC) | O5: Item | P5: Year Code | Q5: Year | R5: Unit | S5: Value | T5: Flag | U5: Flag Description
B6: QCL,"Crops and livestock products","008","Albania","5510","Production","01234","Tomatoes","2020","2020","t","313109","A","Official figure","" | E6: Данные → Текст по столбцам → | H6: QCL | I6: Crops and livestock products | J6: 8 | K6: Albania | L6: 5510 | M6: Production | N6: 1234 | O6: Tomatoes | P6: 2020 | Q6: 2020 | R6: t | S6: 313109 | T6: A | U6: Official figure
B7: QCL,"Crops and livestock products","008","Albania","5510","Production","01234","Tomatoes","2021","2021","t","314470.1","A","Official figure","" | E7: → С разделителями → выбрать "символ-разделитель" | H7: QCL | I7: Crops and livestock products | J7: 8 | K7: Albania | L7: 5510 | M7: Production | N7: 1234 | O7: Tomatoes | P7: 2021 | Q7: 2021 | R7: t | S7: 314470.1 | T7: A | U7: Official figure
B8: QCL,"Crops and livestock products","008","Albania","5510","Production","01234","Tomatoes","2022","2022","t","315057.3","A","Official figure","" | H8: QCL | I8: Crops and livestock products | J8: 8 | K8: Albania | L8: 5510 | M8: Production | N8: 1234 | O8: Tomatoes | P8: 2022 | Q8: 2022 | R8: t | S8: 315057.3 | T8: A | U8: Official figure
B9: QCL,"Crops and livestock products","012","Algeria","5510","Production","01234","Tomatoes","2020","2020","t","1635616.3","A","Official figure","" | H9: QCL | I9: Crops and livestock products | J9: 12 | K9: Algeria | L9: 5510 | M9: Production | N9: 1234 | O9: Tomatoes | P9: 2020 | Q9: 2020 | R9: t | S9: 1635616.3 | T9: A | U9: Official figure
B10: QCL,"Crops and livestock products","012","Algeria","5510","Production","01234","Tomatoes","2021","2021","t","1641636","A","Official figure","" | E10: Если получаются некорректные форматы из-за "." или "," в числах: выделить столбец | H10: QCL | I10: Crops and livestock products | J10: 12 | K10: Algeria | L10: 5510 | M10: Production | N10: 1234 | O10: Tomatoes | P10: 2021 | Q10: 2021 | R10: t | S10: 1641636 | T10: A | U10: Official figure
B11: QCL,"Crops and livestock products","012","Algeria","5510","Production","01234","Tomatoes","2022","2022","t","1661664.37","I","Imputed value","" | H11: QCL | I11: Crops and livestock products | J11: 12 | K11: Algeria | L11: 5510 | M11: Production | N11: 1234 | O11: Tomatoes | P11: 2022 | Q11: 2022 | R11: t | S11: 1661664.4 | T11: I | U11: Imputed value
B12: QCL,"Crops and livestock products","024","Angola","5510","Production","01234","Tomatoes","2020","2020","t","589664","A","Official figure","" | H12: QCL | I12: Crops and livestock products | J12: 24 | K12: Angola | L12: 5510 | M12: Production | N12: 1234 | O12: Tomatoes | P12: 2020 | Q12: 2020 | R12: t | S12: 589664 | T12: A | U12: Official figure
B13: QCL,"Crops and livestock products","024","Angola","5510","Production","01234","Tomatoes","2021","2021","t","561666","A","Official figure","" | H13: QCL | I13: Crops and livestock products | J13: 24 | K13: Angola | L13: 5510 | M13: Production | N13: 1234 | O13: Tomatoes | P13: 2021 | Q13: 2021 | R13: t | S13: 561666 | T13: A | U13: Official figure
B14: QCL,"Crops and livestock products","024","Angola","5510","Production","01234","Tomatoes","2022","2022","t","587785","A","Official figure","" | H14: QCL | I14: Crops and livestock products | J14: 24 | K14: Angola | L14: 5510 | M14: Production | N14: 1234 | O14: Tomatoes | P14: 2022 | Q14: 2022 | R14: t | S14: 587785 | T14: A | U14: Official figure
B15: QCL,"Crops and livestock products","028","Antigua and Barbuda","5510","Production","01234","Tomatoes","2020","2020","t","34.7","A","Official figure","" | H15: QCL | I15: Crops and livestock products | J15: 28 | K15: Antigua and Barbuda | L15: 5510 | M15: Production | N15: 1234 | O15: Tomatoes | P15: 2020 | Q15: 2020 | R15: t | S15: 34.7 | T15: A | U15: Official figure
B16: QCL,"Crops and livestock products","028","Antigua and Barbuda","5510","Production","01234","Tomatoes","2021","2021","t","71.45","A","Official figure","" | H16: QCL | I16: Crops and livestock products | J16: 28 | K16: Antigua and Barbuda | L16: 5510 | M16: Production | N16: 1234 | O16: Tomatoes | P16: 2021 | Q16: 2021 | R16: t | S16: 71.45 | T16: A | U16: Official figure
B17: QCL,"Crops and livestock products","028","Antigua and Barbuda","5510","Production","01234","Tomatoes","2022","2022","t","90.5","A","Official figure","" | H17: QCL | I17: Crops and livestock products | J17: 28 | K17: Antigua and Barbuda | L17: 5510 | M17: Production | N17: 1234 | O17: Tomatoes | P17: 2022 | Q17: 2022 | R17: t | S17: 90.5 | T17: A | U17: Official figure
B18: QCL,"Crops and livestock products","032","Argentina","5510","Production","01234","Tomatoes","2020","2020","t","1221000","A","Official figure","" | H18: QCL | I18: Crops and livestock products | J18: 32 | K18: Argentina | L18: 5510 | M18: Production | N18: 1234 | O18: Tomatoes | P18: 2020 | Q18: 2020 | R18: t | S18: 1221000 | T18: A | U18: Official figure
B19: QCL,"Crops and livestock products","032","Argentina","5510","Production","01234","Tomatoes","2021","2021","t","1362000","A","Official figure","" | H19: QCL | I19: Crops and livestock products | J19: 32 | K19: Argentina | L19: 5510 | M19: Production | N19: 1234 | O19: Tomatoes | P19: 2021 | Q19: 2021 | R19: t | S19: 1362000 | T19: A | U19: Official figure
B20: QCL,"Crops and livestock products","032","Argentina","5510","Production","01234","Tomatoes","2022","2022","t","1393000","A","Official figure","" | H20: QCL | I20: Crops and livestock products | J20: 32 | K20: Argentina | L20: 5510 | M20: Production | N20: 1234 | O20: Tomatoes | P20: 2022 | Q20: 2022 | R20: t | S20: 1393000 | T20: A | U20: Official figure
B21: QCL,"Crops and livestock products","051","Armenia","5510","Production","01234","Tomatoes","2020","2020","t","183656.9","A","Official figure","" | H21: QCL | I21: Crops and livestock products | J21: 51 | K21: Armenia | L21: 5510 | M21: Production | N21: 1234 | O21: Tomatoes | P21: 2020 | Q21: 2020 | R21: t | S21: 183656.9 | T21: A | U21: Official figure
B22: QCL,"Crops and livestock products","051","Armenia","5510","Production","01234","Tomatoes","2021","2021","t","206085.5","A","Official figure","" | H22: QCL | I22: Crops and livestock products | J22: 51 | K22: Armenia | L22: 5510 | M22: Production | N22: 1234 | O22: Tomatoes | P22: 2021 | Q22: 2021 | R22: t | S22: 206085.5 | T22: A | U22: Official figure
... B28: QCL,"Crops and livestock products","040","Austria","5510","Production","01234","Tomatoes","2021","2021","t","59770","A","Official figure","" | H28: QCL | I28: Crops and livestock products | J28: 40 | K28: Austria | L28: 5510 | M28: Production | N28: 1234 | O28: Tomatoes | P28: 2021 | Q28: 2021 | R28: t | S28: 59770 | T28: A | U28: Official figure
B29: QCL,"Crops and livestock products","044","Bahamas","5510","Production","01234","Tomatoes","2020","2020","t","7642.44","E","Estimated value","" | E29: Затем - автозамена "." на "," | H29: QCL | I29: Crops and livestock products | J29: 44 | K29: Bahamas | L29: 5510 | M29: Production | N29: 1234 | O29: Tomatoes | P29: 2020 | Q29: 2020 | R29: t | S29: 7642.44 | T29: E | U29: Estimated value
B30: QCL,"Crops and livestock products","044","Bahamas","5510","Production","01234","Tomatoes","2021","2021","t","7512.81","E","Estimated value","" | H30: QCL | I30: Crops and livestock products | J30: 44 | K30: Bahamas | L30: 5510 | M30: Production | N30: 1234 | O30: Tomatoes | P30: 2021 | Q30: 2021 | R30: t | S30: 7512.81 | T30: E | U30: Estimated value
B32: Объединение ячеек
B34: Исходные данные | E34: Готовые данные: 1 | F34: Готовые данные: 2
B36: Имя | C36: Фамилия | E36: Имя_Фамилия | F36: Имя_Фамилия
B37: Имя1 | C37: Фамилия1 | E37: =B37 & "_" & C37 -> Имя1_Фамилия1 | F37: =CONCATENATE(B37,"_",C37) -> Имя1_Фамилия1
B38: Имя2 | C38: Фамилия2 | E38: =B38 & "_" & C38 -> Имя2_Фамилия2 | F38: =CONCATENATE(B38,"_",C38) -> Имя2_Фамилия2
B39: Имя3 | C39: Фамилия3 | E39: =B39 & "_" & C39 -> Имя3_Фамилия3 | F39: =CONCATENATE(B39,"_",C39) -> Имя3_Фамилия3
B40: Имя4 | C40: Фамилия4 | E40: =B40 & "_" & C40 -> Имя4_Фамилия4 | F40: =CONCATENATE(B40,"_",C40) -> Имя4_Фамилия4
B41: Имя5 | C41: Фамилия5 | E41: =B41 & "_" & C41 -> Имя5_Фамилия5 | F41: =CONCATENATE(B41,"_",C41) -> Имя5_Фамилия5

Sheet Анализ деклараций
A1: Анализ таможенных деклараций
B2: Показатель | G2: ед. изм. | H2: Константа
B3: Первичная обработка
C5: 1 | D5: Скопировать как значения (сильно уменьшает вес файла)
C6: 2 | D6: Закрепить области
C7: 3 | D7: Поставить фильтр
C8: 4 | D8: Проверить, что по столбцам одинаковая информация (особенно, если объединено несколько сводных таблиц)
C9: 5 | D9: Опционально - сгруппировать скрытые столбцы
C10: 6 | D10: Сделать замену (Ctrl+H) символов ", > и < (некорретно считается со знаками)
B12: Сведение данных
C13: СУММЕСЛИ. СУММЕСЛИМН
I14: Выделение диапазона | L14: Выделение всего столбца (увеличивает время расчета)
D15: Объемы торговли, штуки | I15: СУММЕСЛИ | J15: СУММЕСЛИМН | L15: СУММЕСЛИ | M15: СУММЕСЛИМН
E16: ИМ | G16: тыс. шт. | I16: =SUMIF('Декларации_Исх. данные'!$I$3:$I$343,$E16,'Декларации_Исх. данные'!$CA$3:$CA$343)/1000 -> 18515.6 | J16: =SUMIFS('Декларации_Исх. данные'!$CA$3:$CA$343,'Декларации_Исх. данные'!$I$3:$I$343,$E16)/1000 -> 18515.6 | L16: =SUMIF('Декларации_Исх. данные'!$I:$I,$E16,'Декларации_Исх. данные'!$CA:$CA)/1000 -> 18515.6 | M16: =SUMIFS('Декларации_Исх. данные'!$CA:$CA,'Декларации_Исх. данные'!$I:$I,$E16)/1000 -> 18515.6
E17: ЭК | G17: тыс. шт. | I17: =SUMIF('Декларации_Исх. данные'!$I$3:$I$343,$E17,'Декларации_Исх. данные'!$CA$3:$CA$343)/1000 -> 1152 | J17: =SUMIFS('Декларации_Исх. данные'!$CA$3:$CA$343,'Декларации_Исх. данные'!$I$3:$I$343,$E17)/1000 -> 1152 | L17: =SUMIF('Декларации_Исх. данные'!$I:$I,$E17,'Декларации_Исх. данные'!$CA:$CA)/1000 -> 1152 | M17: =SUMIFS('Декларации_Исх. данные'!$CA:$CA,'Декларации_Исх. данные'!$I:$I,$E17)/1000 -> 1152
C19: Важно !
E20: Обязательно должна быть одинаковая длина диапазонов
E21: Не забывай фиксировать ячейки (F4)
C23: Удаление дубликатов
C25: 1 | D25: Выделить весь столбец
C26: 2 | D26: Скопировать и вставить отдельно
C27: 3 | D27: Данные → Удалить дубликаты → Сортировать в пределах указанного диапазона
D29: Импорт. Страна отправления
D30: ИМ | E30: ВЕНГРИЯ | G30: тыс. шт. | I30: =SUMIFS('Декларации_Исх. данные'!$CA:$CA,'Декларации_Исх. данные'!$I:$I,$D30,'Декларации_Исх. данные'!$AR:$AR,$E30)/1000 -> 3113.7
D31: ИМ | E31: КАНАДА | G31: тыс. шт. | I31: =SUMIFS('Декларации_Исх. данные'!$CA:$CA,'Декларации_Исх. данные'!$I:$I,$D31,'Декларации_Исх. данные'!$AR:$AR,$E31)/1000 -> 5626.2
D32: ИМ | E32: СОЕДИНЕННОЕ КОРОЛЕВСТВО | G32: тыс. шт. | I32: =SUMIFS('Декларации_Исх. данные'!$CA:$CA,'Декларации_Исх. данные'!$I:$I,$D32,'Декларации_Исх. данные'!$AR:$AR,$E32)/1000 -> 644.6
D33: ИМ | E33: ГЕРМАНИЯ | G33: тыс. шт. | I33: =SUMIFS('Декларации_Исх. данные'!$CA:$CA,'Декларации_Исх. данные'!$I:$I,$D33,'Декларации_Исх. данные'!$AR:$AR,$E33)/1000 -> 5140.9
D34: ИМ | E34: ФРАНЦИЯ | G34: тыс. шт. | I34: =SUMIFS('Декларации_Исх. данные'!$CA:$CA,'Декларации_Исх. данные'!$I:$I,$D34,'Декларации_Исх. данные'!$AR:$AR,$E34)/1000 -> 1530
D35: ИМ | E35: СЛОВАКИЯ | G35: тыс. шт. | I35: =SUMIFS('Декларации_Исх. данные'!$CA:$CA,'Декларации_Исх. данные'!$I:$I,$D35,'Декларации_Исх. данные'!$AR:$AR,$E35)/1000 -> 1941.2
D36: ИМ | E36: ИСПАНИЯ | G36: тыс. шт. | I36: =SUMIFS('Декларации_Исх. данные'!$CA:$CA,'Декларации_Исх. данные'!$I:$I,$D36,'Декларации_Исх. данные'!$AR:$AR,$E36)/1000 -> 156
D37: ИМ | E37: ИТАЛИЯ | G37: тыс. шт. | I37: =SUMIFS('Декларации_Исх. данные'!$CA:$CA,'Декларации_Исх. данные'!$I:$I,$D37,'Декларации_Исх. данные'!$AR:$AR,$E37)/1000 -> 363
D38: ИМ | E38: РОССИЯ | G38: тыс. шт. | I38: =SUMIFS('Декларации_Исх. данные'!$CA:$CA,'Декларации_Исх. данные'!$I:$I,$D38,'Декларации_Исх. данные'!$AR:$AR,$E38)/1000 -> 0
E39: Всего | G39: тыс. шт. | I39: =SUM(I30:I38) -> 18515.6
F40: Проверка | I40: =I39-I16 -> 0
C42: Частичное совпадение
D44: Импорт по производителям
D45: ИМ | E45: CUDDY FARMS LIMITED 2008 | G45: тыс. шт. | I45: =SUMIFS('Декларации_Исх. данные'!$CA:$CA,'Декларации_Исх. данные'!$I:$I,$D45,'Декларации_Исх. данные'!$BX:$BX,$E45)/1000 -> 5341.4
D46: ИМ | E46: CUDDY FARMS LIMITED 2008, ПЛЕМЗАВОД: KRS0000042053 | G46: тыс. шт. | I46: =SUMIFS('Декларации_Исх. данные'!$CA:$CA,'Декларации_Исх. данные'!$I:$I,$D46,'Декларации_Исх. данные'!$BX:$BX,$E46)/1000 -> 24
D47: ИМ | E47: HENDRIX GENETICS TURKEYS FRANCE | G47: тыс. шт. | I47: =SUMIFS('Декларации_Исх. данные'!$CA:$CA,'Декларации_Исх. данные'!$I:$I,$D47,'Декларации_Исх. данные'!$BX:$BX,$E47)/1000 -> 611.6
D48: ИМ | E48: HENDRIX GENETICS TURKEYS FRANCE SAS | G48: тыс. шт. | I48: =SUMIFS('Декларации_Исх. данные'!$CA:$CA,'Декларации_Исх. данные'!$I:$I,$D48,'Декларации_Исх. данные'!$BX:$BX,$E48)/1000 -> 148.2
...

Sheet Декларации_Исх. данные
BT1: Пример
B2: Учет | C2: D1 Дата выпуска груза | D2: Месяц | E2: ND Номер декларации на товары | F2: 071 Таможня оформления ДТ | G2: 072 Дата ДТ | H2: 073 Порядковый № ДТ | I2: 011 ИМ.ЭК - направление перемещения | J2: 012 Основной таможенный режим | K2: 013 Дополнительный признак | L2: 020 ОГРН.ОГРНИП отправителя | M2: 021 ИНН отправителя | N2: 022 Наименование.ФИО отправителя | O2: 023 Адрес отправителя | P2: 024 ОКАТО отправителя | Q2: 027 КПП отправителя | R2: 03 Листов ДТ | S2: 04 Спецификаций ДТ | T2: 05 Товаров всего | U2: 06 Мест товара всего | V2: 080 ОГРН.ОГРНИП получателя | W2: 081 ИНН получателя | X2: 082 Наименование.ФИО получателя | Y2: 083 Адрес получателя | Z2: 084 ОКАТО получателя | AA2: 087 КПП получателя | AB2: 090 ОГРН.ОГРНИП контрактодержателя | AC2: 091 ИНН контрактодержателя | AD2: 092 Наименование.ФИО контрактодержателя | AE2: 093 Адрес контрактодержателя | AF2: 094 ОКАТО контрактодержателя | AG2: 097 КПП контрактодержателя | AH2: 11 Код торгующей страны | AI2: 11 Торгующая страна | AJ2: 12 Общая таможенная стоимость | AK2: 140 ОГРН.ОГРНИП декларанта | AL2: 141 ИНН контрактодержателя | AM2: 142 Наименование.ФИО декларанта | AN2: 143 Адрес контрактодержателя | AO2: 144 ОКАТО контрактодержателя | AP2: 147 КПП контрактодержателя | AQ2: 15А Код страны отправления | AR2: 15 Страна отправления | AS2: 16 Страна происхождения | AT2: 17А Код страны назначения | AU2: 17 Страна назначения | AV2: 18 Кол-во транспорта при отправлении | AW2: 19 Признак контейнерных перевозок 0ю1 | AX2: 202 Условие поставки | AY2: 2021 Пункт поставки товара | AZ2: 21 Кол-во трансп на границе | BA2: 221 Валюта контракта | BB2: 222 Общая фактурная стоимость | BC2: 2220 Общая фактурная стоимость, руб | BD2: 226 Статистическая стоимость суммарная | BE2: 23 Курс валюты | BF2: 24 Характер сделки | BG2: 25 Вид транспортного средства | BH2: 28 ОКПО банка.паспорт сделки | BI2: 29 Таможня на границе | BJ2: 300 Тип информации | BK2: 301 № свидетельства СВХ.ТС | BL2: 302 Вид документа.Вид ТС | BM2: 30POST Индекс места нахождения товара | BN2: 30SUBD Регион | BO2: 30CITY Населенный пункт | BP2: 30STREET Адрес местонахождения товара | BQ2: 3012 Таможня в зоне которой склад | BR2: 3 Порядковый № листа ДТ | BS2: 31_1 Описание и характеристика товара | BT2: Индей | BU2: Индюш | BV2: Индейка | BW2: 31_11 Товарный знак | BX2: 31_12 Наименование фирмы изготовителя | BY2: 31_2 Кол-во мест товара | BZ2: 31_3 Кол-во контейнеров | CA2: 31_7 Кол-во товара в доп ед. измерения | CB2: 31_71 Дополнительная единица | CC2: 31_8 Кол-во товара в доп единице | CD2: 31_81 Дополнительная единица | CE2: 32 Номер товара по ДТ | CF2: 33 Код товара по ТН ВЭД РФ | CG2: 331 Признак нетарифного регулирования | CH2: 332 Признак объекта интеллект собственности | CI2: 34 Код страны происхождения | CJ2: 35 Вес брутто, кг | CK2: 36 Преференции | CL2: 37 Процедура | CM2: 38 Вес нетто, кг | CN2: 39 Квота | CO2: 391 Код валюты квоты | CP2: 392 Единица измерения квоты | CQ2: 42 Фактурная стоимость | CR2: 420 Фактурная стоимость, руб | CS2: 43 Признак корректировки таможенной стоимости (КТС) | CT2: 431 Метод определения таможенной стоимости | CU2: 45 Таможенная стоимость | CV2: 46 Статистическая стоимость | CW2: D0 Код завршения таможенного оформления | CX2: USD/KG Статистическая стоимость, USD/Dtc НЕТТО, кг | CY2: 541 Свидетельство таможенного брокера | CZ2: 5411 Договор брокера с декларантом | DA2: 5441 ФИО заполнившего ДТ | DB2: ЛНП выпускающего инспектора | DC2: ND_DEL Признак удаления декларации
B3: 1 | C3: 08.08.2023 | D3: 8 | E3: 10013160/080823/3352101 | F3: 10013160 | G3: 08.08.2023 | H3: 3352101 | I3: ИМ | J3: 40 | N3: NAGISZ ZRT. | O3: 4181, , NADUDVAR, FO UT 119, | T3: 1 | U3: 591 | V3: 1047796588146 | W3: 7710553010 | X3: ООО "АГРОИМПОРТ" | Y3: 143421, МОСКОВСКАЯ ОБЛ., КРАСНОГОРСКИЙ Р-Н, 26 КМ А/Д "БАЛТИЯ", БЦ "РИГА-ЛЕНД", | Z3: 46000 | AA3: 502401001 | AB3: 1047796588146 | AC3: 7710553010 | AD3: ООО "АГРОИМПОРТ" | AE3: 143421, МОСКОВСКАЯ ОБЛ., КРАСНОГОРСКИЙ Р-Н, 26 КМ А/Д "БАЛТИЯ", БЦ "РИГА-ЛЕНД", | AF3: 46000 | AG3: 502401001 | AH3: HU | AI3: ВЕНГРИЯ | AJ3: 15945264 | AK3: 1047796588146 | AL3: 7710553010 | AM3: ООО "АГРОИМПОРТ" | AN3: 143421, МОСКОВСКАЯ ОБЛ., КРАСНОГОРСКИЙ Р-Н, 26 КМ А/Д "БАЛТИЯ", БЦ "РИГА-ЛЕНД", | AO3: 46000 | AP3: 502401001 | AQ3: HU | AR3: ВЕНГРИЯ | AS3: ВЕНГРИЯ | AT3: RU | AU3: РОССИЯ | AW3: 0 | AX3: FCA | AY3: NADUDVAR | BA3: EUR | BB3: 147750 | BE3: 106.0543 | BI3: - | BJ3: 99 | BQ3: 10413090 т/п Пензенский областной | BS3: ИНДЮШАЧЬИ ЯЙЦА ДЛЯ ИНКУБАЦИИ, ОПЛОДОТВОРЕННЫЕ, MELEAGRIS GALLOPAVO L., ПОРОДА БЕЛАЯ ШИРОКОГРУДАЯ КРОССА БИГ-6, РАЗМЕЩЕНЫ С ЦЕЛЬЮ ПРЕДОТВРАЩЕНИЯ БОЯ И УНИЧТОЖЕНИЯ В КАРТОННЫХ КОРОБКАХ | BT3: =MIN(1,IFERROR(SEARCH(BT$2,$BS3),0)) -> 0 | BU3: =MIN(1,IFERROR(SEARCH(BU$2,$BS3),0)) -> 1 | BV3: =MAX(BT3,BU3) -> 1 | BW3: ОТСУТСТВУЕТ | BX3: NAGISZ ZRT. | BY3: 591 | BZ3: 0 | CA3: 118200 | CB3: ШТ | CE3: 1 | CF3: 0407191100 | CI3: HU | CJ3: 13002 | CK3: ОООО-ЛП | CL3: 4000000 | CM3: 12411 | CN3: 0 | CQ3: 147750 | CS3: 0 | CT3: 1 | CU3: 15945264 | CV3: 165121.59 | CW3: 10 | CX3: 13.3 | DB3: 1432
B4: 1 | C4: 05.08.2023 | D4: 8 | E4: 10013160/050823/3349274 | F4: 10013160 | G4: 05.08.2023 | H4: 3349274 | I4: ИМ | J4: 40 | N4: NAGISZ ZRT. | O4: 4181, , NADUDVAR, FO UT 119, | T4: 1 | U4: 326 | V4: 1047796588146 | W4: 7710553010 | X4: ООО "АГРОИМПОРТ" | Y4: 143421, МОСКОВСКАЯ ОБЛ., КРАСНОГОРСКИЙ Р-Н, 26 КМ А/Д "БАЛТИЯ", БЦ "РИГА-ЛЕНД", | Z4: 46000 | AA4: 502401001 | AB4: 1047796588146 | AC4: 7710553010 | AD4: ООО "АГРОИМПОРТ" | AE4: 143421, МОСКОВСКАЯ ОБЛ., КРАСНОГОРСКИЙ Р-Н, 26 КМ А/Д "БАЛТИЯ", БЦ "РИГА-ЛЕНД", | AF4: 46000 | AG4: 502401001 | AH4: HU | AI4: ВЕНГРИЯ | AJ4: 8920298.6 | AK4: 1047796588146 | AL4: 7710553010 | AM4: ООО "АГРОИМПОРТ" | AN4: 143421, МОСКОВСКАЯ ОБЛ., КРАСНОГОРСКИЙ Р-Н, 26 КМ А/Д "БАЛТИЯ", БЦ "РИГА-ЛЕНД", | AO4: 46000 | AP4: 502401001 | AQ4: HU | AR4: ВЕНГРИЯ | AS4: ВЕНГРИЯ | AT4: RU | AU4: РОССИЯ | AW4: 0 | AX4: FCA | AY4: NADUDVAR | BA4: EUR | BB4: 83456 | BE4: 103.8379 | BI4: - | BJ4: СВ | BQ4: 10113020 т/п Вяземский | BS4: ИНДЮШАЧЬИ ЯЙЦА ДЛЯ ИНКУБАЦИИ, ОПЛОДОТВОРЕННЫЕ, MELEAGRIS GALLOPAVO L., ПОРОДА БЕЛАЯ ШИРОКОГРУДАЯ КРОССА БИГ-6, РАЗМЕЩЕНЫ С ЦЕЛЬЮ ПРЕДОТВРАЩЕНИЯ БОЯ И УНИЧТОЖЕНИЯ В КАРТОННЫХ КОРОБКАХ | BT4: =MIN(1,IFERROR(SEARCH(BT$2,$BS4),0)) -> 0 | BU4: =MIN(1,IFERROR(SEARCH(BU$2,$BS4),0)) -> 1 | BV4: =MAX(BT4,BU4) -> 1 | BW4: ОТСУТСТВУЕТ | BX4: NAGISZ ZRT. | BY4: 326 | CA4: 65200 | CB4: ШТ | CE4: 1 | CF4: 0407191100 | CI4: HU | CJ4: 7172 | CK4: ОООО-ЛП | CL4: 4000000 | CM4: 6846 | CN4: 0 | CQ4: 83456 | CU4: 8920298.6 | CV4: 94088.43 | CW4: 10 | CX4: 13.74 | DB4: 1390
B5: 1 | C5: 01.08.2023 | D5: 8 | E5: 10013160/010823/3342116 | F5: 10013160 | G5: 01.08.2023 | H5: 3342116 | I5: ИМ | J5: 40 | N5: NAGISZ ZRT. | O5: 4181, , NADUDVAR, FO UT 119, | T5: 1 | U5: 330 | V5: 1047796588146 | W5: 7710553010 | X5: ООО "АГРОИМПОРТ" | Y5: 143421, МОСКОВСКАЯ ОБЛ., КРАСНОГОРСКИЙ Р-Н, 26 КМ А/Д "БАЛТИЯ", БЦ "РИГА-ЛЕНД", | Z5: 46000 | AA5: 502401001 | AB5: 1047796588146 | AC5: 7710553010 | AD5: ООО "АГРОИМПОРТ" | AE5: 143421, МОСКОВСКАЯ ОБЛ., КРАСНОГОРСКИЙ Р-Н, 26 КМ А/Д "БАЛТИЯ", БЦ "РИГА-ЛЕНД", | AF5: 46000 | AG5: 502401001 | AH5: HU | AI5: ВЕНГРИЯ | AJ5: 8590232.3 | AK5: 1047796588146 | AL5: 7710553010 | AM5: ООО "АГРОИМПОРТ" | AN5: 143421, МОСКОВСКАЯ ОБЛ., КРАСНОГОРСКИЙ Р-Н, 26 КМ А/Д "БАЛТИЯ", БЦ "РИГА-ЛЕНД", | AO5: 46000 | AP5: 502401001 | AQ5: HU | AR5: ВЕНГРИЯ | AS5: ВЕНГРИЯ | AT5: RU | AU5: РОССИЯ | AW5: 0 | AX5: FCA | AY5: NADUDVAR | BA5: EUR | BB5: 82500 | BE5: 100.9428 | BI5: - | BJ5: Ин | BQ5: 10413090 т/п Пензенский областной | BS5: ИНДЮШАЧЬИ ЯЙЦА ДЛЯ ИНКУБАЦИИ, ОПЛОДОТВОРЕННЫЕ, MELEAGRIS GALLOPAVO L., ПОРОДА БЕЛАЯ ШИРОКОГРУДАЯ КРОССА БИГ-6, РАЗМЕЩЕНЫ С ЦЕЛЬЮ ПРЕДОТВРАЩЕНИЯ БОЯ И УНИЧТОЖЕНИЯ В КАРТОННЫХ КОРОБКАХ | BT5: =MIN(1,IFERROR(SEARCH(BT$2,$BS5),0)) -> 0 | BU5: =MIN(1,IFERROR(SEARCH(BU$2,$BS5),0)) -> 1 | BV5: =MAX(BT5,BU5) -> 1 | BW5: ОТСУТСТВУЕТ | BX5: NAGISZ ZRT. | BY5: 330 | CA5: 66000 | CB5: ШТ | CE5: 1 | CF5: 0407191100 | CI5: HU | CJ5: 7260 | CK5: ОООО-ЛП | CL5: 4000000 | CM5: 6930 | CN5: 0 | CQ5: 82500 | CU5: 8590232.3 | CV5: 93787.71 | CW5: 10 | CX5: 13.53 | DB5: 1372
B6: 1 | C6: 30.08.2023 | D6: 8 | E6: 10005030/300823/3232114 | F6: 10005030 | G6: 30.08.2023 | H6: 3232114 | I6: ИМ | J6: 40 | N6: CUDDY FARMS LIMITED 2008 | O6: 28429, ONTARIO, STRATHROY, N7G3H6 CENTRE ROAD RR, | T6: 1 | U6: 543 | V6: 1047796588146 | W6: 7710553010 | X6: ООО "АГРОИМПОРТ" | Y6: 143421, МОСКОВСКАЯ ОБЛ., КРАСНОГОРСКИЙ Р-Н, 26 КМ А/Д "БАЛТИЯ", БЦ "РИГА-ЛЕНД", | Z6: 46000 | AA6: 502401001 | AB6: 1047796588146 | AC6: 7710553010 | AD6: ООО "АГРОИМПОРТ" | AE6: 143421, МОСКОВСКАЯ ОБЛ., КРАСНОГОРСКИЙ Р-Н, 26 КМ А/Д "БАЛТИЯ", БЦ "РИГА-ЛЕНД", | AF6: 46000 | AG6: 502401001 | AH6: CA | AI6: КАНАДА | AJ6: 15620192 | AK6: 1047796588146 | AL6: 7710553010 | AM6: ООО "АГРОИМПОРТ" | AN6: 143421, МОСКОВСКАЯ ОБЛ., КРАСНОГОРСКИЙ Р-Н, 26 КМ А/Д "БАЛТИЯ", БЦ "РИГА-ЛЕНД", | AO6: 46000 | AP6: 502401001 | AQ6: CA | AR6: КАНАДА | AS6: КАНАДА | AT6: RU | AU6: РОССИЯ | AW6: 0 | AX6: CPT | AY6: МОСКВА | BA6: EUR | BB6: 150954 | BE6: 103.4765 | BG6: 40 | BI6: - | BJ6: 11 | BQ6: 10001020 т/п Аэропорт Внуково (грузовой) | BS6: ИНДЮШАЧЬИ ЯЙЦА ДЛЯ ИНКУБАЦИИ. ПОРОДА MELEAGRIS GALLOPAVO L. "БЕЛАЯ ШИРОКОГРУДАЯ" (HCONV), КРОСС ХАЙБРИД КОНВЕРТЕР, КАТЕГОРИЯ БРОЙЛЕР, НЕ ПЛЕМЕННЫЕ, РАЗМЕЩЕНЫ В КАРТОННЫХ КАССЕТАХ ПО ДВАДЦАТЬ (20) ЯИЦ В КАЖДОЙ И УПАКОВАНО В ОРИГИНАЛЬНЫЕ КАРТОННЫЕ | BT6: =MIN(1,IFERROR(SEARCH(BT$2,$BS6),0)) -> 0 | BU6: =MIN(1,IFERROR(SEARCH(BU$2,$BS6),0)) -> 1 | BV6: =MAX(BT6,BU6) -> 1 | BW6: ОТСУТСТВУЕТ | BX6: CUDDY FARMS LIMITED 2008 | BY6: 543 | BZ6: 0 | CA6: 108600 | CB6: ШТ | CE6: 1 | CF6: 0407191100 | CI6: CA | CJ6: 10860 | CK6: ОООО-ЛП | CL6: 4000000 | CM6: 9774 | CN6: 0 | CQ6: 150954 | CS6: 0 | CT6: 1 | CU6: 15620192 | CV6: 163208.45 | CW6: 10 | CX6: 16.7 | DB6: 1069
B7: 1 | C7: 20.08.2023 | D7: 8 | E7: 10005030/200823/3221966 | F7: 10005030 | G7: 20.08.2023 | H7: 3221966 | I7: ИМ | J7: 40 | N7: CUDDY FARMS LIMITED 2008 | O7: , , RR #5-28429 CENTRE ROAD, STRATHROY ON N76 3H6, | T7: 1 | U7: 282 | W7: 263034881 | X7: ООО "СПП" | Y7: 453854, РЕСПУБЛИКА БАШКОРТОСТАН, М.Р-Н МЕЛЕУЗОВСКИЙ, Г.МЕЛЕУЗ, УЛ.СОВХОЗНАЯ, ЗДА | AC7: 263034881 | AD7: ООО "СПП" | AE7: 453854, РЕСПУБЛИКА БАШКОРТОСТАН, М.Р-Н МЕЛЕУЗОВСКИЙ, Г.МЕЛЕУЗ, УЛ.СОВХОЗНАЯ, ЗДА | AH7: CA | AI7: КАНАДА | AJ7: 8756929.4 | AL7: 263034881 | AM7: ООО "СПП" | AN7: 453854, РЕСПУБЛИКА БАШКОРТОСТАН, М.Р-Н МЕЛЕУЗОВСКИЙ, Г.МЕЛЕУЗ, УЛ.СОВХОЗНАЯ, ЗДА | AQ7: CA | AR7: КАНАДА | AS7: КАНАДА | AT7: RU | AU7: РОССИЯ | AW7: 0 | AX7: CPT | AY7: МОСКВА | BA7: EUR | BB7: 86292 | BE7: 101.4802 | BG7: 40 | BI7: - | BJ7: 11 | BQ7: 10001020 т/п Аэропорт Внуково (грузовой) | BS7: ОПЛОДОТВОРЕННЫЕ ЯЙЦА ИНДЮШАЧЬИ ДЛЯ ИНКУБАЦИИ, КОД ОКП 98 4766 (ОКПД2 01.47.23.140): ЦЕЛЬ ВВОЗА - ДЛЯ ИНКУБИРОВАНИЯ. | BT7: =MIN(1,IFERROR(SEARCH(BT$2,$BS7),0)) -> 0 | BU7: =MIN(1,IFERROR(SEARCH(BU$2,$BS7),0)) -> 1 | BV7: =MAX(BT7,BU7) -> 1 | BW7: CUDDY FARMS | BX7: CUDDY FARMS LIMITED 2008 | BY7: 282 | BZ7: 0 | CA7: 56400 | CB7: ШТ | CE7: 1 | CF7: 0407191100 | CI7: CA | CJ7: 5640 | CK7: ОООО-ЛП | CL7: 4000000 | CM7: 5076 | CN7: 0 | CQ7: 86292 | CS7: 0 | CT7: 1 | CU7: 8756929.4 | CV7: 93752.56 | CW7: 10 | CX7: 18.47 | DB7: 473
B8: 1 | C8: 19.08.2023 | D8: 8 | E8: 10005030/190823/3221665 | F8: 10005030 | G8: 19.08.2023 | H8: 3221665 | I8: ИМ | J8: 40 | N8: CUDDY FARMS LIMITED 2008 | O8: N7G3H6, ONTARIO, STRATHROY, 28429 CENTRAL ROAD, R. | T8: 1 | U8: 120 | V8: 1177746508235 | W8: 7751046971 | X8: ООО "ЭГМАРТ" | Y8: 108841, , Г. МОСКВА, Г. ТРОИЦК, УЛ. ТЕКСТИЛЬЩИКОВ, ДОМ 3 КОР. 3, ОФ. 4, | Z8: 45000 | AA8: 775101001 | AB8: 1177746508235 | AC8: 7751046971 | AD8: ООО "ЭГМАРТ" | AE8: 108841, , Г. МОСКВА, Г. ТРОИЦК, УЛ. ТЕКСТИЛЬЩИКОВ, ДОМ 3 КОР. 3, ОФ. 4, | AF8: 45000 | AG8: 775101001 | AH8: CA | AI8: КАНАДА | AJ8: 3701997.7 | AK8: 1177746508235 | AL8: 7751046971 | AM8: ООО "ЭГМАРТ" | AN8: 108841, , Г. МОСКВА, Г. ТРОИЦК, УЛ. ТЕКСТИЛЬЩИКОВ, ДОМ 3 КОР. 3, ОФ. 4, | AO8: 45000 | AP8: 775101001 | AQ8: CA | AR8: КАНАДА | AS8: КАНАДА | AT8: RU | AU8: РОССИЯ | AW8: 0 | AX8: CPT | AY8: Г МОСКВА | BA8: EUR | BB8: 36480 | BE8: 101.4802 | BG8: 40 | BI8: - | BJ8: 11 | BQ8: 10001020 т/п Аэропорт Внуково (грузовой) | BS8: ОПЛОДОТВОРЕННЫЕ ИНКУБАЦИОННЫЕ ЯЙЦА ИНДЕЕК (MELEAGRIS GALLOPAVAL.), ДЛЯ ИНКУБАЦИИ И ВЫВЕДЕНИЯ ИНДЕЕК, ДЛЯ ПОСЛЕДУЮЩЕГО ВЫРАЩИВАНИЯ И УБОЯ НА МЯСО. КРОССА "HYBRID CONVERTER"(БЕЛАЯ ШИРОКОГРУДАЯ), СВЕЖИЕ (В КОРОБКЕ ПО 200 ШТ.): | BT8: =MIN(1,IFERROR(SEARCH(BT$2,$BS8),0)) -> 0 | BU8: =MIN(1,IFERROR(SEARCH(BU$2,$BS8),0)) -> 0 | BV8: =MAX(BT8,BU8) -> 0 | BW8: CUDDY | BX8: CUDDY FARMS LIMITED 2008 | BY8: 120 | BZ8: 0 | CA8: 24000 | CB8: ШТ | CE8: 1 | CF8: 0407191100 | CI8: CA | CJ8: 2510 | CK8: ОООО-ЛП | CL8: 4000000 | CM8: 2160 | CN8: 0 | CQ8: 36480 | CS8: 0 | CT8: 1 | CU8: 3701997.7 | CV8: 39633.96 | CW8: 10 | CX8: 18.35 | DB8: 610
B9: 1 | C9: 19.08.2023 | D9: 8 | E9: 10005030/190823/3221568 | F9: 10005030 | G9: 19.08.2023 | H9: 3221568 | I9: ИМ | J9: 40 | N9: AVIAGEN TURKEYS LTD. | O9: , CHESTER CH3 9GA, TATTENHALL, CHOWLEY OAK BUSINES | T9: 1 | U9: 290 | V9: 1047796588146 | W9: 7710553010 | X9: ООО "АГРОИМПОРТ" | Y9: 143421, МОСКОВСКАЯ ОБЛ., КРАСНОГОРСКИЙ Р-Н, 26 КМ А/Д "БАЛТИЯ", БЦ "РИГА-ЛЕНД", | Z9: 46000 | AA9: 502401001 | AB9: 1047796588146 | AC9: 7710553010 | AD9: ООО "АГРОИМПОРТ" | AE9: 143421, МОСКОВСКАЯ ОБЛ., КРАСНОГОРСКИЙ Р-Н, 26 КМ А/Д "БАЛТИЯ", БЦ "РИГА-ЛЕНД", | AF9: 46000 | AG9: 502401001 | AH9: GB | AI9: СОЕДИНЕННОЕ КОРОЛЕВСТВО | AJ9: 39418969 | AK9: 1047796588146 | AL9: 7710553010 | AM9: ООО "АГРОИМПОРТ" | AN9: 143421, МОСКОВСКАЯ ОБЛ., КРАСНОГОРСКИЙ Р-Н, 26 КМ А/Д "БАЛТИЯ", БЦ "РИГА-ЛЕНД", | AO9: 46000 | AP9: 502401001 | AQ9: GB | AR9: СОЕДИНЕННОЕ КОРОЛЕВСТВО | AS9: СОЕДИНЕННОЕ КОРОЛЕВСТВО | AT9: RU | AU9: РОССИЯ | AW9: 0 | AX9: DAP | AY9: МОСКВА | BA9: EUR | BB9: 388440 | BE9: 101.4802 | BG9: 40 | BI9: - | BJ9: 11 | BQ9: 10001020 т/п Аэропорт Внуково (грузовой) | BS9: ПЛЕМЕННЫЕ ИНДЮШАЧЬИ ЯЙЦА ДЛЯ ИНКУБАЦИИ, ОПЛОДОТВОРЁННЫЕ, ДЛЯ ВЫВЕДЕНИЯ РОДИТЕЛЬСКОГО СТАДА MELEAGRIS GALLOPAVO L. ПОРОДЫ БЕЛАЯ ШИРОКОГРУДАЯ BIG 6, РАЗМЕЩЕННЫЕ С ЦЕЛЬЮ ПРЕДОТВРАЩЕНИЯ БОЯ И УНИЧТОЖЕНИЯ В КАРТОННЫХ КОРОБКАХ. | BT9: =MIN(1,IFERROR(SEARCH(BT$2,$BS9),0)) -> 0 | BU9: =MIN(1,IFERROR(SEARCH(BU$2,$BS9),0)) -> 1 | BV9: =MAX(BT9,BU9) -> 1 | BW9: ... | BX9: AVIAGEN TURKEYS INC. | BY9: 290 | BZ9: 0 | CA9: 58000 | CB9: ШТ | CE9: 1 | CF9: 0407191100 | CI9: GB | CJ9: 6090 | CK9: ОООО-ПС | CL9: 4000000 | CM9: 5800 | CN9: 0 | CQ9: 388440 | CS9: 0 | CT9: 1 | CU9: 39418969 | CV9: 422023.4 | CW9: 10 | CX9: 72.76 | DB9: 678
B10: 1 | C10: 19.08.2023 | D10: 8 | E10: 10005030/190823/3221529 | F10: 10005030 | G10: 19.08.2023 | H10: 3221529 | I10: ИМ | J10: 40 | N10: CUDDY FARMS, A DIVISION OF HENDRIX GENETICS LIMITED | O10: N7G3H6, ONTARIO, STRATHROY, ROUTE # 5, | T10: 1 | U10: 120 | V10: 1132651023570 | W10: 2624801566 | X10: ООО "ПТИЧИЙ ДВОР" | Y10: 356800, СТАВРОПОЛЬСКИЙ КРАЙ, Г. БУДЕННОВСК, УЛ. ВОДНИКОВ, Д.7, | Z10: 07000 | AA10: 262401001 | AB10: 1132651023570 | AC10: 2624801566 | AD10: ООО "ПТИЧИЙ ДВОР" | AE10: 356800, СТАВРОПОЛЬСКИЙ КРАЙ, Г. БУДЕННОВСК, УЛ. ВОДНИКОВ, Д.7, | AF10: 07000 | AG10: 262401001 | AH10: CA | AI10: КАНАДА | AJ10: 3701997.7 | AK10: 1132651023570 | AL10: 2624801566 | AM10: ООО "ПТИЧИЙ ДВОР" | AN10: 356800, СТАВРОПОЛЬСКИЙ КРАЙ, Г. БУДЕННОВСК, УЛ. ВОДНИКОВ, Д.7, | AO10: 07000 | AP10: 262401001 | AQ10: CA | AR10: КАНАДА | AS10: КАНАДА | AT10: RU | AU10: РОССИЯ | AW10: 0 | AX10: CPT | AY10: МОСКВА | BA10: EUR | BB10: 36480 | BE10: 101.4802 | BG10: 40 | BI10: - | BJ10: 11 | BQ10: 10001020 т/п Аэропорт Внуково (грузовой) | BS10: СВЕЖИЕ ОПЛОДОТВОРЕННЫЕ ИНКУБАЦИОННЫЕ ЯЙЦА ИНДЕЙКИ (TURKEY HATCHING EGGS), ЛАТИНСКОЕ НАЗВАНИЕ ВИДА "MELEAGRIS GALLOPAVO L." ПОРОДЫ ХАЙБРИД КОНВЕРТЕР, ДЛЯ ИНКУБАЦИИ, ДЛЯ ПОСЛЕДУЮЩЕГО ВЫРАЩИВАНИЯ И УБОЯ НА МЯСО | BT10: =MIN(1,IFERROR(SEARCH(BT$2,$BS10),0)) -> 1 | BU10: =MIN(1,IFERROR(SEARCH(BU$2,$BS10),0)) -> 0 | BV10: =MAX(BT10,BU10) -> 1 | BW10: ОТСУТСТВУЕТ | BX10: CUDDY FARMS LIMITED 2008, ПЛЕМЗАВОД: KRS0000042053 | BY10: 120 | BZ10: 0 | CA10: 24000 | CB10: ШТ | CE10: 1 | CF10: 0407191100 | CI10: CA | CJ10: 2400 | CK10: ОООО-ЛП | CL10: 4000000 | CM10: 2160 | CN10: 0 | CQ10: 36480 | CS10: 0 | CT10: 1 | CU10: 3701997.7 | CV10: 39633.96 | CW10: 10 | CX10: 18.35 | DB10: 636
B11: 1 | C11: 17.08.2023 | D11: 8 | E11: 10005030/170823/3220327 | F11: 10005030 | G11: 17.08.2023 | H11: 3220327 | I11: ИМ | J11: 40 | N11: CUDDY FARMS LIMITED 2008 | O11: , , RR #5-28429 CENTRE ROAD, STRATHROY ON N76 3H6, | T11: 1 | U11: 423 | W11: 263034881 | X11: ООО "СПП" | Y11: 453854, РЕСПУБЛИКА БАШКОРТОСТАН, М.Р-Н МЕЛЕУЗОВСКИЙ, Г.МЕЛЕУЗ, УЛ.СОВХОЗНАЯ, ЗДА | AC11: 263034881 | AD11: ООО "СПП" | AE11: 453854, РЕСПУБЛИКА БАШКОРТОСТАН, М.Р-Н МЕЛЕУЗОВСКИЙ, Г.МЕЛЕУЗ, УЛ.СОВХОЗНАЯ, ЗДА | AH11: CA | AI11: КАНАДА | AJ11: 13676303 | AL11: 263034881 | AM11: ООО "СПП" | AN11: 453854, РЕСПУБЛИКА БАШКОРТОСТАН, М.Р-Н МЕЛЕУЗОВСКИЙ, Г.МЕЛЕУЗ, УЛ.СОВХОЗНАЯ, ЗДА | AQ11: CA | AR11: КАНАДА | AS11: КАНАДА | AT11: RU | AU11: РОССИЯ | AW11: 0 | AX11: CPT | AY11: МОСКВА | BA11: EUR | BB11: 129438 | BE11: 105.6591 | BG11: 40 | BI11: - | BJ11: 11 | BQ11: 10001020 т/п Аэропорт Внуково (грузовой) | BS11: ОПЛОДОТВОРЕННЫЕ ЯЙЦА ИНДЮШАЧЬИ ДЛЯ ИНКУБАЦИИ, КОД ОКП 98 4766 (ОКПД2 01.47.23.140): ЦЕЛЬ ВВОЗА - ДЛЯ ИНКУБИРОВАНИЯ. | BT11: =MIN(1,IFERROR(SEARCH(BT$2,$BS11),0)) -> 0 | BU11: =MIN(1,IFERROR(SEARCH(BU$2,$BS11),0)) -> 1 | BV11: =MAX(BT11,BU11) -> 1 | BW11: CUDDY FARMS | BX11: CUDDY FARMS LIMITED 2008 | BY11: 423 | BZ11: 0 | CA11: 84600 | CB11: ШТ | CE11: 1 | CF11: 0407191100 | CI11: CA | CJ11: 8460 | CK11: ОООО-ЛП | CL11: 4000000 | CM11: 7614 | CN11: 0 | CQ11: 129438 | CS11: 0 | CT11: 1 | CU11: 13676303 | CV11: 141423.64 | CW11: 10 | CX11: 18.57 | DB11: 953
B12: 1 | C12: 14.08.2023 | D12: 8 | E12: 10005030/140823/3216844 | F12: 10005030 | G12: 14.08.2023 | H12: 3216844 | I12: ИМ | J12: 40 | N12: CUDDY FARMS LIMITED 2008 | O12: 28429, ONTARIO, STRATHROY, N7G3H6 CENTRE ROAD RR, | T12: 1 | U12: 362 | V12: 1047796588146 | W12: 7710553010 | X12: ООО "АГРОИМПОРТ" | Y12: 143421, МОСКОВСКАЯ ОБЛ., КРАСНОГОРСКИЙ Р-Н, 26 КМ А/Д "БАЛТИЯ", БЦ "РИГА-ЛЕНД", | Z12: 46000 | AA12: 502401001 | AB12: 1047796588146 | AC12: 7710553010 | AD12: ООО "АГРОИМПОРТ" | AE12: 143421, МОСКОВСКАЯ ОБЛ., КРАСНОГОРСКИЙ Р-Н, 26 КМ А/Д "БАЛТИЯ", БЦ "РИГА-ЛЕНД", | AF12: 46000 | AG12: 502401001 | AH12: CA | AI12: КАНАДА | AJ12: 10865900 | AK12: 1047796588146 | AL12: 7710553010 | AM12: ООО "АГРОИМПОРТ" | AN12: 143421, МОСКОВСКАЯ ОБЛ., КРАСНОГОРСКИЙ Р-Н, 26 КМ А/Д "БАЛТИЯ", БЦ "РИГА-ЛЕНД", | AO12: 46000 | AP12: 502401001 | AQ12: CA | AR12: КАНАДА | AS12: КАНАДА | AT12: RU | AU12: РОССИЯ | AW12: 0 | AX12: CPT | AY12: МОСКВА | BA12: EUR | BB12: 100636 | BE12: 107.9723 | BG12: 40 | BI12: - | BJ12: 11 | BQ12: 10001020 т/п Аэропорт Внуково (грузовой) | BS12: ИНДЮШАЧЬИ ЯЙЦА ДЛЯ ИНКУБАЦИИ, ПОРОДА MELEAGRIS GALLOPAVO L. "БЕЛАЯ ШИРОКОГРУДАЯ" (HCONV), КРОСС ХАЙБРИД КОНВЕРТЕР. КАТЕГОРИЯ БРОЙЛЕР, НЕ ПЛЕМЕННЫЕ, РАЗМЕЩЕНЫ В КАРТОННЫХ КАССЕТАХ ПО ДВАДЦАТЬ (20) ЯИЦ В КАЖДОЙ И УПАКОВАНО В ОРИГИНАЛЬНЫЕ КАРТОННЫЕ | BT12: =MIN(1,IFERROR(SEARCH(BT$2,$BS12),0)) -> 0 | BU12: =MIN(1,IFERROR(SEARCH(BU$2,$BS12),0)) -> 1 | BV12: =MAX(BT12,BU12) -> 1 | BW12: ОТСУТСТВУЕТ | BX12: CUDDY FARMS LIMITED 2008 | BY12: 362 | BZ12: 0 | CA12: 72400 | CB12: ШТ | CE12: 1 | CF12: 0407191100 | CI12: CA | CJ12: 7432 | CK12: ОООО-ЛП | CL12: 4000000 | CM12: 6516 | CN12: 0 | CQ12: 100636 | CS12: 0 | CT12: 1 | CU12: 10865900 | CV12: 110643.28 | CW12: 10 | CX12: 16.98 | DB12: 993
B13: 1 | C13: 13.08.2023 | D13: 8 | E13: 10005030/130823/3215662 | F13: 10005030 | G13: 13.08.2023 | H13: 3215662 | I13: ИМ | J13: 40 | N13: CUDDY FARMS LIMITED 2008 | O13: , , RR #5-28429 CENTRE ROAD, STRATHROY ON N76 3H6, | T13: 1 | U13: 160 | V13: 1144813001046 | W13: 4805016071 | X13: ООО "КРИВЕЦ-ПТИЦА" | Y13: 399174, ЛИПЕЦКАЯ ОБЛ., ДОБРОВСКИЙ РАЙОН, СЕЛО КРИВЕЦ, УЛ. НОВАЯ, Д.2, ПОМЕЩЕНИЕ | Z13: 42000 | AA13: 480501001 | AB13: 1144813001046 | AC13: 4805016071 | AD13: ООО "КРИВЕЦ-ПТИЦА" | AE13: 399174, ЛИПЕЦКАЯ ОБЛ., ДОБРОВСКИЙ РАЙОН, СЕЛО КРИВЕЦ, УЛ. НОВАЯ, Д.2, ПОМЕЩЕНИЕ | AF13: 42000 | AG13: 480501001 | AH13: CA | AI13: КАНАДА | AJ13: 5182670.4 | AK13: 1144813001046 | AL13: 4805016071 | AM13: ООО "КРИВЕЦ-ПТИЦА" | AN13: 399174, ЛИПЕЦКАЯ ОБЛ., ДОБРОВСКИЙ РАЙОН, СЕЛО КРИВЕЦ, УЛ. НОВАЯ, Д.2, ПОМЕЩЕНИЕ | AO13: 42000 | AP13: 480501001 | AQ13: CA | AR13: КАНАДА | AS13: КАНАДА | AT13: RU | AU13: РОССИЯ | AW13: 0 | AX13: CPT | AY13: МОСКВА | BA13: EUR | BB13: 48000 | BE13: 107.9723 | BG13: 40 | BI13: - | BJ13: 11 | BQ13: 10001020 т/п Аэропорт Внуково (грузовой) | BS13: ОПЛОДОТВОРЕННЫЕ ЯЙЦА ИНДЮШАЧЬИ ДЛЯ ИНКУБАЦИИ, КОД ОКП 98 4766 (ОКПД2 01.47.23.140): ЦЕЛЬ ВВОЗА: ИНКУБИРОВАНИЕ И ДАЛЬНЕЙШЕЕ ВЫРАЩИВАНИЕ. | BT13: =MIN(1,IFERROR(SEARCH(BT$2,$BS13),0)) -> 0 | BU13: =MIN(1,IFERROR(SEARCH(BU$2,$BS13),0)) -> 1 | BV13: =MAX(BT13,BU13) -> 1 | BW13: CUDDY FARMS | BX13: CUDDY FARMS LIMITED 2008 | BY13: 160 | BZ13: 0 | CA13: 32000 | CB13: ШТ | CE13: 1 | CF13: 0407191100 | CI13: CA | CJ13: 3200 | CK13: ОООО-ЛП | CL13: 4000000 | CM13: 2880 | CN13: 0 | CQ13: 48000 | CS13: 0 | CT13: 1 | CU13: 5182670.4 | CV13: 52773.14 | CW13: 10 | CX13: 18.32 | DB13: 724
B14: 1 | C14: 12.08.2023 | D14: 8 | E14: 10005030/120823/3215350 | F14: 10005030 | G14: 12.08.2023 | H14: 3215350 | I14: ИМ | J14: 40 | N14: CUDDY FARMS A DIVISION OF HENDRIX GENETICS LTD | O14: N7G 3H6, ONTARIO, STRATHROY, CENTRE ROAD, RR#5, 28 | T14: 1 | U14: 380 | V14: 1116829006910 | W14: 6829076796 | X14: ООО "ТАМБОВСКАЯ ИНДЕЙКА" | Y14: 392000, ТАМБОВСКАЯ ОБЛ., ТАМБОВ, УЛ. СТУДЕНЕЦКАЯ, Д.16А, КОРП.1, ПОМ.16 | Z14: 68000 | AA14: 682901001 | AB14: 1116829006910 | AC14: 6829076796 | AD14: ООО "ТАМБОВСКАЯ ИНДЕЙКА" | AE14: 392000, ТАМБОВСКАЯ ОБЛ., ТАМБОВ, УЛ. СТУДЕНЕЦКАЯ, Д.16А, КОРП.1, ПОМ.16 | AF14: 68000 | AG14: 682901001 | AH14: CA | AI14: КАНАДА | AJ14: 12965314 | AK14: 1116829006910 | AL14: 6829076796 | AM14: ООО "ТАМБОВСКАЯ ИНДЕЙКА" | AN14: 392000, ТАМБОВСКАЯ ОБЛ., ТАМБОВ, УЛ. СТУДЕНЕЦКАЯ, Д.16А, КОРП.1, ПОМ.16 | AO14: 68000 | AP14: 682901001 | AQ14: CA | AR14: КАНАДА | AS14: КАНАДА | AT14: RU | AU14: РОССИЯ | AW14: 0 | AX14: CPT | AY14: МОСКВА | BA14: EUR | BB14: 120080 | BE14: 107.9723 | BG14: 40 | BI14: - | BJ14: 11 | BQ14: 10001020 т/п Аэропорт Внуково (грузовой) | BS14: ЯЙЦА ИНДЕЕК ДОМАШНИХ. СВЕЖИЕ, ОПЛОДОТВОРЕННЫЕ ДЛЯ ИНКУБАЦИИ, ПОРОДЫ HYBRID CONVERTER, НЕ ПЛЕМЕННЫЕ, ДЛЯ ПОСЛЕДУЮЩЕГО ВЫРАЩИВАНИЯ И УБОЯ НА МЯСО СВЕЖЕЕ, В КАРТОННЫХ КОРОБКАХ | BT14: =MIN(1,IFERROR(SEARCH(BT$2,$BS14),0)) -> 0 | BU14: =MIN(1,IFERROR(SEARCH(BU$2,$BS14),0)) -> 0 | BV14: =MAX(BT14,BU14) -> 0 | BW14: CUDDY | BX14: CUDDY FARMS | BY14: 380 | BZ14: 0 | CA14: 76000 | CB14: ШТ | CE14: 1 | CF14: 0407191100 | CI14: CA | CJ14: 7790 | CK14: ОООО-ЛП | CL14: 4000000 | CM14: 6840 | CN14: 0 | CQ14: 120080 | CS14: 0 | CT14: 1 | CU14: 12965314 | CV14: 132020.8 | CW14: 10 | CX14: 19.3 | DB14: 786
B15: 1 | C15: 12.08.2023 | D15: 8 | E15: 10005030/120823/3215210 | F15: 10005030 | G15: 12.08.2023 | H15: 3215210 | I15: ИМ | J15: 40 | N15: AVIAGEN TURKEYS LTD. | O15: , CHESTER CH3 9GA, TATTENHALL, CHOWLEY OAK BUSINES | T15: 1 | U15: 223 | V15: 1047796588146 | W15: 7710553010 | X15: ООО "АГРОИМПОРТ" | Y15: 143421, МОСКОВСКАЯ ОБЛ., КРАСНОГОРСКИЙ Р-Н, 26 КМ А/Д "БАЛТИЯ", БЦ "РИГА-ЛЕНД", | Z15: 46000 | AA15: 502401001 | AB15: 1047796588146 | AC15: 7710553010 | AD15: ООО "АГРОИМПОРТ" | AE15: 143421, МОСКОВСКАЯ ОБЛ., КРАСНОГОРСКИЙ Р-Н, 26 КМ А/Д "БАЛТИЯ", БЦ "РИГА-ЛЕНД", | AF15: 46000 | AG15: 502401001 | AH15: GB | AI15: СОЕДИНЕННОЕ КОРОЛЕВСТВО | AJ15: 32250030 | AK15: 1047796588146 | AL15: 7710553010 | AM15: ООО "АГРОИМПОРТ" | AN15: 143421, МОСКОВСКАЯ ОБЛ., КРАСНОГОРСКИЙ Р-Н, 26 КМ А/Д "БАЛТИЯ", БЦ "РИГА-ЛЕНД", | AO15: 46000 | AP15: 502401001 | AQ15: GB | AR15: СОЕДИНЕННОЕ КОРОЛЕВСТВО | AS15: СОЕДИНЕННОЕ КОРОЛЕВСТВО | AT15: RU | AU15: РОССИЯ | AW15: 0 | AX15: DAP | AY15: МОСКВА | BA15: EUR | BB15: 298688 | BE15: 107.9723 | BG15: 40 | BI15: - | BJ15: 11 | BQ15: 10001020 т/п Аэропорт Внуково (грузовой) | BS15: ПЛЕМЕННЫЕ ИНДЮШАЧЬИ ЯЙЦА ДЛЯ ИНКУБАЦИИ, ОПЛОДОТВОРЁННЫЕ, ДЛЯ ВЫВЕДЕНИЯ РОДИТЕЛЬСКОГО СТАДА MELEAGRIS GALLOPAVO L. ПОРОДЫ БЕЛАЯ ШИРОКОГРУДАЯ BIG 6, РАЗМЕЩЕННЫЕ С ЦЕЛЬЮ ПРЕДОТВРАЩЕНИЯ БОЯ И УНИЧТОЖЕНИЯ В КАРТОННЫХ КОРОБКАХ. | BT15: =MIN(1,IFERROR(SEARCH(BT$2,$BS15),0)) -> 0 | BU15: =MIN(1,IFERROR(SEARCH(BU$2,$BS15),0)) -> 1 | BV15: =MAX(BT15,BU15) -> 1 | BW15: ... | BX15: AVIAGEN TURKEYS INC. | BY15: 223 | BZ15: 0 | CA15: 44600 | CB15: ШТ | CE15: 1 | CF15: 0407191100 | CI15: GB | CJ15: 4683 | CK15: ОООО-ПС | CL15: 4000000 | CM15: 4460 | CN15: 0 | CQ15: 298688 | CS15: 0 | CT15: 1 | CU15: 32250030 | CV15: 328389.64 | CW15: 10 | CX15: 73.63 | DB15: 473
B16: 1 | C16: 10.08.2023 | D16: 8 | E16: 10005030/100823/3213832 | F16: 10005030 | G16: 10.08.2023 | H16: 3213832 | I16: ИМ | J16: 40 | N16: CUDDY FARMS A DIVISION OF HENDRIX GENETICS LTD | O16: N7G 3H6, ONTARIO, STRATHROY, CENTRE ROAD, RR#5, 28 | T16: 1 | U16: 380 | V16: 1116829006910 | W16: 6829076796 | X16: ООО "ТАМБОВСКАЯ ИНДЕЙКА" | Y16: 392000, ТАМБОВСКАЯ ОБЛ., ТАМБОВ, УЛ. СТУДЕНЕЦКАЯ, Д.16А, КОРП.1, ПОМ.16 | Z16: 68000 | AA16: 682901001 | AB16: 1116829006910 | AC16: 6829076796 | AD16: ООО "ТАМБОВСКАЯ ИНДЕЙКА" | AE16: 392000, ТАМБОВСКАЯ ОБЛ., ТАМБОВ, УЛ. СТУДЕНЕЦКАЯ, Д.16А, КОРП.1, ПОМ.16 | AF16: 68000 | AG16: 682901001 | AH16: CA | AI16: КАНАДА | AJ16: 12835315 | AK16: 1116829006910 | AL16: 6829076796 | AM16: ООО "ТАМБОВСКАЯ ИНДЕЙКА" | AN16: 392000, ТАМБОВСКАЯ ОБЛ., ТАМБОВ, УЛ. СТУДЕНЕЦКАЯ, Д.16А, КОРП.1, ПОМ.16 | AO16: 68000 | AP16: 682901001 | AQ16: CA | AR16: КАНАДА | AS16: КАНАДА | AT16: RU | AU16: РОССИЯ | AW16: 0 | AX16: CPT | AY16: МОСКВА | BA16: EUR | BB16: 120080 | BE16: 106.8897 | BG16: 40 | BI16: - | BJ16: 11 | BQ16: 10001020 т/п Аэропорт Внуково (грузовой) | BS16: ЯЙЦА ИНДЕЕК ДОМАШНИХ. СВЕЖИЕ, ОПЛОДОТВОРЕННЫЕ ДЛЯ ИНКУБАЦИИ, ПОРОДЫ HYBRID CONVERTER, НЕ ПЛЕМЕННЫЕ, ДЛЯ ПОСЛЕДУЮЩЕГО ВЫРАЩИВАНИЯ И УБОЯ НА МЯСО СВЕЖЕЕ, В КАРТОННЫХ КОРОБКАХ | BT16: =MIN(1,IFERROR(SEARCH(BT$2,$BS16),0)) -> 0 | BU16: =MIN(1,IFERROR(SEARCH(BU$2,$BS16),0)) -> 0 | BV16: =MAX(BT16,BU16) -> 0 | BW16: CUDDY | BX16: CUDDY FARMS | BY16: 380 | BZ16: 0 | CA16: 76000 | CB16: ШТ | CE16: 1 | CF16: 0407191100 | CJ16: 7600 | CK16: ОООО-ЛП | CL16: 4000000 | CM16: 6840 | CN16: 0 | CQ16: 120080 | CS16: 0 | CT16: 1 | CU16: 12835315 | CV16: 131779.55 | CW16: 10 | CX16: 19.27 | DB16: 708
B17: 1 | C17: 05.08.2023 | D17: 8 | E17: 10005030/050823/5009453 | F17: 10005030 | G17: 05.08.2023 | H17: 5009453 | I17: ИМ | J17: 40 | N17: CUDDY FARMS LIMITED 2008 | O17: N7G3H6, ONTARIO, STRATHROY, 28429 CENTRAL ROAD, R. | T17: 1 | U17: 120 | V17: 1177746508235 | W17: 7751046971 | X17: ООО "ЭГМАРТ" | Y17: 108841, , Г. МОСКВА, Г. ТРОИЦК, УЛ. ТЕКСТИЛЬЩИКОВ, ДОМ 3 КОР. 3, ОФ. 4, | Z17: 45000 | AA17: 775101001 | AB17: 1177746508235 | AC17: 7751046971 | AD17: ООО "ЭГМАРТ" | AE17: 108841, , Г. МОСКВА, Г. ТРОИЦК, УЛ. ТЕКСТИЛЬЩИКОВ, ДОМ 3 КОР. 3, ОФ. 4, | AF17: 45000 | AG17: 775101001 | AH17: CA | AI17: КАНАДА | AJ17: 3788006.6 | AK17: 1177746508235 | AL17: 7751046971 | AM17: ООО "ЭГМАРТ" | AN17: 108841, , Г. МОСКВА, Г. ТРОИЦК, УЛ. ТЕКСТИЛЬЩИКОВ, ДОМ 3 КОР. 3, ОФ. 4, | AO17: 45000 | AP17: 775101001 | AQ17: CA | AR17: КАНАДА | AS17: КАНАДА | AT17: RU | AU17: РОССИЯ | AW17: 0 | AX17: CPT | AY17: Г МОСКВА | BA17: EUR | BB17: 36480 | BE17: 103.8379 | BG17: 40 | BI17: - | BJ17: СВ | BQ17: 10001020 т/п Аэропорт Внуково (грузовой) | BS17: ОПЛОДОТВОРЕННЫЕ ИНКУБАЦИОННЫЕ ЯЙЦА ИНДЕЕК (MELEAGRIS GALLOPAVAL.). ДЛЯ ИНКУБАЦИИ И ВЫВЕДЕНИЯ ИНДЕЕК, ДЛЯ ПОСЛЕДУЮЩЕГО ВЫРАЩИВАНИЯ И УБОЯ НА МЯСО, КРОССА "HYBRID CONVERTER"(БЕЛАЯ ШИРОКОГРУДАЯ), СВЕЖИЕ (В КОРОБКЕ ПО 200 ШТ.): | BT17: =MIN(1,IFERROR(SEARCH(BT$2,$BS17),0)) -> 0 | BU17: =MIN(1,IFERROR(SEARCH(BU$2,$BS17),0)) -> 0 | BV17: =MAX(BT17,BU17) -> 0 | BW17: CUDDY | BX17: CUDDY FARMS LIMITED 2008 | BY17: 120 | CA17: 24000 | CB17: ШТ | CE17: 1 | CF17: 0407191100 | CI17: CA | CJ17: 2502 | CK17: ОООО-ЛП | CL17: 4000000 | CM17: 2160 | CN17: 0 | CQ17: 36480 | CU17: 3788006.6 | CV17: 39954.67 | CW17: 10 | CX17: 18.5 | DB17: 789
B18: 1 | C18: 05.08.2023 | D18: 8 | E18: 10005030/050823/3208921 | F18: 10005030 | G18: 05.08.2023 | H18: 3208921 | I18: ИМ | J18: 40 | N18: CUDDY FARMS, A DIVISION OF HENDRIX GENETICS LIMITED | O18: 28429, ONTARIO, STRATHROY N7G 3H6, ROUTE #5, | T18: 1 | U18: 55 | V18: 1193668026507 | W18: 3613005236 | X18: ООО "ДОНСКАЯ ИНДЕЙКА" | Y18: 396347, ВОРОНЕЖСКАЯ ОБЛАСТЬ, М.Р-Н КАШИРСКИЙ, С.П. ДЗЕРЖИНСКОЕ, П.ИМ.ДЗЕРЖИНСКОГ | Z18: 20000 | AA18: 361301001 | AB18: 1193668026507 | AC18: 3613005236 | AD18: ООО "ДОНСКАЯ ИНДЕЙКА" | AE18: 396347, ВОРОНЕЖСКАЯ ОБЛАСТЬ, М.Р-Н КАШИРСКИЙ, С.П. ДЗЕРЖИНСКОЕ, П.ИМ.ДЗЕРЖИНСКОГ | AF18: 20000 | AG18: 361301001 | AH18: CA | AI18: КАНАДА | AJ18: 1770436.2 | AK18: 1193668026507 | AL18: 3613005236 | AM18: ООО "ДОНСКАЯ ИНДЕЙКА" | AN18: 396347, ВОРОНЕЖСКАЯ ОБЛАСТЬ, М.Р-Н КАШИРСКИЙ, С.П. ДЗЕРЖИНСКОЕ, П.ИМ.ДЗЕРЖИНСКОГ | AO18: 20000 | AP18: 361301001 | AQ18: CA | AR18: КАНАДА | AS18: КАНАДА | AT18: RU | AU18: РОССИЯ | AW18: 0 | AX18: CPT | AY18: МОСКВА | BA18: EUR | BB18: 17050 | BE18: 103.8379 | BG18: 40 | BI18: - | BJ18: СВ | BQ18: 10001020 т/п Аэропорт Внуково (грузовой) | BS18: ОПЛОДОТВОРЕННЫЕ ЯЙЦА ИНДЮШАЧЬИ ДЛЯ ИНКУБАЦИИ, КОД ОКП 98 4766 (ОКПД2 01.47.23.140): | BT18: =MIN(1,IFERROR(SEARCH(BT$2,$BS18),0)) -> 0 | BU18: =MIN(1,IFERROR(SEARCH(BU$2,$BS18),0)) -> 1 | BV18: =MAX(BT18,BU18) -> 1 | BW18: CUDDY FARMS | BX18: CUDDY FARMS LIMITED 2008 | BY18: 55 | CA18: 11000 | CB18: ШТ | CE18: 1 | CF18: 0407191100 | CI18: CA | CJ18: 1158 | CK18: ОООО-ЛП | CL18: 4000000 | CM18: 990 | CN18: 0 | CQ18: 17050 | CU18: 1770436.2 | CV18: 18673.99 | CW18: 10 | CX18: 18.86 | DB18: 1146
B19: 1 | C19: 07.08.2023 | D19: 8 | E19: 10805010/070823/5003781 | F19: 10805010 | G19: 07.08.2023 | H19: 5003781 | I19: ИМ | J19: 40 | N19: PARTIZ 2000 KFT. | O19: 5540, , SZARVAS, RACOKZI U.6/1, | T19: 1 | U19: 125 | V19: 1132651023570 | W19: 2624801566 | X19: ООО "ПТИЧИЙ ДВОР" | Y19: 356800, СТАВРОПОЛЬСКИЙ КРАЙ, Г. БУДЕННОВСК, УЛ. ВОДНИКОВ, Д.7, | Z19: 07000 | AA19: 262401001 | AB19: 1132651023570 | AC19: 2624801566 | AD19: ООО "ПТИЧИЙ ДВОР" | AE19: 356800, СТАВРОПОЛЬСКИЙ КРАЙ, Г. БУДЕННОВСК, УЛ. ВОДНИКОВ, Д.7, | AF19: 07000 | AG19: 262401001 | AH19: HU | AI19: ВЕНГРИЯ | AJ19: 3608367 | AK19: 1132651023570 | AL19: 2624801566 | AM19: ООО "ПТИЧИЙ ДВОР" | AN19: 356800, СТАВРОПОЛЬСКИЙ КРАЙ, Г. БУДЕННОВСК, УЛ. ВОДНИКОВ, Д.7, | AO19: 07000 | AP19: 262401001 | AQ19: HU | AR19: ВЕНГРИЯ | AS19: ВЕНГРИЯ | AT19: RU | AU19: РОССИЯ | AW19: 0 | AX19: FCA | AY19: SZARVAS | BA19: EUR | BB19: 33750 | BE19: 103.8379 | BI19: - | BJ19: 99 | BQ19: 10113100 т/п Стабнинский | BS19: ОПЛОДОТВОРЕННЫЕ НЕПЛЕМЕННЫЕ ИНКУБАЦИОННЫЕ ЯЙЦА ИНДЕЙКИ (TURKEY HATCHING EGGS), ДЛЯ ИНКУБАЦИИ, ДЛЯ ПОСЛЕДУЮЩЕГО ВЫРАЩИВАНИЯ И УБОЯ НА МЯСО, СВЕЖИЕ, ПО 200 ШТ В КОРОБКЕ. | BT19: =MIN(1,IFERROR(SEARCH(BT$2,$BS19),0)) -> 1 | BU19: =MIN(1,IFERROR(SEARCH(BU$2,$BS19),0)) -> 0 | BV19: =MAX(BT19,BU19) -> 1 | BW19: PARTIZ 2000 | BX19: GALLI-EGGS KFT., ПЛЕМЗАВОД HU1009994 | BY19: 125 | CA19: 25000 | CB19: ШТ | CE19: 1 | CF19: 0407191100 | CI19: HU | CJ19: 2625 | CK19: ОООО-ЛП | CL19: 4000000 | CM19: 2500 | CQ19: 33750 | CS19: 0 | CT19: 1 | CU19: 3608367 | CV19: 38059.89 | CW19: 10 | CX19: 15.22 | DB19: 26
B20: 1 | C20: 31.08.2023 | D20: 8 | E20: 10131010/310823/3299352 | F20: 10131010 | G20: 31.08.2023 | H20: 3299352 | I20: ИМ | J20: 40 | N20: MOORGUT KARTZFEHN TURKEY BREEDER GMBH | O20: 26219, ., BOSEL, KARTZ-VON-KAMEKE-ALLEE, 7 | R20: 1 | T20: 1 | U20: 753 | W20: 6829076796 | X20: ООО "ТАМБОВСКАЯ ИНДЕЙКА" | Y20: 392000, ТАМБОВСКАЯ ОБЛ., ТАМБОВ, УЛ. СТУДЕНЕЦКАЯ, Д.16А, КОРП.1, ПОМ.16 | Z20: 68000 | AC20: 6829076796 | AD20: ООО "ТАМБОВСКАЯ ИНДЕЙКА" | AE20: 392000, ТАМБОВСКАЯ ОБЛ., ТАМБОВ, УЛ. СТУДЕНЕЦКАЯ, Д.16А, КОРП.1, ПОМ.16 | AF20: 68000 | AH20: DE | AI20: ГЕРМАНИЯ | AJ20: 29371019 | AL20: 6829076796 | AM20: ООО "ТАМБОВСКАЯ ИНДЕЙКА" | AN20: 392000, ТАМБОВСКАЯ ОБЛ., ТАМБОВ, УЛ. СТУДЕНЕЦКАЯ, Д.16А, КОРП.1, ПОМ.16 | AO20: 68000 | AQ20: DE | AR20: ГЕРМАНИЯ | AS20: ГЕРМАНИЯ | AT20: RU | AU20: РОССИЯ | AV20: 2 | AW20: 0 | AX20: DAP | AY20: ТАМБОВ | BA20: EUR | BB20: 281198 | BE20: 104.4496 | BG20: 31 | BH20: 22121027/3292/0000/2/1 | BI20: 11209103-11209103 | BJ20: 11 | BN20: БРЯНСКАЯ ОБЛ. | BO20: Г.НОВОЗЫБКОВ | BP20: УЛ.РОС | BQ20: 10102073 ОТО и ТК №3 т/п Новозыбковский | BS20: ЯЙЦА ИНДЕЕК ДОМАШНИХ, СВЕЖИЕ, ОПЛОДОТВОРЕННЫЕ ДЛЯ ИНКУБАЦИИ, ПОРОДЫ BUT BIG-6 (WHITE WIDE CASE), НЕ ПЛЕМЕННЫЕ, ДЛЯ ПОСЛЕДУЮЩЕГО ВЫРАЩИВАНИЯ И УБОЯ НА МЯСО СВЕЖЕЕ, В КАРТОННЫХ КОРОБКАХ | BT20: =MIN(1,IFERROR(SEARCH(BT$2,$BS20),0)) -> 0 | BU20: =MIN(1,IFERROR(SEARCH(BU$2,$BS20),0)) -> 0 | BV20: =MAX(BT20,BU20) -> 0 | BW20: KARTZFEHN | BX20: KARTZFEHN MARKISCHE PUTEN GMBH | BY20: 753 | BZ20: 0 | CA20: 150600 | CB20: ШТ | CC20: 0 | CE20: 1 | CF20: 0407191100 | CI20: DE | CJ20: 16566 | CK20: ОООО-ЛП | CL20: 4000000 | CM20: 15060 | CN20: 0 | CQ20: 281198 | CS20: 0 | CT20: 1 | CU20: 29371019 | CV20: 306176.79 | CW20: 10 | CX20: 20.33 | CY20: 933 | DA20: АЛИМПИЕВА | DB20: 551
